[[0, [["55000.00000", "0.01000000", "1699999999.1234", "b", "m", ""]], "trade", "XBT/USD"], [0, {"a": [["55001.00000", "1.00000000", "1699999999.1234"]], "c": "1234"}, "book-10", "XBT/USD"], [0, [["55000.00000", "0.01000000", "1699999999.1234", "b", "m", ""]], "trade", "XBT/USD"], [0, {"a": [["55001.00000", "1.00000000", "1699999999.1234"]], "c": "1234"}, "book-10", "XBT/USD"], [0, [["55000.00000", "0.01000000", "1699999999.1234", "b", "m", ""]], "trade", "XBT/USD"], [0, {"a": [["55001.00000", "1.00000000", "1699999999.1234"]], "c": "1234"}, "book-10", "XBT/USD"], [0, [["55000.00000", "0.01000000", "1699999999.1234", "b", "m", ""]], "trade", "XBT/USD"], [0, {"a": [["55001.00000", "1.00000000", "1699999999.1234"]], "c": "1234"}, "book-10", "XBT/USD"], [0, [["55000.00000", "0.01000000", "1699999999.1234", "b", "m", ""]], "trade", "XBT/USD"], [0, {"a": [["55001.00000", "1.00000000", "1699999999.1234"]], "c": "1234"}, "book-10", "XBT/USD"], [0, [["55000.00000", "0.01000000", "1699999999.1234", "b", "m", ""]], "trade", "XBT/USD"], [0, {"a": [["55001.00000", "1.00000000", "1699999999.1234"]], "c": "1234"}, "book-10", "XBT/USD"], [0, [["55000.00000", "0.01000000", "1699999999.1234", "b", "m", ""]], "trade", "XBT/USD"], [0, {"a": [["55001.00000", "1.00000000", "1699999999.1234"]], "c": "1234"}, "book-10", "XBT/USD"], [0, [["55000.00000", "0.01000000", "1699999999.1234", "b", "m", ""]], "trade", "XBT/USD"], [0, {"a": [["55001.00000", "1.00000000", "1699999999.1234"]], "c": "1234"}, "book-10", "XBT/USD"], [0, [["55000.00000", "0.01000000", "1699999999.1234", "b", "m", ""]], "trade", "XBT/USD"], [0, {"a": [["55001.00000", "1.00000000", "1699999999.1234"]], "c": "1234"}, "book-10", "XBT/USD"], [0, [["55000.00000", "0.01000000", "1699999999.1234", "b", "m", ""]], "trade", "XBT/USD"], [0, {"a": [["55001.00000", "1.00000000", "1699999999.1234"]], "c": "1234"}, "book-10", "XBT/USD"], [0, [["55000.00000", "0.01000000", "1699999999.1234", "b", "m", ""]], "trade", "XBT/USD"], [0, {"a": [["55001.00000", "1.00000000", "1699999999.1234"]], "c": "1234"}, "book-10", "XBT/USD"], [0, [["55000.00000", "0.01000000", "1699999999.1234", "b", "m", ""]], "trade", "XBT/USD"], [0, {"a": [["55001.00000", "1.00000000", "1699999999.1234"]], "c": "1234"}, "book-10", "XBT/USD"], [0, [["55000.00000", "0.01000000", "1699999999.1234", "b", "m", ""]], "trade", "XBT/USD"], [0, {"a": [["55001.00000", "1.00000000", "1699999999.1234"]], "c": "1234"}, "book-10", "XBT/USD"], [0, [["55000.00000", "0.01000000", "1699999999.1234", "b", "m", ""]], "trade", "XBT/USD"], [0, {"a": [["55001.00000", "1.00000000", "1699999999.1234"]], "c": "1234"}, "book-10", "XBT/USD"], [0, [["55000.00000", "0.01000000", "1699999999.1234", "b", "m", ""]], "trade", "XBT/USD"], [0, {"a": [["55001.00000", "1.00000000", "1699999999.1234"]], "c": "1234"}, "book-10", "XBT/USD"], [0, [["55000.00000", "0.01000000", "1699999999.1234", "b", "m", ""]], "trade", "XBT/USD"], [0, {"a": [["55001.00000", "1.00000000", "1699999999.1234"]], "c": "1234"}, "book-10", "XBT/USD"], [0, [["55000.00000", "0.01000000", "1699999999.1234", "b", "m", ""]], "trade", "XBT/USD"], [0, {"a": [["55001.00000", "1.00000000", "1699999999.1234"]], "c": "1234"}, "book-10", "XBT/USD"], [0, [["55000.00000", "0.01000000", "1699999999.1234", "b", "m", ""]], "trade", "XBT/USD"], [0, {"a": [["55001.00000", "1.00000000", "1699999999.1234"]], "c": "1234"}, "book-10", "XBT/USD"], [0, [["55000.00000", "0.01000000", "1699999999.1234", "b", "m", ""]], "trade", "XBT/USD"], [0, {"a": [["55001.00000", "1.00000000", "1699999999.1234"]], "c": "1234"}, "book-10", "XBT/USD"], [0, [["55000.00000", "0.01000000", "1699999999.1234", "b", "m", ""]], "trade", "XBT/USD"], [0, {"a": [["55001.00000", "1.00000000", "1699999999.1234"]], "c": "1234"}, "book-10", "XBT/USD"], [0, [["55000.00000", "0.01000000", "1699999999.1234", "b", "m", ""]], "trade", "XBT/USD"], [0, {"a": [["55001.00000", "1.00000000", "1699999999.1234"]], "c": "1234"}, "book-10", "XBT/USD"], [0, [["55000.00000", "0.01000000", "1699999999.1234", "b", "m", ""]], "trade", "XBT/USD"], [0, {"a": [["55001.00000", "1.00000000", "1699999999.1234"]], "c": "1234"}, "book-10", "XBT/USD"], [0, [["55000.00000", "0.01000000", "1699999999.1234", "b", "m", ""]], "trade", "XBT/USD"], [0, {"a": [["55001.00000", "1.00000000", "1699999999.1234"]], "c": "1234"}, "book-10", "XBT/USD"], [0, [["55000.00000", "0.01000000", "1699999999.1234", "b", "m", ""]], "trade", "XBT/USD"], [0, {"a": [["55001.00000", "1.00000000", "1699999999.1234"]], "c": "1234"}, "book-10", "XBT/USD"], [0, [["55000.00000", "0.01000000", "1699999999.1234", "b", "m", ""]], "trade", "XBT/USD"], [0, {"a": [["55001.00000", "1.00000000", "1699999999.1234"]], "c": "1234"}, "book-10", "XBT/USD"], [0, [["55000.00000", "0.01000000", "1699999999.1234", "b", "m", ""]], "trade", "XBT/USD"], [0, {"a": [["55001.00000", "1.00000000", "1699999999.1234"]], "c": "1234"}, "book-10", "XBT/USD"], [0, [["55000.00000", "0.01000000", "1699999999.1234", "b", "m", ""]], "trade", "XBT/USD"], [0, {"a": [["55001.00000", "1.00000000", "1699999999.1234"]], "c": "1234"}, "book-10", "XBT/USD"], [0, [["55000.00000", "0.01000000", "1699999999.1234", "b", "m", ""]], "trade", "XBT/USD"], [0, {"a": [["55001.00000", "1.00000000", "1699999999.1234"]], "c": "1234"}, "book-10", "XBT/USD"], [0, [["55000.00000", "0.01000000", "1699999999.1234", "b", "m", ""]], "trade", "XBT/USD"], [0, {"a": [["55001.00000", "1.00000000", "1699999999.1234"]], "c": "1234"}, "book-10", "XBT/USD"], [0, [["55000.00000", "0.01000000", "1699999999.1234", "b", "m", ""]], "trade", "XBT/USD"], [0, {"a": [["55001.00000", "1.00000000", "1699999999.1234"]], "c": "1234"}, "book-10", "XBT/USD"], [0, [["55000.00000", "0.01000000", "1699999999.1234", "b", "m", ""]], "trade", "XBT/USD"], [0, {"a": [["55001.00000", "1.00000000", "1699999999.1234"]], "c": "1234"}, "book-10", "XBT/USD"], [0, [["55000.00000", "0.01000000", "1699999999.1234", "b", "m", ""]], "trade", "XBT/USD"], [0, {"a": [["55001.00000", "1.00000000", "1699999999.1234"]], "c": "1234"}, "book-10", "XBT/USD"], [0, [["55000.00000", "0.01000000", "1699999999.1234", "b", "m", ""]], "trade", "XBT/USD"], [0, {"a": [["55001.00000", "1.00000000", "1699999999.1234"]], "c": "1234"}, "book-10", "XBT/USD"], [0, [["55000.00000", "0.01000000", "1699999999.1234", "b", "m", ""]], "trade", "XBT/USD"], [0, {"a": [["55001.00000", "1.00000000", "1699999999.1234"]], "c": "1234"}, "book-10", "XBT/USD"], [0, [["55000.00000", "0.01000000", "1699999999.1234", "b", "m", ""]], "trade", "XBT/USD"], [0, {"a": [["55001.00000", "1.00000000", "1699999999.1234"]], "c": "1234"}, "book-10", "XBT/USD"], [0, [["55000.00000", "0.01000000", "1699999999.1234", "b", "m", ""]], "trade", "XBT/USD"], [0, {"a": [["55001.00000", "1.00000000", "1699999999.1234"]], "c": "1234"}, "book-10", "XBT/USD"], [0, [["55000.00000", "0.01000000", "1699999999.1234", "b", "m", ""]], "trade", "XBT/USD"], [0, {"a": [["55001.00000", "1.00000000", "1699999999.1234"]], "c": "1234"}, "book-10", "XBT/USD"], [0, [["55000.00000", "0.01000000", "1699999999.1234", "b", "m", ""]], "trade", "XBT/USD"], [0, {"a": [["55001.00000", "1.00000000", "1699999999.1234"]], "c": "1234"}, "book-10", "XBT/USD"], [0, [["55000.00000", "0.01000000", "1699999999.1234", "b", "m", ""]], "trade", "XBT/USD"], [0, {"a": [["55001.00000", "1.00000000", "1699999999.1234"]], "c": "1234"}, "book-10", "XBT/USD"], [0, [["55000.00000", "0.01000000", "1699999999.1234", "b", "m", ""]], "trade", "XBT/USD"], [0, {"a": [["55001.00000", "1.00000000", "1699999999.1234"]], "c": "1234"}, "book-10", "XBT/USD"], [0, [["55000.00000", "0.01000000", "1699999999.1234", "b", "m", ""]], "trade", "XBT/USD"], [0, {"a": [["55001.00000", "1.00000000", "1699999999.1234"]], "c": "1234"}, "book-10", "XBT/USD"], [0, [["55000.00000", "0.01000000", "1699999999.1234", "b", "m", ""]], "trade", "XBT/USD"], [0, {"a": [["55001.00000", "1.00000000", "1699999999.1234"]], "c": "1234"}, "book-10", "XBT/USD"], [0, [["55000.00000", "0.01000000", "1699999999.1234", "b", "m", ""]], "trade", "XBT/USD"], [0, {"a": [["55001.00000", "1.00000000", "1699999999.1234"]], "c": "1234"}, "book-10", "XBT/USD"], [0, [["55000.00000", "0.01000000", "1699999999.1234", "b", "m", ""]], "trade", "XBT/USD"], [0, {"a": [["55001.00000", "1.00000000", "1699999999.1234"]], "c": "1234"}, "book-10", "XBT/USD"], [0, [["55000.00000", "0.01000000", "1699999999.1234", "b", "m", ""]], "trade", "XBT/USD"], [0, {"a": [["55001.00000", "1.00000000", "1699999999.1234"]], "c": "1234"}, "book-10", "XBT/USD"], [0, [["55000.00000", "0.01000000", "1699999999.1234", "b", "m", ""]], "trade", "XBT/USD"], [0, {"a": [["55001.00000", "1.00000000", "1699999999.1234"]], "c": "1234"}, "book-10", "XBT/USD"], [0, [["55000.00000", "0.01000000", "1699999999.1234", "b", "m", ""]], "trade", "XBT/USD"], [0, {"a": [["55001.00000", "1.00000000", "1699999999.1234"]], "c": "1234"}, "book-10", "XBT/USD"], [0, [["55000.00000", "0.01000000", "1699999999.1234", "b", "m", ""]], "trade", "XBT/USD"], [0, {"a": [["55001.00000", "1.00000000", "1699999999.1234"]], "c": "1234"}, "book-10", "XBT/USD"], [0, [["55000.00000", "0.01000000", "1699999999.1234", "b", "m", ""]], "trade", "XBT/USD"], [0, {"a": [["55001.00000", "1.00000000", "1699999999.1234"]], "c": "1234"}, "book-10", "XBT/USD"], [0, [["55000.00000", "0.01000000", "1699999999.1234", "b", "m", ""]], "trade", "XBT/USD"], [0, {"a": [["55001.00000", "1.00000000", "1699999999.1234"]], "c": "1234"}, "book-10", "XBT/USD"], [0, [["55000.00000", "0.01000000", "1699999999.1234", "b", "m", ""]], "trade", "XBT/USD"], [0, {"a": [["55001.00000", "1.00000000", "1699999999.1234"]], "c": "1234"}, "book-10", "XBT/USD"], [0, [["55000.00000", "0.01000000", "1699999999.1234", "b", "m", ""]], "trade", "XBT/USD"], [0, {"a": [["55001.00000", "1.00000000", "1699999999.1234"]], "c": "1234"}, "book-10", "XBT/USD"], [0, [["55000.00000", "0.01000000", "1699999999.1234", "b", "m", ""]], "trade", "XBT/USD"], [0, {"a": [["55001.00000", "1.00000000", "1699999999.1234"]], "c": "1234"}, "book-10", "XBT/USD"], [0, [["55000.00000", "0.01000000", "1699999999.1234", "b", "m", ""]], "trade", "XBT/USD"], [0, {"a": [["55001.00000", "1.00000000", "1699999999.1234"]], "c": "1234"}, "book-10", "XBT/USD"], [0, [["55000.00000", "0.01000000", "1699999999.1234", "b", "m", ""]], "trade", "XBT/USD"], [0, {"a": [["55001.00000", "1.00000000", "1699999999.1234"]], "c": "1234"}, "book-10", "XBT/USD"], [0, [["55000.00000", "0.01000000", "1699999999.1234", "b", "m", ""]], "trade", "XBT/USD"], [0, {"a": [["55001.00000", "1.00000000", "1699999999.1234"]], "c": "1234"}, "book-10", "XBT/USD"], [0, [["55000.00000", "0.01000000", "1699999999.1234", "b", "m", ""]], "trade", "XBT/USD"], [0, {"a": [["55001.00000", "1.00000000", "1699999999.1234"]], "c": "1234"}, "book-10", "XBT/USD"], [0, [["55000.00000", "0.01000000", "1699999999.1234", "b", "m", ""]], "trade", "XBT/USD"], [0, {"a": [["55001.00000", "1.00000000", "1699999999.1234"]], "c": "1234"}, "book-10", "XBT/USD"], [0, [["55000.00000", "0.01000000", "1699999999.1234", "b", "m", ""]], "trade", "XBT/USD"], [0, {"a": [["55001.00000", "1.00000000", "1699999999.1234"]], "c": "1234"}, "book-10", "XBT/USD"], [0, [["55000.00000", "0.01000000", "1699999999.1234", "b", "m", ""]], "trade", "XBT/USD"], [0, {"a": [["55001.00000", "1.00000000", "1699999999.1234"]], "c": "1234"}, "book-10", "XBT/USD"], [0, [["55000.00000", "0.01000000", "1699999999.1234", "b", "m", ""]], "trade", "XBT/USD"], [0, {"a": [["55001.00000", "1.00000000", "1699999999.1234"]], "c": "1234"}, "book-10", "XBT/USD"], [0, [["55000.00000", "0.01000000", "1699999999.1234", "b", "m", ""]], "trade", "XBT/USD"], [0, {"a": [["55001.00000", "1.00000000", "1699999999.1234"]], "c": "1234"}, "book-10", "XBT/USD"], [0, [["55000.00000", "0.01000000", "1699999999.1234", "b", "m", ""]], "trade", "XBT/USD"], [0, {"a": [["55001.00000", "1.00000000", "1699999999.1234"]], "c": "1234"}, "book-10", "XBT/USD"], [0, [["55000.00000", "0.01000000", "1699999999.1234", "b", "m", ""]], "trade", "XBT/USD"], [0, {"a": [["55001.00000", "1.00000000", "1699999999.1234"]], "c": "1234"}, "book-10", "XBT/USD"], [0, [["55000.00000", "0.01000000", "1699999999.1234", "b", "m", ""]], "trade", "XBT/USD"], [0, {"a": [["55001.00000", "1.00000000", "1699999999.1234"]], "c": "1234"}, "book-10", "XBT/USD"], [0, [["55000.00000", "0.01000000", "1699999999.1234", "b", "m", ""]], "trade", "XBT/USD"], [0, {"a": [["55001.00000", "1.00000000", "1699999999.1234"]], "c": "1234"}, "book-10", "XBT/USD"], [0, [["55000.00000", "0.01000000", "1699999999.1234", "b", "m", ""]], "trade", "XBT/USD"], [0, {"a": [["55001.00000", "1.00000000", "1699999999.1234"]], "c": "1234"}, "book-10", "XBT/USD"], [0, [["55000.00000", "0.01000000", "1699999999.1234", "b", "m", ""]], "trade", "XBT/USD"], [0, {"a": [["55001.00000", "1.00000000", "1699999999.1234"]], "c": "1234"}, "book-10", "XBT/USD"], [0, [["55000.00000", "0.01000000", "1699999999.1234", "b", "m", ""]], "trade", "XBT/USD"], [0, {"a": [["55001.00000", "1.00000000", "1699999999.1234"]], "c": "1234"}, "book-10", "XBT/USD"], [0, [["55000.00000", "0.01000000", "1699999999.1234", "b", "m", ""]], "trade", "XBT/USD"], [0, {"a": [["55001.00000", "1.00000000", "1699999999.1234"]], "c": "1234"}, "book-10", "XBT/USD"], [0, [["55000.00000", "0.01000000", "1699999999.1234", "b", "m", ""]], "trade", "XBT/USD"], [0, {"a": [["55001.00000", "1.00000000", "1699999999.1234"]], "c": "1234"}, "book-10", "XBT/USD"], [0, [["55000.00000", "0.01000000", "1699999999.1234", "b", "m", ""]], "trade", "XBT/USD"], [0, {"a": [["55001.00000", "1.00000000", "1699999999.1234"]], "c": "1234"}, "book-10", "XBT/USD"], [0, [["55000.00000", "0.01000000", "1699999999.1234", "b", "m", ""]], "trade", "XBT/USD"], [0, {"a": [["55001.00000", "1.00000000", "1699999999.1234"]], "c": "1234"}, "book-10", "XBT/USD"], [0, [["55000.00000", "0.01000000", "1699999999.1234", "b", "m", ""]], "trade", "XBT/USD"], [0, {"a": [["55001.00000", "1.00000000", "1699999999.1234"]], "c": "1234"}, "book-10", "XBT/USD"], [0, [["55000.00000", "0.01000000", "1699999999.1234", "b", "m", ""]], "trade", "XBT/USD"], [0, {"a": [["55001.00000", "1.00000000", "1699999999.1234"]], "c": "1234"}, "book-10", "XBT/USD"], [0, [["55000.00000", "0.01000000", "1699999999.1234", "b", "m", ""]], "trade", "XBT/USD"], [0, {"a": [["55001.00000", "1.00000000", "1699999999.1234"]], "c": "1234"}, "book-10", "XBT/USD"], [0, [["55000.00000", "0.01000000", "1699999999.1234", "b", "m", ""]], "trade", "XBT/USD"], [0, {"a": [["55001.00000", "1.00000000", "1699999999.1234"]], "c": "1234"}, "book-10", "XBT/USD"], [0, [["55000.00000", "0.01000000", "1699999999.1234", "b", "m", ""]], "trade", "XBT/USD"], [0, {"a": [["55001.00000", "1.00000000", "1699999999.1234"]], "c": "1234"}, "book-10", "XBT/USD"], [0, [["55000.00000", "0.01000000", "1699999999.1234", "b", "m", ""]], "trade", "XBT/USD"], [0, {"a": [["55001.00000", "1.00000000", "1699999999.1234"]], "c": "1234"}, "book-10", "XBT/USD"], [0, [["55000.00000", "0.01000000", "1699999999.1234", "b", "m", ""]], "trade", "XBT/USD"], [0, {"a": [["55001.00000", "1.00000000", "1699999999.1234"]], "c": "1234"}, "book-10", "XBT/USD"], [0, [["55000.00000", "0.01000000", "1699999999.1234", "b", "m", ""]], "trade", "XBT/USD"], [0, {"a": [["55001.00000", "1.00000000", "1699999999.1234"]], "c": "1234"}, "book-10", "XBT/USD"], [0, [["55000.00000", "0.01000000", "1699999999.1234", "b", "m", ""]], "trade", "XBT/USD"], [0, {"a": [["55001.00000", "1.00000000", "1699999999.1234"]], "c": "1234"}, "book-10", "XBT/USD"], [0, [["55000.00000", "0.01000000", "1699999999.1234", "b", "m", ""]], "trade", "XBT/USD"], [0, {"a": [["55001.00000", "1.00000000", "1699999999.1234"]], "c": "1234"}, "book-10", "XBT/USD"], [0, [["55000.00000", "0.01000000", "1699999999.1234", "b", "m", ""]], "trade", "XBT/USD"], [0, {"a": [["55001.00000", "1.00000000", "1699999999.1234"]], "c": "1234"}, "book-10", "XBT/USD"], [0, [["55000.00000", "0.01000000", "1699999999.1234", "b", "m", ""]], "trade", "XBT/USD"], [0, {"a": [["55001.00000", "1.00000000", "1699999999.1234"]], "c": "1234"}, "book-10", "XBT/USD"], [0, [["55000.00000", "0.01000000", "1699999999.1234", "b", "m", ""]], "trade", "XBT/USD"], [0, {"a": [["55001.00000", "1.00000000", "1699999999.1234"]], "c": "1234"}, "book-10", "XBT/USD"], [0, [["55000.00000", "0.01000000", "1699999999.1234", "b", "m", ""]], "trade", "XBT/USD"], [0, {"a": [["55001.00000", "1.00000000", "1699999999.1234"]], "c": "1234"}, "book-10", "XBT/USD"], [0, [["55000.00000", "0.01000000", "1699999999.1234", "b", "m", ""]], "trade", "XBT/USD"], [0, {"a": [["55001.00000", "1.00000000", "1699999999.1234"]], "c": "1234"}, "book-10", "XBT/USD"], [0, [["55000.00000", "0.01000000", "1699999999.1234", "b", "m", ""]], "trade", "XBT/USD"], [0, {"a": [["55001.00000", "1.00000000", "1699999999.1234"]], "c": "1234"}, "book-10", "XBT/USD"], [0, [["55000.00000", "0.01000000", "1699999999.1234", "b", "m", ""]], "trade", "XBT/USD"], [0, {"a": [["55001.00000", "1.00000000", "1699999999.1234"]], "c": "1234"}, "book-10", "XBT/USD"], [0, [["55000.00000", "0.01000000", "1699999999.1234", "b", "m", ""]], "trade", "XBT/USD"], [0, {"a": [["55001.00000", "1.00000000", "1699999999.1234"]], "c": "1234"}, "book-10", "XBT/USD"], [0, [["55000.00000", "0.01000000", "1699999999.1234", "b", "m", ""]], "trade", "XBT/USD"], [0, {"a": [["55001.00000", "1.00000000", "1699999999.1234"]], "c": "1234"}, "book-10", "XBT/USD"], [0, [["55000.00000", "0.01000000", "1699999999.1234", "b", "m", ""]], "trade", "XBT/USD"], [0, {"a": [["55001.00000", "1.00000000", "1699999999.1234"]], "c": "1234"}, "book-10", "XBT/USD"], [0, [["55000.00000", "0.01000000", "1699999999.1234", "b", "m", ""]], "trade", "XBT/USD"], [0, {"a": [["55001.00000", "1.00000000", "1699999999.1234"]], "c": "1234"}, "book-10", "XBT/USD"], [0, [["55000.00000", "0.01000000", "1699999999.1234", "b", "m", ""]], "trade", "XBT/USD"], [0, {"a": [["55001.00000", "1.00000000", "1699999999.1234"]], "c": "1234"}, "book-10", "XBT/USD"], [0, [["55000.00000", "0.01000000", "1699999999.1234", "b", "m", ""]], "trade", "XBT/USD"], [0, {"a": [["55001.00000", "1.00000000", "1699999999.1234"]], "c": "1234"}, "book-10", "XBT/USD"], [0, [["55000.00000", "0.01000000", "1699999999.1234", "b", "m", ""]], "trade", "XBT/USD"], [0, {"a": [["55001.00000", "1.00000000", "1699999999.1234"]], "c": "1234"}, "book-10", "XBT/USD"], [0, [["55000.00000", "0.01000000", "1699999999.1234", "b", "m", ""]], "trade", "XBT/USD"], [0, {"a": [["55001.00000", "1.00000000", "1699999999.1234"]], "c": "1234"}, "book-10", "XBT/USD"], [0, [["55000.00000", "0.01000000", "1699999999.1234", "b", "m", ""]], "trade", "XBT/USD"], [0, {"a": [["55001.00000", "1.00000000", "1699999999.1234"]], "c": "1234"}, "book-10", "XBT/USD"], [0, [["55000.00000", "0.01000000", "1699999999.1234", "b", "m", ""]], "trade", "XBT/USD"], [0, {"a": [["55001.00000", "1.00000000", "1699999999.1234"]], "c": "1234"}, "book-10", "XBT/USD"], [0, [["55000.00000", "0.01000000", "1699999999.1234", "b", "m", ""]], "trade", "XBT/USD"], [0, {"a": [["55001.00000", "1.00000000", "1699999999.1234"]], "c": "1234"}, "book-10", "XBT/USD"], [0, [["55000.00000", "0.01000000", "1699999999.1234", "b", "m", ""]], "trade", "XBT/USD"], [0, {"a": [["55001.00000", "1.00000000", "1699999999.1234"]], "c": "1234"}, "book-10", "XBT/USD"], [0, [["55000.00000", "0.01000000", "1699999999.1234", "b", "m", ""]], "trade", "XBT/USD"], [0, {"a": [["55001.00000", "1.00000000", "1699999999.1234"]], "c": "1234"}, "book-10", "XBT/USD"], [0, [["55000.00000", "0.01000000", "1699999999.1234", "b", "m", ""]], "trade", "XBT/USD"], [0, {"a": [["55001.00000", "1.00000000", "1699999999.1234"]], "c": "1234"}, "book-10", "XBT/USD"], [0, [["55000.00000", "0.01000000", "1699999999.1234", "b", "m", ""]], "trade", "XBT/USD"], [0, {"a": [["55001.00000", "1.00000000", "1699999999.1234"]], "c": "1234"}, "book-10", "XBT/USD"], [0, [["55000.00000", "0.01000000", "1699999999.1234", "b", "m", ""]], "trade", "XBT/USD"], [0, {"a": [["55001.00000", "1.00000000", "1699999999.1234"]], "c": "1234"}, "book-10", "XBT/USD"], [0, [["55000.00000", "0.01000000", "1699999999.1234", "b", "m", ""]], "trade", "XBT/USD"], [0, {"a": [["55001.00000", "1.00000000", "1699999999.1234"]], "c": "1234"}, "book-10", "XBT/USD"], [0, [["55000.00000", "0.01000000", "1699999999.1234", "b", "m", ""]], "trade", "XBT/USD"], [0, {"a": [["55001.00000", "1.00000000", "1699999999.1234"]], "c": "1234"}, "book-10", "XBT/USD"], [0, [["55000.00000", "0.01000000", "1699999999.1234", "b", "m", ""]], "trade", "XBT/USD"], [0, {"a": [["55001.00000", "1.00000000", "1699999999.1234"]], "c": "1234"}, "book-10", "XBT/USD"], [0, [["55000.00000", "0.01000000", "1699999999.1234", "b", "m", ""]], "trade", "XBT/USD"], [0, {"a": [["55001.00000", "1.00000000", "1699999999.1234"]], "c": "1234"}, "book-10", "XBT/USD"], [0, [["55000.00000", "0.01000000", "1699999999.1234", "b", "m", ""]], "trade", "XBT/USD"], [0, {"a": [["55001.00000", "1.00000000", "1699999999.1234"]], "c": "1234"}, "book-10", "XBT/USD"], [0, [["55000.00000", "0.01000000", "1699999999.1234", "b", "m", ""]], "trade", "XBT/USD"], [0, {"a": [["55001.00000", "1.00000000", "1699999999.1234"]], "c": "1234"}, "book-10", "XBT/USD"], [0, [["55000.00000", "0.01000000", "1699999999.1234", "b", "m", ""]], "trade", "XBT/USD"], [0, {"a": [["55001.00000", "1.00000000", "1699999999.1234"]], "c": "1234"}, "book-10", "XBT/USD"], [0, [["55000.00000", "0.01000000", "1699999999.1234", "b", "m", ""]], "trade", "XBT/USD"], [0, {"a": [["55001.00000", "1.00000000", "1699999999.1234"]], "c": "1234"}, "book-10", "XBT/USD"], [0, [["55000.00000", "0.01000000", "1699999999.1234", "b", "m", ""]], "trade", "XBT/USD"], [0, {"a": [["55001.00000", "1.00000000", "1699999999.1234"]], "c": "1234"}, "book-10", "XBT/USD"], [0, [["55000.00000", "0.01000000", "1699999999.1234", "b", "m", ""]], "trade", "XBT/USD"], [0, {"a": [["55001.00000", "1.00000000", "1699999999.1234"]], "c": "1234"}, "book-10", "XBT/USD"], [0, [["55000.00000", "0.01000000", "1699999999.1234", "b", "m", ""]], "trade", "XBT/USD"], [0, {"a": [["55001.00000", "1.00000000", "1699999999.1234"]], "c": "1234"}, "book-10", "XBT/USD"], [0, [["55000.00000", "0.01000000", "1699999999.1234", "b", "m", ""]], "trade", "XBT/USD"], [0, {"a": [["55001.00000", "1.00000000", "1699999999.1234"]], "c": "1234"}, "book-10", "XBT/USD"], [0, [["55000.00000", "0.01000000", "1699999999.1234", "b", "m", ""]], "trade", "XBT/USD"], [0, {"a": [["55001.00000", "1.00000000", "1699999999.1234"]], "c": "1234"}, "book-10", "XBT/USD"], [0, [["55000.00000", "0.01000000", "1699999999.1234", "b", "m", ""]], "trade", "XBT/USD"], [0, {"a": [["55001.00000", "1.00000000", "1699999999.1234"]], "c": "1234"}, "book-10", "XBT/USD"], [0, [["55000.00000", "0.01000000", "1699999999.1234", "b", "m", ""]], "trade", "XBT/USD"], [0, {"a": [["55001.00000", "1.00000000", "1699999999.1234"]], "c": "1234"}, "book-10", "XBT/USD"], [0, [["55000.00000", "0.01000000", "1699999999.1234", "b", "m", ""]], "trade", "XBT/USD"], [0, {"a": [["55001.00000", "1.00000000", "1699999999.1234"]], "c": "1234"}, "book-10", "XBT/USD"], [0, [["55000.00000", "0.01000000", "1699999999.1234", "b", "m", ""]], "trade", "XBT/USD"], [0, {"a": [["55001.00000", "1.00000000", "1699999999.1234"]], "c": "1234"}, "book-10", "XBT/USD"], [0, [["55000.00000", "0.01000000", "1699999999.1234", "b", "m", ""]], "trade", "XBT/USD"], [0, {"a": [["55001.00000", "1.00000000", "1699999999.1234"]], "c": "1234"}, "book-10", "XBT/USD"], [0, [["55000.00000", "0.01000000", "1699999999.1234", "b", "m", ""]], "trade", "XBT/USD"], [0, {"a": [["55001.00000", "1.00000000", "1699999999.1234"]], "c": "1234"}, "book-10", "XBT/USD"], [0, [["55000.00000", "0.01000000", "1699999999.1234", "b", "m", ""]], "trade", "XBT/USD"], [0, {"a": [["55001.00000", "1.00000000", "1699999999.1234"]], "c": "1234"}, "book-10", "XBT/USD"], [0, [["55000.00000", "0.01000000", "1699999999.1234", "b", "m", ""]], "trade", "XBT/USD"], [0, {"a": [["55001.00000", "1.00000000", "1699999999.1234"]], "c": "1234"}, "book-10", "XBT/USD"], [0, [["55000.00000", "0.01000000", "1699999999.1234", "b", "m", ""]], "trade", "XBT/USD"], [0, {"a": [["55001.00000", "1.00000000", "1699999999.1234"]], "c": "1234"}, "book-10", "XBT/USD"], [0, [["55000.00000", "0.01000000", "1699999999.1234", "b", "m", ""]], "trade", "XBT/USD"], [0, {"a": [["55001.00000", "1.00000000", "1699999999.1234"]], "c": "1234"}, "book-10", "XBT/USD"], [0, [["55000.00000", "0.01000000", "1699999999.1234", "b", "m", ""]], "trade", "XBT/USD"], [0, {"a": [["55001.00000", "1.00000000", "1699999999.1234"]], "c": "1234"}, "book-10", "XBT/USD"], [0, [["55000.00000", "0.01000000", "1699999999.1234", "b", "m", ""]], "trade", "XBT/USD"], [0, {"a": [["55001.00000", "1.00000000", "1699999999.1234"]], "c": "1234"}, "book-10", "XBT/USD"], [0, [["55000.00000", "0.01000000", "1699999999.1234", "b", "m", ""]], "trade", "XBT/USD"], [0, {"a": [["55001.00000", "1.00000000", "1699999999.1234"]], "c": "1234"}, "book-10", "XBT/USD"], [0, [["55000.00000", "0.01000000", "1699999999.1234", "b", "m", ""]], "trade", "XBT/USD"], [0, {"a": [["55001.00000", "1.00000000", "1699999999.1234"]], "c": "1234"}, "book-10", "XBT/USD"], [0, [["55000.00000", "0.01000000", "1699999999.1234", "b", "m", ""]], "trade", "XBT/USD"], [0, {"a": [["55001.00000", "1.00000000", "1699999999.1234"]], "c": "1234"}, "book-10", "XBT/USD"], [0, [["55000.00000", "0.01000000", "1699999999.1234", "b", "m", ""]], "trade", "XBT/USD"], [0, {"a": [["55001.00000", "1.00000000", "1699999999.1234"]], "c": "1234"}, "book-10", "XBT/USD"], [0, [["55000.00000", "0.01000000", "1699999999.1234", "b", "m", ""]], "trade", "XBT/USD"], [0, {"a": [["55001.00000", "1.00000000", "1699999999.1234"]], "c": "1234"}, "book-10", "XBT/USD"], [0, [["55000.00000", "0.01000000", "1699999999.1234", "b", "m", ""]], "trade", "XBT/USD"], [0, {"a": [["55001.00000", "1.00000000", "1699999999.1234"]], "c": "1234"}, "book-10", "XBT/USD"], [0, [["55000.00000", "0.01000000", "1699999999.1234", "b", "m", ""]], "trade", "XBT/USD"], [0, {"a": [["55001.00000", "1.00000000", "1699999999.1234"]], "c": "1234"}, "book-10", "XBT/USD"], [0, [["55000.00000", "0.01000000", "1699999999.1234", "b", "m", ""]], "trade", "XBT/USD"], [0, {"a": [["55001.00000", "1.00000000", "1699999999.1234"]], "c": "1234"}, "book-10", "XBT/USD"], [0, [["55000.00000", "0.01000000", "1699999999.1234", "b", "m", ""]], "trade", "XBT/USD"], [0, {"a": [["55001.00000", "1.00000000", "1699999999.1234"]], "c": "1234"}, "book-10", "XBT/USD"], [0, [["55000.00000", "0.01000000", "1699999999.1234", "b", "m", ""]], "trade", "XBT/USD"], [0, {"a": [["55001.00000", "1.00000000", "1699999999.1234"]], "c": "1234"}, "book-10", "XBT/USD"], [0, [["55000.00000", "0.01000000", "1699999999.1234", "b", "m", ""]], "trade", "XBT/USD"], [0, {"a": [["55001.00000", "1.00000000", "1699999999.1234"]], "c": "1234"}, "book-10", "XBT/USD"], [0, [["55000.00000", "0.01000000", "1699999999.1234", "b", "m", ""]], "trade", "XBT/USD"], [0, {"a": [["55001.00000", "1.00000000", "1699999999.1234"]], "c": "1234"}, "book-10", "XBT/USD"], [0, [["55000.00000", "0.01000000", "1699999999.1234", "b", "m", ""]], "trade", "XBT/USD"], [0, {"a": [["55001.00000", "1.00000000", "1699999999.1234"]], "c": "1234"}, "book-10", "XBT/USD"], [0, [["55000.00000", "0.01000000", "1699999999.1234", "b", "m", ""]], "trade", "XBT/USD"], [0, {"a": [["55001.00000", "1.00000000", "1699999999.1234"]], "c": "1234"}, "book-10", "XBT/USD"], [0, [["55000.00000", "0.01000000", "1699999999.1234", "b", "m", ""]], "trade", "XBT/USD"], [0, {"a": [["55001.00000", "1.00000000", "1699999999.1234"]], "c": "1234"}, "book-10", "XBT/USD"], [0, [["55000.00000", "0.01000000", "1699999999.1234", "b", "m", ""]], "trade", "XBT/USD"], [0, {"a": [["55001.00000", "1.00000000", "1699999999.1234"]], "c": "1234"}, "book-10", "XBT/USD"], [0, [["55000.00000", "0.01000000", "1699999999.1234", "b", "m", ""]], "trade", "XBT/USD"], [0, {"a": [["55001.00000", "1.00000000", "1699999999.1234"]], "c": "1234"}, "book-10", "XBT/USD"], [0, [["55000.00000", "0.01000000", "1699999999.1234", "b", "m", ""]], "trade", "XBT/USD"], [0, {"a": [["55001.00000", "1.00000000", "1699999999.1234"]], "c": "1234"}, "book-10", "XBT/USD"], [0, [["55000.00000", "0.01000000", "1699999999.1234", "b", "m", ""]], "trade", "XBT/USD"], [0, {"a": [["55001.00000", "1.00000000", "1699999999.1234"]], "c": "1234"}, "book-10", "XBT/USD"], [0, [["55000.00000", "0.01000000", "1699999999.1234", "b", "m", ""]], "trade", "XBT/USD"], [0, {"a": [["55001.00000", "1.00000000", "1699999999.1234"]], "c": "1234"}, "book-10", "XBT/USD"], [0, [["55000.00000", "0.01000000", "1699999999.1234", "b", "m", ""]], "trade", "XBT/USD"], [0, {"a": [["55001.00000", "1.00000000", "1699999999.1234"]], "c": "1234"}, "book-10", "XBT/USD"], [0, [["55000.00000", "0.01000000", "1699999999.1234", "b", "m", ""]], "trade", "XBT/USD"], [0, {"a": [["55001.00000", "1.00000000", "1699999999.1234"]], "c": "1234"}, "book-10", "XBT/USD"], [0, [["55000.00000", "0.01000000", "1699999999.1234", "b", "m", ""]], "trade", "XBT/USD"], [0, {"a": [["55001.00000", "1.00000000", "1699999999.1234"]], "c": "1234"}, "book-10", "XBT/USD"], [0, [["55000.00000", "0.01000000", "1699999999.1234", "b", "m", ""]], "trade", "XBT/USD"], [0, {"a": [["55001.00000", "1.00000000", "1699999999.1234"]], "c": "1234"}, "book-10", "XBT/USD"], [0, [["55000.00000", "0.01000000", "1699999999.1234", "b", "m", ""]], "trade", "XBT/USD"], [0, {"a": [["55001.00000", "1.00000000", "1699999999.1234"]], "c": "1234"}, "book-10", "XBT/USD"], [0, [["55000.00000", "0.01000000", "1699999999.1234", "b", "m", ""]], "trade", "XBT/USD"], [0, {"a": [["55001.00000", "1.00000000", "1699999999.1234"]], "c": "1234"}, "book-10", "XBT/USD"], [0, [["55000.00000", "0.01000000", "1699999999.1234", "b", "m", ""]], "trade", "XBT/USD"], [0, {"a": [["55001.00000", "1.00000000", "1699999999.1234"]], "c": "1234"}, "book-10", "XBT/USD"], [0, [["55000.00000", "0.01000000", "1699999999.1234", "b", "m", ""]], "trade", "XBT/USD"], [0, {"a": [["55001.00000", "1.00000000", "1699999999.1234"]], "c": "1234"}, "book-10", "XBT/USD"], [0, [["55000.00000", "0.01000000", "1699999999.1234", "b", "m", ""]], "trade", "XBT/USD"], [0, {"a": [["55001.00000", "1.00000000", "1699999999.1234"]], "c": "1234"}, "book-10", "XBT/USD"], [0, [["55000.00000", "0.01000000", "1699999999.1234", "b", "m", ""]], "trade", "XBT/USD"], [0, {"a": [["55001.00000", "1.00000000", "1699999999.1234"]], "c": "1234"}, "book-10", "XBT/USD"], [0, [["55000.00000", "0.01000000", "1699999999.1234", "b", "m", ""]], "trade", "XBT/USD"], [0, {"a": [["55001.00000", "1.00000000", "1699999999.1234"]], "c": "1234"}, "book-10", "XBT/USD"], [0, [["55000.00000", "0.01000000", "1699999999.1234", "b", "m", ""]], "trade", "XBT/USD"], [0, {"a": [["55001.00000", "1.00000000", "1699999999.1234"]], "c": "1234"}, "book-10", "XBT/USD"], [0, [["55000.00000", "0.01000000", "1699999999.1234", "b", "m", ""]], "trade", "XBT/USD"], [0, {"a": [["55001.00000", "1.00000000", "1699999999.1234"]], "c": "1234"}, "book-10", "XBT/USD"], [0, [["55000.00000", "0.01000000", "1699999999.1234", "b", "m", ""]], "trade", "XBT/USD"], [0, {"a": [["55001.00000", "1.00000000", "1699999999.1234"]], "c": "1234"}, "book-10", "XBT/USD"], [0, [["55000.00000", "0.01000000", "1699999999.1234", "b", "m", ""]], "trade", "XBT/USD"], [0, {"a": [["55001.00000", "1.00000000", "1699999999.1234"]], "c": "1234"}, "book-10", "XBT/USD"], [0, [["55000.00000", "0.01000000", "1699999999.1234", "b", "m", ""]], "trade", "XBT/USD"], [0, {"a": [["55001.00000", "1.00000000", "1699999999.1234"]], "c": "1234"}, "book-10", "XBT/USD"], [0, [["55000.00000", "0.01000000", "1699999999.1234", "b", "m", ""]], "trade", "XBT/USD"], [0, {"a": [["55001.00000", "1.00000000", "1699999999.1234"]], "c": "1234"}, "book-10", "XBT/USD"], [0, [["55000.00000", "0.01000000", "1699999999.1234", "b", "m", ""]], "trade", "XBT/USD"], [0, {"a": [["55001.00000", "1.00000000", "1699999999.1234"]], "c": "1234"}, "book-10", "XBT/USD"], [0, [["55000.00000", "0.01000000", "1699999999.1234", "b", "m", ""]], "trade", "XBT/USD"], [0, {"a": [["55001.00000", "1.00000000", "1699999999.1234"]], "c": "1234"}, "book-10", "XBT/USD"], [0, [["55000.00000", "0.01000000", "1699999999.1234", "b", "m", ""]], "trade", "XBT/USD"], [0, {"a": [["55001.00000", "1.00000000", "1699999999.1234"]], "c": "1234"}, "book-10", "XBT/USD"], [0, [["55000.00000", "0.01000000", "1699999999.1234", "b", "m", ""]], "trade", "XBT/USD"], [0, {"a": [["55001.00000", "1.00000000", "1699999999.1234"]], "c": "1234"}, "book-10", "XBT/USD"], [0, [["55000.00000", "0.01000000", "1699999999.1234", "b", "m", ""]], "trade", "XBT/USD"], [0, {"a": [["55001.00000", "1.00000000", "1699999999.1234"]], "c": "1234"}, "book-10", "XBT/USD"], [0, [["55000.00000", "0.01000000", "1699999999.1234", "b", "m", ""]], "trade", "XBT/USD"], [0, {"a": [["55001.00000", "1.00000000", "1699999999.1234"]], "c": "1234"}, "book-10", "XBT/USD"], [0, [["55000.00000", "0.01000000", "1699999999.1234", "b", "m", ""]], "trade", "XBT/USD"], [0, {"a": [["55001.00000", "1.00000000", "1699999999.1234"]], "c": "1234"}, "book-10", "XBT/USD"], [0, [["55000.00000", "0.01000000", "1699999999.1234", "b", "m", ""]], "trade", "XBT/USD"], [0, {"a": [["55001.00000", "1.00000000", "1699999999.1234"]], "c": "1234"}, "book-10", "XBT/USD"], [0, [["55000.00000", "0.01000000", "1699999999.1234", "b", "m", ""]], "trade", "XBT/USD"], [0, {"a": [["55001.00000", "1.00000000", "1699999999.1234"]], "c": "1234"}, "book-10", "XBT/USD"], [0, [["55000.00000", "0.01000000", "1699999999.1234", "b", "m", ""]], "trade", "XBT/USD"], [0, {"a": [["55001.00000", "1.00000000", "1699999999.1234"]], "c": "1234"}, "book-10", "XBT/USD"], [0, [["55000.00000", "0.01000000", "1699999999.1234", "b", "m", ""]], "trade", "XBT/USD"], [0, {"a": [["55001.00000", "1.00000000", "1699999999.1234"]], "c": "1234"}, "book-10", "XBT/USD"], [0, [["55000.00000", "0.01000000", "1699999999.1234", "b", "m", ""]], "trade", "XBT/USD"], [0, {"a": [["55001.00000", "1.00000000", "1699999999.1234"]], "c": "1234"}, "book-10", "XBT/USD"], [0, [["55000.00000", "0.01000000", "1699999999.1234", "b", "m", ""]], "trade", "XBT/USD"], [0, {"a": [["55001.00000", "1.00000000", "1699999999.1234"]], "c": "1234"}, "book-10", "XBT/USD"], [0, [["55000.00000", "0.01000000", "1699999999.1234", "b", "m", ""]], "trade", "XBT/USD"], [0, {"a": [["55001.00000", "1.00000000", "1699999999.1234"]], "c": "1234"}, "book-10", "XBT/USD"], [0, [["55000.00000", "0.01000000", "1699999999.1234", "b", "m", ""]], "trade", "XBT/USD"], [0, {"a": [["55001.00000", "1.00000000", "1699999999.1234"]], "c": "1234"}, "book-10", "XBT/USD"], [0, [["55000.00000", "0.01000000", "1699999999.1234", "b", "m", ""]], "trade", "XBT/USD"], [0, {"a": [["55001.00000", "1.00000000", "1699999999.1234"]], "c": "1234"}, "book-10", "XBT/USD"], [0, [["55000.00000", "0.01000000", "1699999999.1234", "b", "m", ""]], "trade", "XBT/USD"], [0, {"a": [["55001.00000", "1.00000000", "1699999999.1234"]], "c": "1234"}, "book-10", "XBT/USD"], [0, [["55000.00000", "0.01000000", "1699999999.1234", "b", "m", ""]], "trade", "XBT/USD"], [0, {"a": [["55001.00000", "1.00000000", "1699999999.1234"]], "c": "1234"}, "book-10", "XBT/USD"], [0, [["55000.00000", "0.01000000", "1699999999.1234", "b", "m", ""]], "trade", "XBT/USD"], [0, {"a": [["55001.00000", "1.00000000", "1699999999.1234"]], "c": "1234"}, "book-10", "XBT/USD"], [0, [["55000.00000", "0.01000000", "1699999999.1234", "b", "m", ""]], "trade", "XBT/USD"], [0, {"a": [["55001.00000", "1.00000000", "1699999999.1234"]], "c": "1234"}, "book-10", "XBT/USD"], [0, [["55000.00000", "0.01000000", "1699999999.1234", "b", "m", ""]], "trade", "XBT/USD"], [0, {"a": [["55001.00000", "1.00000000", "1699999999.1234"]], "c": "1234"}, "book-10", "XBT/USD"], [0, [["55000.00000", "0.01000000", "1699999999.1234", "b", "m", ""]], "trade", "XBT/USD"], [0, {"a": [["55001.00000", "1.00000000", "1699999999.1234"]], "c": "1234"}, "book-10", "XBT/USD"], [0, [["55000.00000", "0.01000000", "1699999999.1234", "b", "m", ""]], "trade", "XBT/USD"], [0, {"a": [["55001.00000", "1.00000000", "1699999999.1234"]], "c": "1234"}, "book-10", "XBT/USD"], [0, [["55000.00000", "0.01000000", "1699999999.1234", "b", "m", ""]], "trade", "XBT/USD"], [0, {"a": [["55001.00000", "1.00000000", "1699999999.1234"]], "c": "1234"}, "book-10", "XBT/USD"], [0, [["55000.00000", "0.01000000", "1699999999.1234", "b", "m", ""]], "trade", "XBT/USD"], [0, {"a": [["55001.00000", "1.00000000", "1699999999.1234"]], "c": "1234"}, "book-10", "XBT/USD"], [0, [["55000.00000", "0.01000000", "1699999999.1234", "b", "m", ""]], "trade", "XBT/USD"], [0, {"a": [["55001.00000", "1.00000000", "1699999999.1234"]], "c": "1234"}, "book-10", "XBT/USD"], [0, [["55000.00000", "0.01000000", "1699999999.1234", "b", "m", ""]], "trade", "XBT/USD"], [0, {"a": [["55001.00000", "1.00000000", "1699999999.1234"]], "c": "1234"}, "book-10", "XBT/USD"], [0, [["55000.00000", "0.01000000", "1699999999.1234", "b", "m", ""]], "trade", "XBT/USD"], [0, {"a": [["55001.00000", "1.00000000", "1699999999.1234"]], "c": "1234"}, "book-10", "XBT/USD"], [0, [["55000.00000", "0.01000000", "1699999999.1234", "b", "m", ""]], "trade", "XBT/USD"], [0, {"a": [["55001.00000", "1.00000000", "1699999999.1234"]], "c": "1234"}, "book-10", "XBT/USD"], [0, [["55000.00000", "0.01000000", "1699999999.1234", "b", "m", ""]], "trade", "XBT/USD"], [0, {"a": [["55001.00000", "1.00000000", "1699999999.1234"]], "c": "1234"}, "book-10", "XBT/USD"], [0, [["55000.00000", "0.01000000", "1699999999.1234", "b", "m", ""]], "trade", "XBT/USD"], [0, {"a": [["55001.00000", "1.00000000", "1699999999.1234"]], "c": "1234"}, "book-10", "XBT/USD"], [0, [["55000.00000", "0.01000000", "1699999999.1234", "b", "m", ""]], "trade", "XBT/USD"], [0, {"a": [["55001.00000", "1.00000000", "1699999999.1234"]], "c": "1234"}, "book-10", "XBT/USD"], [0, [["55000.00000", "0.01000000", "1699999999.1234", "b", "m", ""]], "trade", "XBT/USD"], [0, {"a": [["55001.00000", "1.00000000", "1699999999.1234"]], "c": "1234"}, "book-10", "XBT/USD"], [0, [["55000.00000", "0.01000000", "1699999999.1234", "b", "m", ""]], "trade", "XBT/USD"], [0, {"a": [["55001.00000", "1.00000000", "1699999999.1234"]], "c": "1234"}, "book-10", "XBT/USD"], [0, [["55000.00000", "0.01000000", "1699999999.1234", "b", "m", ""]], "trade", "XBT/USD"], [0, {"a": [["55001.00000", "1.00000000", "1699999999.1234"]], "c": "1234"}, "book-10", "XBT/USD"], [0, [["55000.00000", "0.01000000", "1699999999.1234", "b", "m", ""]], "trade", "XBT/USD"], [0, {"a": [["55001.00000", "1.00000000", "1699999999.1234"]], "c": "1234"}, "book-10", "XBT/USD"], [0, [["55000.00000", "0.01000000", "1699999999.1234", "b", "m", ""]], "trade", "XBT/USD"], [0, {"a": [["55001.00000", "1.00000000", "1699999999.1234"]], "c": "1234"}, "book-10", "XBT/USD"], [0, [["55000.00000", "0.01000000", "1699999999.1234", "b", "m", ""]], "trade", "XBT/USD"], [0, {"a": [["55001.00000", "1.00000000", "1699999999.1234"]], "c": "1234"}, "book-10", "XBT/USD"], [0, [["55000.00000", "0.01000000", "1699999999.1234", "b", "m", ""]], "trade", "XBT/USD"], [0, {"a": [["55001.00000", "1.00000000", "1699999999.1234"]], "c": "1234"}, "book-10", "XBT/USD"], [0, [["55000.00000", "0.01000000", "1699999999.1234", "b", "m", ""]], "trade", "XBT/USD"], [0, {"a": [["55001.00000", "1.00000000", "1699999999.1234"]], "c": "1234"}, "book-10", "XBT/USD"], [0, [["55000.00000", "0.01000000", "1699999999.1234", "b", "m", ""]], "trade", "XBT/USD"], [0, {"a": [["55001.00000", "1.00000000", "1699999999.1234"]], "c": "1234"}, "book-10", "XBT/USD"], [0, [["55000.00000", "0.01000000", "1699999999.1234", "b", "m", ""]], "trade", "XBT/USD"], [0, {"a": [["55001.00000", "1.00000000", "1699999999.1234"]], "c": "1234"}, "book-10", "XBT/USD"], [0, [["55000.00000", "0.01000000", "1699999999.1234", "b", "m", ""]], "trade", "XBT/USD"], [0, {"a": [["55001.00000", "1.00000000", "1699999999.1234"]], "c": "1234"}, "book-10", "XBT/USD"], [0, [["55000.00000", "0.01000000", "1699999999.1234", "b", "m", ""]], "trade", "XBT/USD"], [0, {"a": [["55001.00000", "1.00000000", "1699999999.1234"]], "c": "1234"}, "book-10", "XBT/USD"], [0, [["55000.00000", "0.01000000", "1699999999.1234", "b", "m", ""]], "trade", "XBT/USD"], [0, {"a": [["55001.00000", "1.00000000", "1699999999.1234"]], "c": "1234"}, "book-10", "XBT/USD"], [0, [["55000.00000", "0.01000000", "1699999999.1234", "b", "m", ""]], "trade", "XBT/USD"], [0, {"a": [["55001.00000", "1.00000000", "1699999999.1234"]], "c": "1234"}, "book-10", "XBT/USD"], [0, [["55000.00000", "0.01000000", "1699999999.1234", "b", "m", ""]], "trade", "XBT/USD"], [0, {"a": [["55001.00000", "1.00000000", "1699999999.1234"]], "c": "1234"}, "book-10", "XBT/USD"], [0, [["55000.00000", "0.01000000", "1699999999.1234", "b", "m", ""]], "trade", "XBT/USD"], [0, {"a": [["55001.00000", "1.00000000", "1699999999.1234"]], "c": "1234"}, "book-10", "XBT/USD"], [0, [["55000.00000", "0.01000000", "1699999999.1234", "b", "m", ""]], "trade", "XBT/USD"], [0, {"a": [["55001.00000", "1.00000000", "1699999999.1234"]], "c": "1234"}, "book-10", "XBT/USD"], [0, [["55000.00000", "0.01000000", "1699999999.1234", "b", "m", ""]], "trade", "XBT/USD"], [0, {"a": [["55001.00000", "1.00000000", "1699999999.1234"]], "c": "1234"}, "book-10", "XBT/USD"], [0, [["55000.00000", "0.01000000", "1699999999.1234", "b", "m", ""]], "trade", "XBT/USD"], [0, {"a": [["55001.00000", "1.00000000", "1699999999.1234"]], "c": "1234"}, "book-10", "XBT/USD"], [0, [["55000.00000", "0.01000000", "1699999999.1234", "b", "m", ""]], "trade", "XBT/USD"], [0, {"a": [["55001.00000", "1.00000000", "1699999999.1234"]], "c": "1234"}, "book-10", "XBT/USD"], [0, [["55000.00000", "0.01000000", "1699999999.1234", "b", "m", ""]], "trade", "XBT/USD"], [0, {"a": [["55001.00000", "1.00000000", "1699999999.1234"]], "c": "1234"}, "book-10", "XBT/USD"], [0, [["55000.00000", "0.01000000", "1699999999.1234", "b", "m", ""]], "trade", "XBT/USD"], [0, {"a": [["55001.00000", "1.00000000", "1699999999.1234"]], "c": "1234"}, "book-10", "XBT/USD"], [0, [["55000.00000", "0.01000000", "1699999999.1234", "b", "m", ""]], "trade", "XBT/USD"], [0, {"a": [["55001.00000", "1.00000000", "1699999999.1234"]], "c": "1234"}, "book-10", "XBT/USD"], [0, [["55000.00000", "0.01000000", "1699999999.1234", "b", "m", ""]], "trade", "XBT/USD"], [0, {"a": [["55001.00000", "1.00000000", "1699999999.1234"]], "c": "1234"}, "book-10", "XBT/USD"], [0, [["55000.00000", "0.01000000", "1699999999.1234", "b", "m", ""]], "trade", "XBT/USD"], [0, {"a": [["55001.00000", "1.00000000", "1699999999.1234"]], "c": "1234"}, "book-10", "XBT/USD"], [0, [["55000.00000", "0.01000000", "1699999999.1234", "b", "m", ""]], "trade", "XBT/USD"], [0, {"a": [["55001.00000", "1.00000000", "1699999999.1234"]], "c": "1234"}, "book-10", "XBT/USD"], [0, [["55000.00000", "0.01000000", "1699999999.1234", "b", "m", ""]], "trade", "XBT/USD"], [0, {"a": [["55001.00000", "1.00000000", "1699999999.1234"]], "c": "1234"}, "book-10", "XBT/USD"], [0, [["55000.00000", "0.01000000", "1699999999.1234", "b", "m", ""]], "trade", "XBT/USD"], [0, {"a": [["55001.00000", "1.00000000", "1699999999.1234"]], "c": "1234"}, "book-10", "XBT/USD"], [0, [["55000.00000", "0.01000000", "1699999999.1234", "b", "m", ""]], "trade", "XBT/USD"], [0, {"a": [["55001.00000", "1.00000000", "1699999999.1234"]], "c": "1234"}, "book-10", "XBT/USD"], [0, [["55000.00000", "0.01000000", "1699999999.1234", "b", "m", ""]], "trade", "XBT/USD"], [0, {"a": [["55001.00000", "1.00000000", "1699999999.1234"]], "c": "1234"}, "book-10", "XBT/USD"], [0, [["55000.00000", "0.01000000", "1699999999.1234", "b", "m", ""]], "trade", "XBT/USD"], [0, {"a": [["55001.00000", "1.00000000", "1699999999.1234"]], "c": "1234"}, "book-10", "XBT/USD"], [0, [["55000.00000", "0.01000000", "1699999999.1234", "b", "m", ""]], "trade", "XBT/USD"], [0, {"a": [["55001.00000", "1.00000000", "1699999999.1234"]], "c": "1234"}, "book-10", "XBT/USD"], [0, [["55000.00000", "0.01000000", "1699999999.1234", "b", "m", ""]], "trade", "XBT/USD"], [0, {"a": [["55001.00000", "1.00000000", "1699999999.1234"]], "c": "1234"}, "book-10", "XBT/USD"], [0, [["55000.00000", "0.01000000", "1699999999.1234", "b", "m", ""]], "trade", "XBT/USD"], [0, {"a": [["55001.00000", "1.00000000", "1699999999.1234"]], "c": "1234"}, "book-10", "XBT/USD"], [0, [["55000.00000", "0.01000000", "1699999999.1234", "b", "m", ""]], "trade", "XBT/USD"], [0, {"a": [["55001.00000", "1.00000000", "1699999999.1234"]], "c": "1234"}, "book-10", "XBT/USD"], [0, [["55000.00000", "0.01000000", "1699999999.1234", "b", "m", ""]], "trade", "XBT/USD"], [0, {"a": [["55001.00000", "1.00000000", "1699999999.1234"]], "c": "1234"}, "book-10", "XBT/USD"], [0, [["55000.00000", "0.01000000", "1699999999.1234", "b", "m", ""]], "trade", "XBT/USD"], [0, {"a": [["55001.00000", "1.00000000", "1699999999.1234"]], "c": "1234"}, "book-10", "XBT/USD"], [0, [["55000.00000", "0.01000000", "1699999999.1234", "b", "m", ""]], "trade", "XBT/USD"], [0, {"a": [["55001.00000", "1.00000000", "1699999999.1234"]], "c": "1234"}, "book-10", "XBT/USD"], [0, [["55000.00000", "0.01000000", "1699999999.1234", "b", "m", ""]], "trade", "XBT/USD"], [0, {"a": [["55001.00000", "1.00000000", "1699999999.1234"]], "c": "1234"}, "book-10", "XBT/USD"], [0, [["55000.00000", "0.01000000", "1699999999.1234", "b", "m", ""]], "trade", "XBT/USD"], [0, {"a": [["55001.00000", "1.00000000", "1699999999.1234"]], "c": "1234"}, "book-10", "XBT/USD"], [0, [["55000.00000", "0.01000000", "1699999999.1234", "b", "m", ""]], "trade", "XBT/USD"], [0, {"a": [["55001.00000", "1.00000000", "1699999999.1234"]], "c": "1234"}, "book-10", "XBT/USD"], [0, [["55000.00000", "0.01000000", "1699999999.1234", "b", "m", ""]], "trade", "XBT/USD"], [0, {"a": [["55001.00000", "1.00000000", "1699999999.1234"]], "c": "1234"}, "book-10", "XBT/USD"], [0, [["55000.00000", "0.01000000", "1699999999.1234", "b", "m", ""]], "trade", "XBT/USD"], [0, {"a": [["55001.00000", "1.00000000", "1699999999.1234"]], "c": "1234"}, "book-10", "XBT/USD"], [0, [["55000.00000", "0.01000000", "1699999999.1234", "b", "m", ""]], "trade", "XBT/USD"], [0, {"a": [["55001.00000", "1.00000000", "1699999999.1234"]], "c": "1234"}, "book-10", "XBT/USD"], [0, [["55000.00000", "0.01000000", "1699999999.1234", "b", "m", ""]], "trade", "XBT/USD"], [0, {"a": [["55001.00000", "1.00000000", "1699999999.1234"]], "c": "1234"}, "book-10", "XBT/USD"], [0, [["55000.00000", "0.01000000", "1699999999.1234", "b", "m", ""]], "trade", "XBT/USD"], [0, {"a": [["55001.00000", "1.00000000", "1699999999.1234"]], "c": "1234"}, "book-10", "XBT/USD"], [0, [["55000.00000", "0.01000000", "1699999999.1234", "b", "m", ""]], "trade", "XBT/USD"], [0, {"a": [["55001.00000", "1.00000000", "1699999999.1234"]], "c": "1234"}, "book-10", "XBT/USD"], [0, [["55000.00000", "0.01000000", "1699999999.1234", "b", "m", ""]], "trade", "XBT/USD"], [0, {"a": [["55001.00000", "1.00000000", "1699999999.1234"]], "c": "1234"}, "book-10", "XBT/USD"], [0, [["55000.00000", "0.01000000", "1699999999.1234", "b", "m", ""]], "trade", "XBT/USD"], [0, {"a": [["55001.00000", "1.00000000", "1699999999.1234"]], "c": "1234"}, "book-10", "XBT/USD"], [0, [["55000.00000", "0.01000000", "1699999999.1234", "b", "m", ""]], "trade", "XBT/USD"], [0, {"a": [["55001.00000", "1.00000000", "1699999999.1234"]], "c": "1234"}, "book-10", "XBT/USD"], [0, [["55000.00000", "0.01000000", "1699999999.1234", "b", "m", ""]], "trade", "XBT/USD"], [0, {"a": [["55001.00000", "1.00000000", "1699999999.1234"]], "c": "1234"}, "book-10", "XBT/USD"], [0, [["55000.00000", "0.01000000", "1699999999.1234", "b", "m", ""]], "trade", "XBT/USD"], [0, {"a": [["55001.00000", "1.00000000", "1699999999.1234"]], "c": "1234"}, "book-10", "XBT/USD"], [0, [["55000.00000", "0.01000000", "1699999999.1234", "b", "m", ""]], "trade", "XBT/USD"], [0, {"a": [["55001.00000", "1.00000000", "1699999999.1234"]], "c": "1234"}, "book-10", "XBT/USD"], [0, [["55000.00000", "0.01000000", "1699999999.1234", "b", "m", ""]], "trade", "XBT/USD"], [0, {"a": [["55001.00000", "1.00000000", "1699999999.1234"]], "c": "1234"}, "book-10", "XBT/USD"], [0, [["55000.00000", "0.01000000", "1699999999.1234", "b", "m", ""]], "trade", "XBT/USD"], [0, {"a": [["55001.00000", "1.00000000", "1699999999.1234"]], "c": "1234"}, "book-10", "XBT/USD"], [0, [["55000.00000", "0.01000000", "1699999999.1234", "b", "m", ""]], "trade", "XBT/USD"], [0, {"a": [["55001.00000", "1.00000000", "1699999999.1234"]], "c": "1234"}, "book-10", "XBT/USD"], [0, [["55000.00000", "0.01000000", "1699999999.1234", "b", "m", ""]], "trade", "XBT/USD"], [0, {"a": [["55001.00000", "1.00000000", "1699999999.1234"]], "c": "1234"}, "book-10", "XBT/USD"], [0, [["55000.00000", "0.01000000", "1699999999.1234", "b", "m", ""]], "trade", "XBT/USD"], [0, {"a": [["55001.00000", "1.00000000", "1699999999.1234"]], "c": "1234"}, "book-10", "XBT/USD"], [0, [["55000.00000", "0.01000000", "1699999999.1234", "b", "m", ""]], "trade", "XBT/USD"], [0, {"a": [["55001.00000", "1.00000000", "1699999999.1234"]], "c": "1234"}, "book-10", "XBT/USD"], [0, [["55000.00000", "0.01000000", "1699999999.1234", "b", "m", ""]], "trade", "XBT/USD"], [0, {"a": [["55001.00000", "1.00000000", "1699999999.1234"]], "c": "1234"}, "book-10", "XBT/USD"], [0, [["55000.00000", "0.01000000", "1699999999.1234", "b", "m", ""]], "trade", "XBT/USD"], [0, {"a": [["55001.00000", "1.00000000", "1699999999.1234"]], "c": "1234"}, "book-10", "XBT/USD"], [0, [["55000.00000", "0.01000000", "1699999999.1234", "b", "m", ""]], "trade", "XBT/USD"], [0, {"a": [["55001.00000", "1.00000000", "1699999999.1234"]], "c": "1234"}, "book-10", "XBT/USD"], [0, [["55000.00000", "0.01000000", "1699999999.1234", "b", "m", ""]], "trade", "XBT/USD"], [0, {"a": [["55001.00000", "1.00000000", "1699999999.1234"]], "c": "1234"}, "book-10", "XBT/USD"], [0, [["55000.00000", "0.01000000", "1699999999.1234", "b", "m", ""]], "trade", "XBT/USD"], [0, {"a": [["55001.00000", "1.00000000", "1699999999.1234"]], "c": "1234"}, "book-10", "XBT/USD"], [0, [["55000.00000", "0.01000000", "1699999999.1234", "b", "m", ""]], "trade", "XBT/USD"], [0, {"a": [["55001.00000", "1.00000000", "1699999999.1234"]], "c": "1234"}, "book-10", "XBT/USD"], [0, [["55000.00000", "0.01000000", "1699999999.1234", "b", "m", ""]], "trade", "XBT/USD"], [0, {"a": [["55001.00000", "1.00000000", "1699999999.1234"]], "c": "1234"}, "book-10", "XBT/USD"], [0, [["55000.00000", "0.01000000", "1699999999.1234", "b", "m", ""]], "trade", "XBT/USD"], [0, {"a": [["55001.00000", "1.00000000", "1699999999.1234"]], "c": "1234"}, "book-10", "XBT/USD"], [0, [["55000.00000", "0.01000000", "1699999999.1234", "b", "m", ""]], "trade", "XBT/USD"], [0, {"a": [["55001.00000", "1.00000000", "1699999999.1234"]], "c": "1234"}, "book-10", "XBT/USD"], [0, [["55000.00000", "0.01000000", "1699999999.1234", "b", "m", ""]], "trade", "XBT/USD"], [0, {"a": [["55001.00000", "1.00000000", "1699999999.1234"]], "c": "1234"}, "book-10", "XBT/USD"], [0, [["55000.00000", "0.01000000", "1699999999.1234", "b", "m", ""]], "trade", "XBT/USD"], [0, {"a": [["55001.00000", "1.00000000", "1699999999.1234"]], "c": "1234"}, "book-10", "XBT/USD"], [0, [["55000.00000", "0.01000000", "1699999999.1234", "b", "m", ""]], "trade", "XBT/USD"], [0, {"a": [["55001.00000", "1.00000000", "1699999999.1234"]], "c": "1234"}, "book-10", "XBT/USD"], [0, [["55000.00000", "0.01000000", "1699999999.1234", "b", "m", ""]], "trade", "XBT/USD"], [0, {"a": [["55001.00000", "1.00000000", "1699999999.1234"]], "c": "1234"}, "book-10", "XBT/USD"], [0, [["55000.00000", "0.01000000", "1699999999.1234", "b", "m", ""]], "trade", "XBT/USD"], [0, {"a": [["55001.00000", "1.00000000", "1699999999.1234"]], "c": "1234"}, "book-10", "XBT/USD"], [0, [["55000.00000", "0.01000000", "1699999999.1234", "b", "m", ""]], "trade", "XBT/USD"], [0, {"a": [["55001.00000", "1.00000000", "1699999999.1234"]], "c": "1234"}, "book-10", "XBT/USD"], [0, [["55000.00000", "0.01000000", "1699999999.1234", "b", "m", ""]], "trade", "XBT/USD"], [0, {"a": [["55001.00000", "1.00000000", "1699999999.1234"]], "c": "1234"}, "book-10", "XBT/USD"], [0, [["55000.00000", "0.01000000", "1699999999.1234", "b", "m", ""]], "trade", "XBT/USD"], [0, {"a": [["55001.00000", "1.00000000", "1699999999.1234"]], "c": "1234"}, "book-10", "XBT/USD"], [0, [["55000.00000", "0.01000000", "1699999999.1234", "b", "m", ""]], "trade", "XBT/USD"], [0, {"a": [["55001.00000", "1.00000000", "1699999999.1234"]], "c": "1234"}, "book-10", "XBT/USD"], [0, [["55000.00000", "0.01000000", "1699999999.1234", "b", "m", ""]], "trade", "XBT/USD"], [0, {"a": [["55001.00000", "1.00000000", "1699999999.1234"]], "c": "1234"}, "book-10", "XBT/USD"], [0, [["55000.00000", "0.01000000", "1699999999.1234", "b", "m", ""]], "trade", "XBT/USD"], [0, {"a": [["55001.00000", "1.00000000", "1699999999.1234"]], "c": "1234"}, "book-10", "XBT/USD"], [0, [["55000.00000", "0.01000000", "1699999999.1234", "b", "m", ""]], "trade", "XBT/USD"], [0, {"a": [["55001.00000", "1.00000000", "1699999999.1234"]], "c": "1234"}, "book-10", "XBT/USD"], [0, [["55000.00000", "0.01000000", "1699999999.1234", "b", "m", ""]], "trade", "XBT/USD"], [0, {"a": [["55001.00000", "1.00000000", "1699999999.1234"]], "c": "1234"}, "book-10", "XBT/USD"], [0, [["55000.00000", "0.01000000", "1699999999.1234", "b", "m", ""]], "trade", "XBT/USD"], [0, {"a": [["55001.00000", "1.00000000", "1699999999.1234"]], "c": "1234"}, "book-10", "XBT/USD"], [0, [["55000.00000", "0.01000000", "1699999999.1234", "b", "m", ""]], "trade", "XBT/USD"], [0, {"a": [["55001.00000", "1.00000000", "1699999999.1234"]], "c": "1234"}, "book-10", "XBT/USD"], [0, [["55000.00000", "0.01000000", "1699999999.1234", "b", "m", ""]], "trade", "XBT/USD"], [0, {"a": [["55001.00000", "1.00000000", "1699999999.1234"]], "c": "1234"}, "book-10", "XBT/USD"], [0, [["55000.00000", "0.01000000", "1699999999.1234", "b", "m", ""]], "trade", "XBT/USD"], [0, {"a": [["55001.00000", "1.00000000", "1699999999.1234"]], "c": "1234"}, "book-10", "XBT/USD"], [0, [["55000.00000", "0.01000000", "1699999999.1234", "b", "m", ""]], "trade", "XBT/USD"], [0, {"a": [["55001.00000", "1.00000000", "1699999999.1234"]], "c": "1234"}, "book-10", "XBT/USD"], [0, [["55000.00000", "0.01000000", "1699999999.1234", "b", "m", ""]], "trade", "XBT/USD"], [0, {"a": [["55001.00000", "1.00000000", "1699999999.1234"]], "c": "1234"}, "book-10", "XBT/USD"], [0, [["55000.00000", "0.01000000", "1699999999.1234", "b", "m", ""]], "trade", "XBT/USD"], [0, {"a": [["55001.00000", "1.00000000", "1699999999.1234"]], "c": "1234"}, "book-10", "XBT/USD"], [0, [["55000.00000", "0.01000000", "1699999999.1234", "b", "m", ""]], "trade", "XBT/USD"], [0, {"a": [["55001.00000", "1.00000000", "1699999999.1234"]], "c": "1234"}, "book-10", "XBT/USD"], [0, [["55000.00000", "0.01000000", "1699999999.1234", "b", "m", ""]], "trade", "XBT/USD"], [0, {"a": [["55001.00000", "1.00000000", "1699999999.1234"]], "c": "1234"}, "book-10", "XBT/USD"], [0, [["55000.00000", "0.01000000", "1699999999.1234", "b", "m", ""]], "trade", "XBT/USD"], [0, {"a": [["55001.00000", "1.00000000", "1699999999.1234"]], "c": "1234"}, "book-10", "XBT/USD"], [0, [["55000.00000", "0.01000000", "1699999999.1234", "b", "m", ""]], "trade", "XBT/USD"], [0, {"a": [["55001.00000", "1.00000000", "1699999999.1234"]], "c": "1234"}, "book-10", "XBT/USD"], [0, [["55000.00000", "0.01000000", "1699999999.1234", "b", "m", ""]], "trade", "XBT/USD"], [0, {"a": [["55001.00000", "1.00000000", "1699999999.1234"]], "c": "1234"}, "book-10", "XBT/USD"], [0, [["55000.00000", "0.01000000", "1699999999.1234", "b", "m", ""]], "trade", "XBT/USD"], [0, {"a": [["55001.00000", "1.00000000", "1699999999.1234"]], "c": "1234"}, "book-10", "XBT/USD"], [0, [["55000.00000", "0.01000000", "1699999999.1234", "b", "m", ""]], "trade", "XBT/USD"], [0, {"a": [["55001.00000", "1.00000000", "1699999999.1234"]], "c": "1234"}, "book-10", "XBT/USD"], [0, [["55000.00000", "0.01000000", "1699999999.1234", "b", "m", ""]], "trade", "XBT/USD"], [0, {"a": [["55001.00000", "1.00000000", "1699999999.1234"]], "c": "1234"}, "book-10", "XBT/USD"], [0, [["55000.00000", "0.01000000", "1699999999.1234", "b", "m", ""]], "trade", "XBT/USD"], [0, {"a": [["55001.00000", "1.00000000", "1699999999.1234"]], "c": "1234"}, "book-10", "XBT/USD"], [0, [["55000.00000", "0.01000000", "1699999999.1234", "b", "m", ""]], "trade", "XBT/USD"], [0, {"a": [["55001.00000", "1.00000000", "1699999999.1234"]], "c": "1234"}, "book-10", "XBT/USD"], [0, [["55000.00000", "0.01000000", "1699999999.1234", "b", "m", ""]], "trade", "XBT/USD"], [0, {"a": [["55001.00000", "1.00000000", "1699999999.1234"]], "c": "1234"}, "book-10", "XBT/USD"], [0, [["55000.00000", "0.01000000", "1699999999.1234", "b", "m", ""]], "trade", "XBT/USD"], [0, {"a": [["55001.00000", "1.00000000", "1699999999.1234"]], "c": "1234"}, "book-10", "XBT/USD"], [0, [["55000.00000", "0.01000000", "1699999999.1234", "b", "m", ""]], "trade", "XBT/USD"], [0, {"a": [["55001.00000", "1.00000000", "1699999999.1234"]], "c": "1234"}, "book-10", "XBT/USD"], [0, [["55000.00000", "0.01000000", "1699999999.1234", "b", "m", ""]], "trade", "XBT/USD"], [0, {"a": [["55001.00000", "1.00000000", "1699999999.1234"]], "c": "1234"}, "book-10", "XBT/USD"], [0, [["55000.00000", "0.01000000", "1699999999.1234", "b", "m", ""]], "trade", "XBT/USD"], [0, {"a": [["55001.00000", "1.00000000", "1699999999.1234"]], "c": "1234"}, "book-10", "XBT/USD"], [0, [["55000.00000", "0.01000000", "1699999999.1234", "b", "m", ""]], "trade", "XBT/USD"], [0, {"a": [["55001.00000", "1.00000000", "1699999999.1234"]], "c": "1234"}, "book-10", "XBT/USD"], [0, [["55000.00000", "0.01000000", "1699999999.1234", "b", "m", ""]], "trade", "XBT/USD"], [0, {"a": [["55001.00000", "1.00000000", "1699999999.1234"]], "c": "1234"}, "book-10", "XBT/USD"], [0, [["55000.00000", "0.01000000", "1699999999.1234", "b", "m", ""]], "trade", "XBT/USD"], [0, {"a": [["55001.00000", "1.00000000", "1699999999.1234"]], "c": "1234"}, "book-10", "XBT/USD"], [0, [["55000.00000", "0.01000000", "1699999999.1234", "b", "m", ""]], "trade", "XBT/USD"], [0, {"a": [["55001.00000", "1.00000000", "1699999999.1234"]], "c": "1234"}, "book-10", "XBT/USD"], [0, [["55000.00000", "0.01000000", "1699999999.1234", "b", "m", ""]], "trade", "XBT/USD"], [0, {"a": [["55001.00000", "1.00000000", "1699999999.1234"]], "c": "1234"}, "book-10", "XBT/USD"], [0, [["55000.00000", "0.01000000", "1699999999.1234", "b", "m", ""]], "trade", "XBT/USD"], [0, {"a": [["55001.00000", "1.00000000", "1699999999.1234"]], "c": "1234"}, "book-10", "XBT/USD"], [0, [["55000.00000", "0.01000000", "1699999999.1234", "b", "m", ""]], "trade", "XBT/USD"], [0, {"a": [["55001.00000", "1.00000000", "1699999999.1234"]], "c": "1234"}, "book-10", "XBT/USD"], [0, [["55000.00000", "0.01000000", "1699999999.1234", "b", "m", ""]], "trade", "XBT/USD"], [0, {"a": [["55001.00000", "1.00000000", "1699999999.1234"]], "c": "1234"}, "book-10", "XBT/USD"], [0, [["55000.00000", "0.01000000", "1699999999.1234", "b", "m", ""]], "trade", "XBT/USD"], [0, {"a": [["55001.00000", "1.00000000", "1699999999.1234"]], "c": "1234"}, "book-10", "XBT/USD"], [0, [["55000.00000", "0.01000000", "1699999999.1234", "b", "m", ""]], "trade", "XBT/USD"], [0, {"a": [["55001.00000", "1.00000000", "1699999999.1234"]], "c": "1234"}, "book-10", "XBT/USD"], [0, [["55000.00000", "0.01000000", "1699999999.1234", "b", "m", ""]], "trade", "XBT/USD"], [0, {"a": [["55001.00000", "1.00000000", "1699999999.1234"]], "c": "1234"}, "book-10", "XBT/USD"], [0, [["55000.00000", "0.01000000", "1699999999.1234", "b", "m", ""]], "trade", "XBT/USD"], [0, {"a": [["55001.00000", "1.00000000", "1699999999.1234"]], "c": "1234"}, "book-10", "XBT/USD"], [0, [["55000.00000", "0.01000000", "1699999999.1234", "b", "m", ""]], "trade", "XBT/USD"], [0, {"a": [["55001.00000", "1.00000000", "1699999999.1234"]], "c": "1234"}, "book-10", "XBT/USD"], [0, [["55000.00000", "0.01000000", "1699999999.1234", "b", "m", ""]], "trade", "XBT/USD"], [0, {"a": [["55001.00000", "1.00000000", "1699999999.1234"]], "c": "1234"}, "book-10", "XBT/USD"], [0, [["55000.00000", "0.01000000", "1699999999.1234", "b", "m", ""]], "trade", "XBT/USD"], [0, {"a": [["55001.00000", "1.00000000", "1699999999.1234"]], "c": "1234"}, "book-10", "XBT/USD"], [0, [["55000.00000", "0.01000000", "1699999999.1234", "b", "m", ""]], "trade", "XBT/USD"], [0, {"a": [["55001.00000", "1.00000000", "1699999999.1234"]], "c": "1234"}, "book-10", "XBT/USD"], [0, [["55000.00000", "0.01000000", "1699999999.1234", "b", "m", ""]], "trade", "XBT/USD"], [0, {"a": [["55001.00000", "1.00000000", "1699999999.1234"]], "c": "1234"}, "book-10", "XBT/USD"], [0, [["55000.00000", "0.01000000", "1699999999.1234", "b", "m", ""]], "trade", "XBT/USD"], [0, {"a": [["55001.00000", "1.00000000", "1699999999.1234"]], "c": "1234"}, "book-10", "XBT/USD"], [0, [["55000.00000", "0.01000000", "1699999999.1234", "b", "m", ""]], "trade", "XBT/USD"], [0, {"a": [["55001.00000", "1.00000000", "1699999999.1234"]], "c": "1234"}, "book-10", "XBT/USD"], [0, [["55000.00000", "0.01000000", "1699999999.1234", "b", "m", ""]], "trade", "XBT/USD"], [0, {"a": [["55001.00000", "1.00000000", "1699999999.1234"]], "c": "1234"}, "book-10", "XBT/USD"], [0, [["55000.00000", "0.01000000", "1699999999.1234", "b", "m", ""]], "trade", "XBT/USD"], [0, {"a": [["55001.00000", "1.00000000", "1699999999.1234"]], "c": "1234"}, "book-10", "XBT/USD"], [0, [["55000.00000", "0.01000000", "1699999999.1234", "b", "m", ""]], "trade", "XBT/USD"], [0, {"a": [["55001.00000", "1.00000000", "1699999999.1234"]], "c": "1234"}, "book-10", "XBT/USD"], [0, [["55000.00000", "0.01000000", "1699999999.1234", "b", "m", ""]], "trade", "XBT/USD"], [0, {"a": [["55001.00000", "1.00000000", "1699999999.1234"]], "c": "1234"}, "book-10", "XBT/USD"], [0, [["55000.00000", "0.01000000", "1699999999.1234", "b", "m", ""]], "trade", "XBT/USD"], [0, {"a": [["55001.00000", "1.00000000", "1699999999.1234"]], "c": "1234"}, "book-10", "XBT/USD"], [0, [["55000.00000", "0.01000000", "1699999999.1234", "b", "m", ""]], "trade", "XBT/USD"], [0, {"a": [["55001.00000", "1.00000000", "1699999999.1234"]], "c": "1234"}, "book-10", "XBT/USD"], [0, [["55000.00000", "0.01000000", "1699999999.1234", "b", "m", ""]], "trade", "XBT/USD"], [0, {"a": [["55001.00000", "1.00000000", "1699999999.1234"]], "c": "1234"}, "book-10", "XBT/USD"], [0, [["55000.00000", "0.01000000", "1699999999.1234", "b", "m", ""]], "trade", "XBT/USD"], [0, {"a": [["55001.00000", "1.00000000", "1699999999.1234"]], "c": "1234"}, "book-10", "XBT/USD"], [0, [["55000.00000", "0.01000000", "1699999999.1234", "b", "m", ""]], "trade", "XBT/USD"], [0, {"a": [["55001.00000", "1.00000000", "1699999999.1234"]], "c": "1234"}, "book-10", "XBT/USD"], [0, [["55000.00000", "0.01000000", "1699999999.1234", "b", "m", ""]], "trade", "XBT/USD"], [0, {"a": [["55001.00000", "1.00000000", "1699999999.1234"]], "c": "1234"}, "book-10", "XBT/USD"], [0, [["55000.00000", "0.01000000", "1699999999.1234", "b", "m", ""]], "trade", "XBT/USD"], [0, {"a": [["55001.00000", "1.00000000", "1699999999.1234"]], "c": "1234"}, "book-10", "XBT/USD"], [0, [["55000.00000", "0.01000000", "1699999999.1234", "b", "m", ""]], "trade", "XBT/USD"], [0, {"a": [["55001.00000", "1.00000000", "1699999999.1234"]], "c": "1234"}, "book-10", "XBT/USD"], [0, [["55000.00000", "0.01000000", "1699999999.1234", "b", "m", ""]], "trade", "XBT/USD"], [0, {"a": [["55001.00000", "1.00000000", "1699999999.1234"]], "c": "1234"}, "book-10", "XBT/USD"], [0, [["55000.00000", "0.01000000", "1699999999.1234", "b", "m", ""]], "trade", "XBT/USD"], [0, {"a": [["55001.00000", "1.00000000", "1699999999.1234"]], "c": "1234"}, "book-10", "XBT/USD"], [0, [["55000.00000", "0.01000000", "1699999999.1234", "b", "m", ""]], "trade", "XBT/USD"], [0, {"a": [["55001.00000", "1.00000000", "1699999999.1234"]], "c": "1234"}, "book-10", "XBT/USD"], [0, [["55000.00000", "0.01000000", "1699999999.1234", "b", "m", ""]], "trade", "XBT/USD"], [0, {"a": [["55001.00000", "1.00000000", "1699999999.1234"]], "c": "1234"}, "book-10", "XBT/USD"], [0, [["55000.00000", "0.01000000", "1699999999.1234", "b", "m", ""]], "trade", "XBT/USD"], [0, {"a": [["55001.00000", "1.00000000", "1699999999.1234"]], "c": "1234"}, "book-10", "XBT/USD"], [0, [["55000.00000", "0.01000000", "1699999999.1234", "b", "m", ""]], "trade", "XBT/USD"], [0, {"a": [["55001.00000", "1.00000000", "1699999999.1234"]], "c": "1234"}, "book-10", "XBT/USD"], [0, [["55000.00000", "0.01000000", "1699999999.1234", "b", "m", ""]], "trade", "XBT/USD"], [0, {"a": [["55001.00000", "1.00000000", "1699999999.1234"]], "c": "1234"}, "book-10", "XBT/USD"], [0, [["55000.00000", "0.01000000", "1699999999.1234", "b", "m", ""]], "trade", "XBT/USD"], [0, {"a": [["55001.00000", "1.00000000", "1699999999.1234"]], "c": "1234"}, "book-10", "XBT/USD"], [0, [["55000.00000", "0.01000000", "1699999999.1234", "b", "m", ""]], "trade", "XBT/USD"], [0, {"a": [["55001.00000", "1.00000000", "1699999999.1234"]], "c": "1234"}, "book-10", "XBT/USD"], [0, [["55000.00000", "0.01000000", "1699999999.1234", "b", "m", ""]], "trade", "XBT/USD"], [0, {"a": [["55001.00000", "1.00000000", "1699999999.1234"]], "c": "1234"}, "book-10", "XBT/USD"], [0, [["55000.00000", "0.01000000", "1699999999.1234", "b", "m", ""]], "trade", "XBT/USD"], [0, {"a": [["55001.00000", "1.00000000", "1699999999.1234"]], "c": "1234"}, "book-10", "XBT/USD"], [0, [["55000.00000", "0.01000000", "1699999999.1234", "b", "m", ""]], "trade", "XBT/USD"], [0, {"a": [["55001.00000", "1.00000000", "1699999999.1234"]], "c": "1234"}, "book-10", "XBT/USD"], [0, [["55000.00000", "0.01000000", "1699999999.1234", "b", "m", ""]], "trade", "XBT/USD"], [0, {"a": [["55001.00000", "1.00000000", "1699999999.1234"]], "c": "1234"}, "book-10", "XBT/USD"], [0, [["55000.00000", "0.01000000", "1699999999.1234", "b", "m", ""]], "trade", "XBT/USD"], [0, {"a": [["55001.00000", "1.00000000", "1699999999.1234"]], "c": "1234"}, "book-10", "XBT/USD"], [0, [["55000.00000", "0.01000000", "1699999999.1234", "b", "m", ""]], "trade", "XBT/USD"], [0, {"a": [["55001.00000", "1.00000000", "1699999999.1234"]], "c": "1234"}, "book-10", "XBT/USD"], [0, [["55000.00000", "0.01000000", "1699999999.1234", "b", "m", ""]], "trade", "XBT/USD"], [0, {"a": [["55001.00000", "1.00000000", "1699999999.1234"]], "c": "1234"}, "book-10", "XBT/USD"], [0, [["55000.00000", "0.01000000", "1699999999.1234", "b", "m", ""]], "trade", "XBT/USD"], [0, {"a": [["55001.00000", "1.00000000", "1699999999.1234"]], "c": "1234"}, "book-10", "XBT/USD"], [0, [["55000.00000", "0.01000000", "1699999999.1234", "b", "m", ""]], "trade", "XBT/USD"], [0, {"a": [["55001.00000", "1.00000000", "1699999999.1234"]], "c": "1234"}, "book-10", "XBT/USD"], [0, [["55000.00000", "0.01000000", "1699999999.1234", "b", "m", ""]], "trade", "XBT/USD"], [0, {"a": [["55001.00000", "1.00000000", "1699999999.1234"]], "c": "1234"}, "book-10", "XBT/USD"], [0, [["55000.00000", "0.01000000", "1699999999.1234", "b", "m", ""]], "trade", "XBT/USD"], [0, {"a": [["55001.00000", "1.00000000", "1699999999.1234"]], "c": "1234"}, "book-10", "XBT/USD"], [0, [["55000.00000", "0.01000000", "1699999999.1234", "b", "m", ""]], "trade", "XBT/USD"], [0, {"a": [["55001.00000", "1.00000000", "1699999999.1234"]], "c": "1234"}, "book-10", "XBT/USD"], [0, [["55000.00000", "0.01000000", "1699999999.1234", "b", "m", ""]], "trade", "XBT/USD"], [0, {"a": [["55001.00000", "1.00000000", "1699999999.1234"]], "c": "1234"}, "book-10", "XBT/USD"], [0, [["55000.00000", "0.01000000", "1699999999.1234", "b", "m", ""]], "trade", "XBT/USD"], [0, {"a": [["55001.00000", "1.00000000", "1699999999.1234"]], "c": "1234"}, "book-10", "XBT/USD"], [0, [["55000.00000", "0.01000000", "1699999999.1234", "b", "m", ""]], "trade", "XBT/USD"], [0, {"a": [["55001.00000", "1.00000000", "1699999999.1234"]], "c": "1234"}, "book-10", "XBT/USD"], [0, [["55000.00000", "0.01000000", "1699999999.1234", "b", "m", ""]], "trade", "XBT/USD"], [0, {"a": [["55001.00000", "1.00000000", "1699999999.1234"]], "c": "1234"}, "book-10", "XBT/USD"], [0, [["55000.00000", "0.01000000", "1699999999.1234", "b", "m", ""]], "trade", "XBT/USD"], [0, {"a": [["55001.00000", "1.00000000", "1699999999.1234"]], "c": "1234"}, "book-10", "XBT/USD"], [0, [["55000.00000", "0.01000000", "1699999999.1234", "b", "m", ""]], "trade", "XBT/USD"], [0, {"a": [["55001.00000", "1.00000000", "1699999999.1234"]], "c": "1234"}, "book-10", "XBT/USD"], [0, [["55000.00000", "0.01000000", "1699999999.1234", "b", "m", ""]], "trade", "XBT/USD"], [0, {"a": [["55001.00000", "1.00000000", "1699999999.1234"]], "c": "1234"}, "book-10", "XBT/USD"], [0, [["55000.00000", "0.01000000", "1699999999.1234", "b", "m", ""]], "trade", "XBT/USD"], [0, {"a": [["55001.00000", "1.00000000", "1699999999.1234"]], "c": "1234"}, "book-10", "XBT/USD"], [0, [["55000.00000", "0.01000000", "1699999999.1234", "b", "m", ""]], "trade", "XBT/USD"], [0, {"a": [["55001.00000", "1.00000000", "1699999999.1234"]], "c": "1234"}, "book-10", "XBT/USD"], [0, [["55000.00000", "0.01000000", "1699999999.1234", "b", "m", ""]], "trade", "XBT/USD"], [0, {"a": [["55001.00000", "1.00000000", "1699999999.1234"]], "c": "1234"}, "book-10", "XBT/USD"], [0, [["55000.00000", "0.01000000", "1699999999.1234", "b", "m", ""]], "trade", "XBT/USD"], [0, {"a": [["55001.00000", "1.00000000", "1699999999.1234"]], "c": "1234"}, "book-10", "XBT/USD"], [0, [["55000.00000", "0.01000000", "1699999999.1234", "b", "m", ""]], "trade", "XBT/USD"], [0, {"a": [["55001.00000", "1.00000000", "1699999999.1234"]], "c": "1234"}, "book-10", "XBT/USD"], [0, [["55000.00000", "0.01000000", "1699999999.1234", "b", "m", ""]], "trade", "XBT/USD"], [0, {"a": [["55001.00000", "1.00000000", "1699999999.1234"]], "c": "1234"}, "book-10", "XBT/USD"], [0, [["55000.00000", "0.01000000", "1699999999.1234", "b", "m", ""]], "trade", "XBT/USD"], [0, {"a": [["55001.00000", "1.00000000", "1699999999.1234"]], "c": "1234"}, "book-10", "XBT/USD"], [0, [["55000.00000", "0.01000000", "1699999999.1234", "b", "m", ""]], "trade", "XBT/USD"], [0, {"a": [["55001.00000", "1.00000000", "1699999999.1234"]], "c": "1234"}, "book-10", "XBT/USD"], [0, [["55000.00000", "0.01000000", "1699999999.1234", "b", "m", ""]], "trade", "XBT/USD"], [0, {"a": [["55001.00000", "1.00000000", "1699999999.1234"]], "c": "1234"}, "book-10", "XBT/USD"], [0, [["55000.00000", "0.01000000", "1699999999.1234", "b", "m", ""]], "trade", "XBT/USD"], [0, {"a": [["55001.00000", "1.00000000", "1699999999.1234"]], "c": "1234"}, "book-10", "XBT/USD"], [0, [["55000.00000", "0.01000000", "1699999999.1234", "b", "m", ""]], "trade", "XBT/USD"], [0, {"a": [["55001.00000", "1.00000000", "1699999999.1234"]], "c": "1234"}, "book-10", "XBT/USD"], [0, [["55000.00000", "0.01000000", "1699999999.1234", "b", "m", ""]], "trade", "XBT/USD"], [0, {"a": [["55001.00000", "1.00000000", "1699999999.1234"]], "c": "1234"}, "book-10", "XBT/USD"], [0, [["55000.00000", "0.01000000", "1699999999.1234", "b", "m", ""]], "trade", "XBT/USD"], [0, {"a": [["55001.00000", "1.00000000", "1699999999.1234"]], "c": "1234"}, "book-10", "XBT/USD"], [0, [["55000.00000", "0.01000000", "1699999999.1234", "b", "m", ""]], "trade", "XBT/USD"], [0, {"a": [["55001.00000", "1.00000000", "1699999999.1234"]], "c": "1234"}, "book-10", "XBT/USD"], [0, [["55000.00000", "0.01000000", "1699999999.1234", "b", "m", ""]], "trade", "XBT/USD"], [0, {"a": [["55001.00000", "1.00000000", "1699999999.1234"]], "c": "1234"}, "book-10", "XBT/USD"], [0, [["55000.00000", "0.01000000", "1699999999.1234", "b", "m", ""]], "trade", "XBT/USD"], [0, {"a": [["55001.00000", "1.00000000", "1699999999.1234"]], "c": "1234"}, "book-10", "XBT/USD"], [0, [["55000.00000", "0.01000000", "1699999999.1234", "b", "m", ""]], "trade", "XBT/USD"], [0, {"a": [["55001.00000", "1.00000000", "1699999999.1234"]], "c": "1234"}, "book-10", "XBT/USD"], [0, [["55000.00000", "0.01000000", "1699999999.1234", "b", "m", ""]], "trade", "XBT/USD"], [0, {"a": [["55001.00000", "1.00000000", "1699999999.1234"]], "c": "1234"}, "book-10", "XBT/USD"], [0, [["55000.00000", "0.01000000", "1699999999.1234", "b", "m", ""]], "trade", "XBT/USD"], [0, {"a": [["55001.00000", "1.00000000", "1699999999.1234"]], "c": "1234"}, "book-10", "XBT/USD"], [0, [["55000.00000", "0.01000000", "1699999999.1234", "b", "m", ""]], "trade", "XBT/USD"], [0, {"a": [["55001.00000", "1.00000000", "1699999999.1234"]], "c": "1234"}, "book-10", "XBT/USD"], [0, [["55000.00000", "0.01000000", "1699999999.1234", "b", "m", ""]], "trade", "XBT/USD"], [0, {"a": [["55001.00000", "1.00000000", "1699999999.1234"]], "c": "1234"}, "book-10", "XBT/USD"], [0, [["55000.00000", "0.01000000", "1699999999.1234", "b", "m", ""]], "trade", "XBT/USD"], [0, {"a": [["55001.00000", "1.00000000", "1699999999.1234"]], "c": "1234"}, "book-10", "XBT/USD"], [0, [["55000.00000", "0.01000000", "1699999999.1234", "b", "m", ""]], "trade", "XBT/USD"], [0, {"a": [["55001.00000", "1.00000000", "1699999999.1234"]], "c": "1234"}, "book-10", "XBT/USD"], [0, [["55000.00000", "0.01000000", "1699999999.1234", "b", "m", ""]], "trade", "XBT/USD"], [0, {"a": [["55001.00000", "1.00000000", "1699999999.1234"]], "c": "1234"}, "book-10", "XBT/USD"], [0, [["55000.00000", "0.01000000", "1699999999.1234", "b", "m", ""]], "trade", "XBT/USD"], [0, {"a": [["55001.00000", "1.00000000", "1699999999.1234"]], "c": "1234"}, "book-10", "XBT/USD"], [0, [["55000.00000", "0.01000000", "1699999999.1234", "b", "m", ""]], "trade", "XBT/USD"], [0, {"a": [["55001.00000", "1.00000000", "1699999999.1234"]], "c": "1234"}, "book-10", "XBT/USD"], [0, [["55000.00000", "0.01000000", "1699999999.1234", "b", "m", ""]], "trade", "XBT/USD"], [0, {"a": [["55001.00000", "1.00000000", "1699999999.1234"]], "c": "1234"}, "book-10", "XBT/USD"], [0, [["55000.00000", "0.01000000", "1699999999.1234", "b", "m", ""]], "trade", "XBT/USD"], [0, {"a": [["55001.00000", "1.00000000", "1699999999.1234"]], "c": "1234"}, "book-10", "XBT/USD"], [0, [["55000.00000", "0.01000000", "1699999999.1234", "b", "m", ""]], "trade", "XBT/USD"], [0, {"a": [["55001.00000", "1.00000000", "1699999999.1234"]], "c": "1234"}, "book-10", "XBT/USD"], [0, [["55000.00000", "0.01000000", "1699999999.1234", "b", "m", ""]], "trade", "XBT/USD"], [0, {"a": [["55001.00000", "1.00000000", "1699999999.1234"]], "c": "1234"}, "book-10", "XBT/USD"], [0, [["55000.00000", "0.01000000", "1699999999.1234", "b", "m", ""]], "trade", "XBT/USD"], [0, {"a": [["55001.00000", "1.00000000", "1699999999.1234"]], "c": "1234"}, "book-10", "XBT/USD"], [0, [["55000.00000", "0.01000000", "1699999999.1234", "b", "m", ""]], "trade", "XBT/USD"], [0, {"a": [["55001.00000", "1.00000000", "1699999999.1234"]], "c": "1234"}, "book-10", "XBT/USD"], [0, [["55000.00000", "0.01000000", "1699999999.1234", "b", "m", ""]], "trade", "XBT/USD"], [0, {"a": [["55001.00000", "1.00000000", "1699999999.1234"]], "c": "1234"}, "book-10", "XBT/USD"], [0, [["55000.00000", "0.01000000", "1699999999.1234", "b", "m", ""]], "trade", "XBT/USD"], [0, {"a": [["55001.00000", "1.00000000", "1699999999.1234"]], "c": "1234"}, "book-10", "XBT/USD"], [0, [["55000.00000", "0.01000000", "1699999999.1234", "b", "m", ""]], "trade", "XBT/USD"], [0, {"a": [["55001.00000", "1.00000000", "1699999999.1234"]], "c": "1234"}, "book-10", "XBT/USD"], [0, [["55000.00000", "0.01000000", "1699999999.1234", "b", "m", ""]], "trade", "XBT/USD"], [0, {"a": [["55001.00000", "1.00000000", "1699999999.1234"]], "c": "1234"}, "book-10", "XBT/USD"], [0, [["55000.00000", "0.01000000", "1699999999.1234", "b", "m", ""]], "trade", "XBT/USD"], [0, {"a": [["55001.00000", "1.00000000", "1699999999.1234"]], "c": "1234"}, "book-10", "XBT/USD"], [0, [["55000.00000", "0.01000000", "1699999999.1234", "b", "m", ""]], "trade", "XBT/USD"], [0, {"a": [["55001.00000", "1.00000000", "1699999999.1234"]], "c": "1234"}, "book-10", "XBT/USD"], [0, [["55000.00000", "0.01000000", "1699999999.1234", "b", "m", ""]], "trade", "XBT/USD"], [0, {"a": [["55001.00000", "1.00000000", "1699999999.1234"]], "c": "1234"}, "book-10", "XBT/USD"], [0, [["55000.00000", "0.01000000", "1699999999.1234", "b", "m", ""]], "trade", "XBT/USD"], [0, {"a": [["55001.00000", "1.00000000", "1699999999.1234"]], "c": "1234"}, "book-10", "XBT/USD"], [0, [["55000.00000", "0.01000000", "1699999999.1234", "b", "m", ""]], "trade", "XBT/USD"], [0, {"a": [["55001.00000", "1.00000000", "1699999999.1234"]], "c": "1234"}, "book-10", "XBT/USD"], [0, [["55000.00000", "0.01000000", "1699999999.1234", "b", "m", ""]], "trade", "XBT/USD"], [0, {"a": [["55001.00000", "1.00000000", "1699999999.1234"]], "c": "1234"}, "book-10", "XBT/USD"], [0, [["55000.00000", "0.01000000", "1699999999.1234", "b", "m", ""]], "trade", "XBT/USD"], [0, {"a": [["55001.00000", "1.00000000", "1699999999.1234"]], "c": "1234"}, "book-10", "XBT/USD"], [0, [["55000.00000", "0.01000000", "1699999999.1234", "b", "m", ""]], "trade", "XBT/USD"], [0, {"a": [["55001.00000", "1.00000000", "1699999999.1234"]], "c": "1234"}, "book-10", "XBT/USD"], [0, [["55000.00000", "0.01000000", "1699999999.1234", "b", "m", ""]], "trade", "XBT/USD"], [0, {"a": [["55001.00000", "1.00000000", "1699999999.1234"]], "c": "1234"}, "book-10", "XBT/USD"], [0, [["55000.00000", "0.01000000", "1699999999.1234", "b", "m", ""]], "trade", "XBT/USD"], [0, {"a": [["55001.00000", "1.00000000", "1699999999.1234"]], "c": "1234"}, "book-10", "XBT/USD"], [0, [["55000.00000", "0.01000000", "1699999999.1234", "b", "m", ""]], "trade", "XBT/USD"], [0, {"a": [["55001.00000", "1.00000000", "1699999999.1234"]], "c": "1234"}, "book-10", "XBT/USD"], [0, [["55000.00000", "0.01000000", "1699999999.1234", "b", "m", ""]], "trade", "XBT/USD"], [0, {"a": [["55001.00000", "1.00000000", "1699999999.1234"]], "c": "1234"}, "book-10", "XBT/USD"], [0, [["55000.00000", "0.01000000", "1699999999.1234", "b", "m", ""]], "trade", "XBT/USD"], [0, {"a": [["55001.00000", "1.00000000", "1699999999.1234"]], "c": "1234"}, "book-10", "XBT/USD"], [0, [["55000.00000", "0.01000000", "1699999999.1234", "b", "m", ""]], "trade", "XBT/USD"], [0, {"a": [["55001.00000", "1.00000000", "1699999999.1234"]], "c": "1234"}, "book-10", "XBT/USD"], [0, [["55000.00000", "0.01000000", "1699999999.1234", "b", "m", ""]], "trade", "XBT/USD"], [0, {"a": [["55001.00000", "1.00000000", "1699999999.1234"]], "c": "1234"}, "book-10", "XBT/USD"], [0, [["55000.00000", "0.01000000", "1699999999.1234", "b", "m", ""]], "trade", "XBT/USD"], [0, {"a": [["55001.00000", "1.00000000", "1699999999.1234"]], "c": "1234"}, "book-10", "XBT/USD"], [0, [["55000.00000", "0.01000000", "1699999999.1234", "b", "m", ""]], "trade", "XBT/USD"], [0, {"a": [["55001.00000", "1.00000000", "1699999999.1234"]], "c": "1234"}, "book-10", "XBT/USD"], [0, [["55000.00000", "0.01000000", "1699999999.1234", "b", "m", ""]], "trade", "XBT/USD"], [0, {"a": [["55001.00000", "1.00000000", "1699999999.1234"]], "c": "1234"}, "book-10", "XBT/USD"], [0, [["55000.00000", "0.01000000", "1699999999.1234", "b", "m", ""]], "trade", "XBT/USD"], [0, {"a": [["55001.00000", "1.00000000", "1699999999.1234"]], "c": "1234"}, "book-10", "XBT/USD"], [0, [["55000.00000", "0.01000000", "1699999999.1234", "b", "m", ""]], "trade", "XBT/USD"], [0, {"a": [["55001.00000", "1.00000000", "1699999999.1234"]], "c": "1234"}, "book-10", "XBT/USD"], [0, [["55000.00000", "0.01000000", "1699999999.1234", "b", "m", ""]], "trade", "XBT/USD"], [0, {"a": [["55001.00000", "1.00000000", "1699999999.1234"]], "c": "1234"}, "book-10", "XBT/USD"], [0, [["55000.00000", "0.01000000", "1699999999.1234", "b", "m", ""]], "trade", "XBT/USD"], [0, {"a": [["55001.00000", "1.00000000", "1699999999.1234"]], "c": "1234"}, "book-10", "XBT/USD"], [0, [["55000.00000", "0.01000000", "1699999999.1234", "b", "m", ""]], "trade", "XBT/USD"], [0, {"a": [["55001.00000", "1.00000000", "1699999999.1234"]], "c": "1234"}, "book-10", "XBT/USD"], [0, [["55000.00000", "0.01000000", "1699999999.1234", "b", "m", ""]], "trade", "XBT/USD"], [0, {"a": [["55001.00000", "1.00000000", "1699999999.1234"]], "c": "1234"}, "book-10", "XBT/USD"], [0, [["55000.00000", "0.01000000", "1699999999.1234", "b", "m", ""]], "trade", "XBT/USD"], [0, {"a": [["55001.00000", "1.00000000", "1699999999.1234"]], "c": "1234"}, "book-10", "XBT/USD"], [0, [["55000.00000", "0.01000000", "1699999999.1234", "b", "m", ""]], "trade", "XBT/USD"], [0, {"a": [["55001.00000", "1.00000000", "1699999999.1234"]], "c": "1234"}, "book-10", "XBT/USD"], [0, [["55000.00000", "0.01000000", "1699999999.1234", "b", "m", ""]], "trade", "XBT/USD"], [0, {"a": [["55001.00000", "1.00000000", "1699999999.1234"]], "c": "1234"}, "book-10", "XBT/USD"], [0, [["55000.00000", "0.01000000", "1699999999.1234", "b", "m", ""]], "trade", "XBT/USD"], [0, {"a": [["55001.00000", "1.00000000", "1699999999.1234"]], "c": "1234"}, "book-10", "XBT/USD"], [0, [["55000.00000", "0.01000000", "1699999999.1234", "b", "m", ""]], "trade", "XBT/USD"], [0, {"a": [["55001.00000", "1.00000000", "1699999999.1234"]], "c": "1234"}, "book-10", "XBT/USD"], [0, [["55000.00000", "0.01000000", "1699999999.1234", "b", "m", ""]], "trade", "XBT/USD"], [0, {"a": [["55001.00000", "1.00000000", "1699999999.1234"]], "c": "1234"}, "book-10", "XBT/USD"], [0, [["55000.00000", "0.01000000", "1699999999.1234", "b", "m", ""]], "trade", "XBT/USD"], [0, {"a": [["55001.00000", "1.00000000", "1699999999.1234"]], "c": "1234"}, "book-10", "XBT/USD"], [0, [["55000.00000", "0.01000000", "1699999999.1234", "b", "m", ""]], "trade", "XBT/USD"], [0, {"a": [["55001.00000", "1.00000000", "1699999999.1234"]], "c": "1234"}, "book-10", "XBT/USD"], [0, [["55000.00000", "0.01000000", "1699999999.1234", "b", "m", ""]], "trade", "XBT/USD"], [0, {"a": [["55001.00000", "1.00000000", "1699999999.1234"]], "c": "1234"}, "book-10", "XBT/USD"], [0, [["55000.00000", "0.01000000", "1699999999.1234", "b", "m", ""]], "trade", "XBT/USD"], [0, {"a": [["55001.00000", "1.00000000", "1699999999.1234"]], "c": "1234"}, "book-10", "XBT/USD"], [0, [["55000.00000", "0.01000000", "1699999999.1234", "b", "m", ""]], "trade", "XBT/USD"], [0, {"a": [["55001.00000", "1.00000000", "1699999999.1234"]], "c": "1234"}, "book-10", "XBT/USD"], [0, [["55000.00000", "0.01000000", "1699999999.1234", "b", "m", ""]], "trade", "XBT/USD"], [0, {"a": [["55001.00000", "1.00000000", "1699999999.1234"]], "c": "1234"}, "book-10", "XBT/USD"], [0, [["55000.00000", "0.01000000", "1699999999.1234", "b", "m", ""]], "trade", "XBT/USD"], [0, {"a": [["55001.00000", "1.00000000", "1699999999.1234"]], "c": "1234"}, "book-10", "XBT/USD"], [0, [["55000.00000", "0.01000000", "1699999999.1234", "b", "m", ""]], "trade", "XBT/USD"], [0, {"a": [["55001.00000", "1.00000000", "1699999999.1234"]], "c": "1234"}, "book-10", "XBT/USD"], [0, [["55000.00000", "0.01000000", "1699999999.1234", "b", "m", ""]], "trade", "XBT/USD"], [0, {"a": [["55001.00000", "1.00000000", "1699999999.1234"]], "c": "1234"}, "book-10", "XBT/USD"], [0, [["55000.00000", "0.01000000", "1699999999.1234", "b", "m", ""]], "trade", "XBT/USD"], [0, {"a": [["55001.00000", "1.00000000", "1699999999.1234"]], "c": "1234"}, "book-10", "XBT/USD"], [0, [["55000.00000", "0.01000000", "1699999999.1234", "b", "m", ""]], "trade", "XBT/USD"], [0, {"a": [["55001.00000", "1.00000000", "1699999999.1234"]], "c": "1234"}, "book-10", "XBT/USD"], [0, [["55000.00000", "0.01000000", "1699999999.1234", "b", "m", ""]], "trade", "XBT/USD"], [0, {"a": [["55001.00000", "1.00000000", "1699999999.1234"]], "c": "1234"}, "book-10", "XBT/USD"], [0, [["55000.00000", "0.01000000", "1699999999.1234", "b", "m", ""]], "trade", "XBT/USD"], [0, {"a": [["55001.00000", "1.00000000", "1699999999.1234"]], "c": "1234"}, "book-10", "XBT/USD"], [0, [["55000.00000", "0.01000000", "1699999999.1234", "b", "m", ""]], "trade", "XBT/USD"], [0, {"a": [["55001.00000", "1.00000000", "1699999999.1234"]], "c": "1234"}, "book-10", "XBT/USD"], [0, [["55000.00000", "0.01000000", "1699999999.1234", "b", "m", ""]], "trade", "XBT/USD"], [0, {"a": [["55001.00000", "1.00000000", "1699999999.1234"]], "c": "1234"}, "book-10", "XBT/USD"], [0, [["55000.00000", "0.01000000", "1699999999.1234", "b", "m", ""]], "trade", "XBT/USD"], [0, {"a": [["55001.00000", "1.00000000", "1699999999.1234"]], "c": "1234"}, "book-10", "XBT/USD"], [0, [["55000.00000", "0.01000000", "1699999999.1234", "b", "m", ""]], "trade", "XBT/USD"], [0, {"a": [["55001.00000", "1.00000000", "1699999999.1234"]], "c": "1234"}, "book-10", "XBT/USD"], [0, [["55000.00000", "0.01000000", "1699999999.1234", "b", "m", ""]], "trade", "XBT/USD"], [0, {"a": [["55001.00000", "1.00000000", "1699999999.1234"]], "c": "1234"}, "book-10", "XBT/USD"], [0, [["55000.00000", "0.01000000", "1699999999.1234", "b", "m", ""]], "trade", "XBT/USD"], [0, {"a": [["55001.00000", "1.00000000", "1699999999.1234"]], "c": "1234"}, "book-10", "XBT/USD"], [0, [["55000.00000", "0.01000000", "1699999999.1234", "b", "m", ""]], "trade", "XBT/USD"], [0, {"a": [["55001.00000", "1.00000000", "1699999999.1234"]], "c": "1234"}, "book-10", "XBT/USD"], [0, [["55000.00000", "0.01000000", "1699999999.1234", "b", "m", ""]], "trade", "XBT/USD"], [0, {"a": [["55001.00000", "1.00000000", "1699999999.1234"]], "c": "1234"}, "book-10", "XBT/USD"], [0, [["55000.00000", "0.01000000", "1699999999.1234", "b", "m", ""]], "trade", "XBT/USD"], [0, {"a": [["55001.00000", "1.00000000", "1699999999.1234"]], "c": "1234"}, "book-10", "XBT/USD"], [0, [["55000.00000", "0.01000000", "1699999999.1234", "b", "m", ""]], "trade", "XBT/USD"], [0, {"a": [["55001.00000", "1.00000000", "1699999999.1234"]], "c": "1234"}, "book-10", "XBT/USD"], [0, [["55000.00000", "0.01000000", "1699999999.1234", "b", "m", ""]], "trade", "XBT/USD"], [0, {"a": [["55001.00000", "1.00000000", "1699999999.1234"]], "c": "1234"}, "book-10", "XBT/USD"], [0, [["55000.00000", "0.01000000", "1699999999.1234", "b", "m", ""]], "trade", "XBT/USD"], [0, {"a": [["55001.00000", "1.00000000", "1699999999.1234"]], "c": "1234"}, "book-10", "XBT/USD"], [0, [["55000.00000", "0.01000000", "1699999999.1234", "b", "m", ""]], "trade", "XBT/USD"], [0, {"a": [["55001.00000", "1.00000000", "1699999999.1234"]], "c": "1234"}, "book-10", "XBT/USD"], [0, [["55000.00000", "0.01000000", "1699999999.1234", "b", "m", ""]], "trade", "XBT/USD"], [0, {"a": [["55001.00000", "1.00000000", "1699999999.1234"]], "c": "1234"}, "book-10", "XBT/USD"], [0, [["55000.00000", "0.01000000", "1699999999.1234", "b", "m", ""]], "trade", "XBT/USD"], [0, {"a": [["55001.00000", "1.00000000", "1699999999.1234"]], "c": "1234"}, "book-10", "XBT/USD"], [0, [["55000.00000", "0.01000000", "1699999999.1234", "b", "m", ""]], "trade", "XBT/USD"], [0, {"a": [["55001.00000", "1.00000000", "1699999999.1234"]], "c": "1234"}, "book-10", "XBT/USD"], [0, [["55000.00000", "0.01000000", "1699999999.1234", "b", "m", ""]], "trade", "XBT/USD"], [0, {"a": [["55001.00000", "1.00000000", "1699999999.1234"]], "c": "1234"}, "book-10", "XBT/USD"], [0, [["55000.00000", "0.01000000", "1699999999.1234", "b", "m", ""]], "trade", "XBT/USD"], [0, {"a": [["55001.00000", "1.00000000", "1699999999.1234"]], "c": "1234"}, "book-10", "XBT/USD"], [0, [["55000.00000", "0.01000000", "1699999999.1234", "b", "m", ""]], "trade", "XBT/USD"], [0, {"a": [["55001.00000", "1.00000000", "1699999999.1234"]], "c": "1234"}, "book-10", "XBT/USD"], [0, [["55000.00000", "0.01000000", "1699999999.1234", "b", "m", ""]], "trade", "XBT/USD"], [0, {"a": [["55001.00000", "1.00000000", "1699999999.1234"]], "c": "1234"}, "book-10", "XBT/USD"], [0, [["55000.00000", "0.01000000", "1699999999.1234", "b", "m", ""]], "trade", "XBT/USD"], [0, {"a": [["55001.00000", "1.00000000", "1699999999.1234"]], "c": "1234"}, "book-10", "XBT/USD"], [0, [["55000.00000", "0.01000000", "1699999999.1234", "b", "m", ""]], "trade", "XBT/USD"], [0, {"a": [["55001.00000", "1.00000000", "1699999999.1234"]], "c": "1234"}, "book-10", "XBT/USD"], [0, [["55000.00000", "0.01000000", "1699999999.1234", "b", "m", ""]], "trade", "XBT/USD"], [0, {"a": [["55001.00000", "1.00000000", "1699999999.1234"]], "c": "1234"}, "book-10", "XBT/USD"], [0, [["55000.00000", "0.01000000", "1699999999.1234", "b", "m", ""]], "trade", "XBT/USD"], [0, {"a": [["55001.00000", "1.00000000", "1699999999.1234"]], "c": "1234"}, "book-10", "XBT/USD"], [0, [["55000.00000", "0.01000000", "1699999999.1234", "b", "m", ""]], "trade", "XBT/USD"], [0, {"a": [["55001.00000", "1.00000000", "1699999999.1234"]], "c": "1234"}, "book-10", "XBT/USD"], [0, [["55000.00000", "0.01000000", "1699999999.1234", "b", "m", ""]], "trade", "XBT/USD"], [0, {"a": [["55001.00000", "1.00000000", "1699999999.1234"]], "c": "1234"}, "book-10", "XBT/USD"], [0, [["55000.00000", "0.01000000", "1699999999.1234", "b", "m", ""]], "trade", "XBT/USD"], [0, {"a": [["55001.00000", "1.00000000", "1699999999.1234"]], "c": "1234"}, "book-10", "XBT/USD"], [0, [["55000.00000", "0.01000000", "1699999999.1234", "b", "m", ""]], "trade", "XBT/USD"], [0, {"a": [["55001.00000", "1.00000000", "1699999999.1234"]], "c": "1234"}, "book-10", "XBT/USD"], [0, [["55000.00000", "0.01000000", "1699999999.1234", "b", "m", ""]], "trade", "XBT/USD"], [0, {"a": [["55001.00000", "1.00000000", "1699999999.1234"]], "c": "1234"}, "book-10", "XBT/USD"], [0, [["55000.00000", "0.01000000", "1699999999.1234", "b", "m", ""]], "trade", "XBT/USD"], [0, {"a": [["55001.00000", "1.00000000", "1699999999.1234"]], "c": "1234"}, "book-10", "XBT/USD"], [0, [["55000.00000", "0.01000000", "1699999999.1234", "b", "m", ""]], "trade", "XBT/USD"], [0, {"a": [["55001.00000", "1.00000000", "1699999999.1234"]], "c": "1234"}, "book-10", "XBT/USD"], [0, [["55000.00000", "0.01000000", "1699999999.1234", "b", "m", ""]], "trade", "XBT/USD"], [0, {"a": [["55001.00000", "1.00000000", "1699999999.1234"]], "c": "1234"}, "book-10", "XBT/USD"], [0, [["55000.00000", "0.01000000", "1699999999.1234", "b", "m", ""]], "trade", "XBT/USD"], [0, {"a": [["55001.00000", "1.00000000", "1699999999.1234"]], "c": "1234"}, "book-10", "XBT/USD"], [0, [["55000.00000", "0.01000000", "1699999999.1234", "b", "m", ""]], "trade", "XBT/USD"], [0, {"a": [["55001.00000", "1.00000000", "1699999999.1234"]], "c": "1234"}, "book-10", "XBT/USD"], [0, [["55000.00000", "0.01000000", "1699999999.1234", "b", "m", ""]], "trade", "XBT/USD"], [0, {"a": [["55001.00000", "1.00000000", "1699999999.1234"]], "c": "1234"}, "book-10", "XBT/USD"], [0, [["55000.00000", "0.01000000", "1699999999.1234", "b", "m", ""]], "trade", "XBT/USD"], [0, {"a": [["55001.00000", "1.00000000", "1699999999.1234"]], "c": "1234"}, "book-10", "XBT/USD"], [0, [["55000.00000", "0.01000000", "1699999999.1234", "b", "m", ""]], "trade", "XBT/USD"], [0, {"a": [["55001.00000", "1.00000000", "1699999999.1234"]], "c": "1234"}, "book-10", "XBT/USD"], [0, [["55000.00000", "0.01000000", "1699999999.1234", "b", "m", ""]], "trade", "XBT/USD"], [0, {"a": [["55001.00000", "1.00000000", "1699999999.1234"]], "c": "1234"}, "book-10", "XBT/USD"], [0, [["55000.00000", "0.01000000", "1699999999.1234", "b", "m", ""]], "trade", "XBT/USD"], [0, {"a": [["55001.00000", "1.00000000", "1699999999.1234"]], "c": "1234"}, "book-10", "XBT/USD"], [0, [["55000.00000", "0.01000000", "1699999999.1234", "b", "m", ""]], "trade", "XBT/USD"], [0, {"a": [["55001.00000", "1.00000000", "1699999999.1234"]], "c": "1234"}, "book-10", "XBT/USD"], [0, [["55000.00000", "0.01000000", "1699999999.1234", "b", "m", ""]], "trade", "XBT/USD"], [0, {"a": [["55001.00000", "1.00000000", "1699999999.1234"]], "c": "1234"}, "book-10", "XBT/USD"], [0, [["55000.00000", "0.01000000", "1699999999.1234", "b", "m", ""]], "trade", "XBT/USD"], [0, {"a": [["55001.00000", "1.00000000", "1699999999.1234"]], "c": "1234"}, "book-10", "XBT/USD"], [0, [["55000.00000", "0.01000000", "1699999999.1234", "b", "m", ""]], "trade", "XBT/USD"], [0, {"a": [["55001.00000", "1.00000000", "1699999999.1234"]], "c": "1234"}, "book-10", "XBT/USD"], [0, [["55000.00000", "0.01000000", "1699999999.1234", "b", "m", ""]], "trade", "XBT/USD"], [0, {"a": [["55001.00000", "1.00000000", "1699999999.1234"]], "c": "1234"}, "book-10", "XBT/USD"], [0, [["55000.00000", "0.01000000", "1699999999.1234", "b", "m", ""]], "trade", "XBT/USD"], [0, {"a": [["55001.00000", "1.00000000", "1699999999.1234"]], "c": "1234"}, "book-10", "XBT/USD"], [0, [["55000.00000", "0.01000000", "1699999999.1234", "b", "m", ""]], "trade", "XBT/USD"], [0, {"a": [["55001.00000", "1.00000000", "1699999999.1234"]], "c": "1234"}, "book-10", "XBT/USD"], [0, [["55000.00000", "0.01000000", "1699999999.1234", "b", "m", ""]], "trade", "XBT/USD"], [0, {"a": [["55001.00000", "1.00000000", "1699999999.1234"]], "c": "1234"}, "book-10", "XBT/USD"], [0, [["55000.00000", "0.01000000", "1699999999.1234", "b", "m", ""]], "trade", "XBT/USD"], [0, {"a": [["55001.00000", "1.00000000", "1699999999.1234"]], "c": "1234"}, "book-10", "XBT/USD"], [0, [["55000.00000", "0.01000000", "1699999999.1234", "b", "m", ""]], "trade", "XBT/USD"], [0, {"a": [["55001.00000", "1.00000000", "1699999999.1234"]], "c": "1234"}, "book-10", "XBT/USD"], [0, [["55000.00000", "0.01000000", "1699999999.1234", "b", "m", ""]], "trade", "XBT/USD"], [0, {"a": [["55001.00000", "1.00000000", "1699999999.1234"]], "c": "1234"}, "book-10", "XBT/USD"], [0, [["55000.00000", "0.01000000", "1699999999.1234", "b", "m", ""]], "trade", "XBT/USD"], [0, {"a": [["55001.00000", "1.00000000", "1699999999.1234"]], "c": "1234"}, "book-10", "XBT/USD"], [0, [["55000.00000", "0.01000000", "1699999999.1234", "b", "m", ""]], "trade", "XBT/USD"], [0, {"a": [["55001.00000", "1.00000000", "1699999999.1234"]], "c": "1234"}, "book-10", "XBT/USD"], [0, [["55000.00000", "0.01000000", "1699999999.1234", "b", "m", ""]], "trade", "XBT/USD"], [0, {"a": [["55001.00000", "1.00000000", "1699999999.1234"]], "c": "1234"}, "book-10", "XBT/USD"], [0, [["55000.00000", "0.01000000", "1699999999.1234", "b", "m", ""]], "trade", "XBT/USD"], [0, {"a": [["55001.00000", "1.00000000", "1699999999.1234"]], "c": "1234"}, "book-10", "XBT/USD"], [0, [["55000.00000", "0.01000000", "1699999999.1234", "b", "m", ""]], "trade", "XBT/USD"], [0, {"a": [["55001.00000", "1.00000000", "1699999999.1234"]], "c": "1234"}, "book-10", "XBT/USD"], [0, [["55000.00000", "0.01000000", "1699999999.1234", "b", "m", ""]], "trade", "XBT/USD"], [0, {"a": [["55001.00000", "1.00000000", "1699999999.1234"]], "c": "1234"}, "book-10", "XBT/USD"], [0, [["55000.00000", "0.01000000", "1699999999.1234", "b", "m", ""]], "trade", "XBT/USD"], [0, {"a": [["55001.00000", "1.00000000", "1699999999.1234"]], "c": "1234"}, "book-10", "XBT/USD"], [0, [["55000.00000", "0.01000000", "1699999999.1234", "b", "m", ""]], "trade", "XBT/USD"], [0, {"a": [["55001.00000", "1.00000000", "1699999999.1234"]], "c": "1234"}, "book-10", "XBT/USD"], [0, [["55000.00000", "0.01000000", "1699999999.1234", "b", "m", ""]], "trade", "XBT/USD"], [0, {"a": [["55001.00000", "1.00000000", "1699999999.1234"]], "c": "1234"}, "book-10", "XBT/USD"], [0, [["55000.00000", "0.01000000", "1699999999.1234", "b", "m", ""]], "trade", "XBT/USD"], [0, {"a": [["55001.00000", "1.00000000", "1699999999.1234"]], "c": "1234"}, "book-10", "XBT/USD"], [0, [["55000.00000", "0.01000000", "1699999999.1234", "b", "m", ""]], "trade", "XBT/USD"], [0, {"a": [["55001.00000", "1.00000000", "1699999999.1234"]], "c": "1234"}, "book-10", "XBT/USD"], [0, [["55000.00000", "0.01000000", "1699999999.1234", "b", "m", ""]], "trade", "XBT/USD"], [0, {"a": [["55001.00000", "1.00000000", "1699999999.1234"]], "c": "1234"}, "book-10", "XBT/USD"], [0, [["55000.00000", "0.01000000", "1699999999.1234", "b", "m", ""]], "trade", "XBT/USD"], [0, {"a": [["55001.00000", "1.00000000", "1699999999.1234"]], "c": "1234"}, "book-10", "XBT/USD"], [0, [["55000.00000", "0.01000000", "1699999999.1234", "b", "m", ""]], "trade", "XBT/USD"], [0, {"a": [["55001.00000", "1.00000000", "1699999999.1234"]], "c": "1234"}, "book-10", "XBT/USD"], [0, [["55000.00000", "0.01000000", "1699999999.1234", "b", "m", ""]], "trade", "XBT/USD"], [0, {"a": [["55001.00000", "1.00000000", "1699999999.1234"]], "c": "1234"}, "book-10", "XBT/USD"], [0, [["55000.00000", "0.01000000", "1699999999.1234", "b", "m", ""]], "trade", "XBT/USD"], [0, {"a": [["55001.00000", "1.00000000", "1699999999.1234"]], "c": "1234"}, "book-10", "XBT/USD"], [0, [["55000.00000", "0.01000000", "1699999999.1234", "b", "m", ""]], "trade", "XBT/USD"], [0, {"a": [["55001.00000", "1.00000000", "1699999999.1234"]], "c": "1234"}, "book-10", "XBT/USD"], [0, [["55000.00000", "0.01000000", "1699999999.1234", "b", "m", ""]], "trade", "XBT/USD"], [0, {"a": [["55001.00000", "1.00000000", "1699999999.1234"]], "c": "1234"}, "book-10", "XBT/USD"], [0, [["55000.00000", "0.01000000", "1699999999.1234", "b", "m", ""]], "trade", "XBT/USD"], [0, {"a": [["55001.00000", "1.00000000", "1699999999.1234"]], "c": "1234"}, "book-10", "XBT/USD"], [0, [["55000.00000", "0.01000000", "1699999999.1234", "b", "m", ""]], "trade", "XBT/USD"], [0, {"a": [["55001.00000", "1.00000000", "1699999999.1234"]], "c": "1234"}, "book-10", "XBT/USD"], [0, [["55000.00000", "0.01000000", "1699999999.1234", "b", "m", ""]], "trade", "XBT/USD"], [0, {"a": [["55001.00000", "1.00000000", "1699999999.1234"]], "c": "1234"}, "book-10", "XBT/USD"], [0, [["55000.00000", "0.01000000", "1699999999.1234", "b", "m", ""]], "trade", "XBT/USD"], [0, {"a": [["55001.00000", "1.00000000", "1699999999.1234"]], "c": "1234"}, "book-10", "XBT/USD"], [0, [["55000.00000", "0.01000000", "1699999999.1234", "b", "m", ""]], "trade", "XBT/USD"], [0, {"a": [["55001.00000", "1.00000000", "1699999999.1234"]], "c": "1234"}, "book-10", "XBT/USD"], [0, [["55000.00000", "0.01000000", "1699999999.1234", "b", "m", ""]], "trade", "XBT/USD"], [0, {"a": [["55001.00000", "1.00000000", "1699999999.1234"]], "c": "1234"}, "book-10", "XBT/USD"], [0, [["55000.00000", "0.01000000", "1699999999.1234", "b", "m", ""]], "trade", "XBT/USD"], [0, {"a": [["55001.00000", "1.00000000", "1699999999.1234"]], "c": "1234"}, "book-10", "XBT/USD"], [0, [["55000.00000", "0.01000000", "1699999999.1234", "b", "m", ""]], "trade", "XBT/USD"], [0, {"a": [["55001.00000", "1.00000000", "1699999999.1234"]], "c": "1234"}, "book-10", "XBT/USD"], [0, [["55000.00000", "0.01000000", "1699999999.1234", "b", "m", ""]], "trade", "XBT/USD"], [0, {"a": [["55001.00000", "1.00000000", "1699999999.1234"]], "c": "1234"}, "book-10", "XBT/USD"], [0, [["55000.00000", "0.01000000", "1699999999.1234", "b", "m", ""]], "trade", "XBT/USD"], [0, {"a": [["55001.00000", "1.00000000", "1699999999.1234"]], "c": "1234"}, "book-10", "XBT/USD"], [0, [["55000.00000", "0.01000000", "1699999999.1234", "b", "m", ""]], "trade", "XBT/USD"], [0, {"a": [["55001.00000", "1.00000000", "1699999999.1234"]], "c": "1234"}, "book-10", "XBT/USD"], [0, [["55000.00000", "0.01000000", "1699999999.1234", "b", "m", ""]], "trade", "XBT/USD"], [0, {"a": [["55001.00000", "1.00000000", "1699999999.1234"]], "c": "1234"}, "book-10", "XBT/USD"], [0, [["55000.00000", "0.01000000", "1699999999.1234", "b", "m", ""]], "trade", "XBT/USD"], [0, {"a": [["55001.00000", "1.00000000", "1699999999.1234"]], "c": "1234"}, "book-10", "XBT/USD"], [0, [["55000.00000", "0.01000000", "1699999999.1234", "b", "m", ""]], "trade", "XBT/USD"], [0, {"a": [["55001.00000", "1.00000000", "1699999999.1234"]], "c": "1234"}, "book-10", "XBT/USD"], [0, [["55000.00000", "0.01000000", "1699999999.1234", "b", "m", ""]], "trade", "XBT/USD"], [0, {"a": [["55001.00000", "1.00000000", "1699999999.1234"]], "c": "1234"}, "book-10", "XBT/USD"], [0, [["55000.00000", "0.01000000", "1699999999.1234", "b", "m", ""]], "trade", "XBT/USD"], [0, {"a": [["55001.00000", "1.00000000", "1699999999.1234"]], "c": "1234"}, "book-10", "XBT/USD"], [0, [["55000.00000", "0.01000000", "1699999999.1234", "b", "m", ""]], "trade", "XBT/USD"], [0, {"a": [["55001.00000", "1.00000000", "1699999999.1234"]], "c": "1234"}, "book-10", "XBT/USD"], [0, [["55000.00000", "0.01000000", "1699999999.1234", "b", "m", ""]], "trade", "XBT/USD"], [0, {"a": [["55001.00000", "1.00000000", "1699999999.1234"]], "c": "1234"}, "book-10", "XBT/USD"], [0, [["55000.00000", "0.01000000", "1699999999.1234", "b", "m", ""]], "trade", "XBT/USD"], [0, {"a": [["55001.00000", "1.00000000", "1699999999.1234"]], "c": "1234"}, "book-10", "XBT/USD"], [0, [["55000.00000", "0.01000000", "1699999999.1234", "b", "m", ""]], "trade", "XBT/USD"], [0, {"a": [["55001.00000", "1.00000000", "1699999999.1234"]], "c": "1234"}, "book-10", "XBT/USD"], [0, [["55000.00000", "0.01000000", "1699999999.1234", "b", "m", ""]], "trade", "XBT/USD"], [0, {"a": [["55001.00000", "1.00000000", "1699999999.1234"]], "c": "1234"}, "book-10", "XBT/USD"], [0, [["55000.00000", "0.01000000", "1699999999.1234", "b", "m", ""]], "trade", "XBT/USD"], [0, {"a": [["55001.00000", "1.00000000", "1699999999.1234"]], "c": "1234"}, "book-10", "XBT/USD"], [0, [["55000.00000", "0.01000000", "1699999999.1234", "b", "m", ""]], "trade", "XBT/USD"], [0, {"a": [["55001.00000", "1.00000000", "1699999999.1234"]], "c": "1234"}, "book-10", "XBT/USD"], [0, [["55000.00000", "0.01000000", "1699999999.1234", "b", "m", ""]], "trade", "XBT/USD"], [0, {"a": [["55001.00000", "1.00000000", "1699999999.1234"]], "c": "1234"}, "book-10", "XBT/USD"], [0, [["55000.00000", "0.01000000", "1699999999.1234", "b", "m", ""]], "trade", "XBT/USD"], [0, {"a": [["55001.00000", "1.00000000", "1699999999.1234"]], "c": "1234"}, "book-10", "XBT/USD"], [0, [["55000.00000", "0.01000000", "1699999999.1234", "b", "m", ""]], "trade", "XBT/USD"], [0, {"a": [["55001.00000", "1.00000000", "1699999999.1234"]], "c": "1234"}, "book-10", "XBT/USD"], [0, [["55000.00000", "0.01000000", "1699999999.1234", "b", "m", ""]], "trade", "XBT/USD"], [0, {"a": [["55001.00000", "1.00000000", "1699999999.1234"]], "c": "1234"}, "book-10", "XBT/USD"], [0, [["55000.00000", "0.01000000", "1699999999.1234", "b", "m", ""]], "trade", "XBT/USD"], [0, {"a": [["55001.00000", "1.00000000", "1699999999.1234"]], "c": "1234"}, "book-10", "XBT/USD"], [0, [["55000.00000", "0.01000000", "1699999999.1234", "b", "m", ""]], "trade", "XBT/USD"], [0, {"a": [["55001.00000", "1.00000000", "1699999999.1234"]], "c": "1234"}, "book-10", "XBT/USD"], [0, [["55000.00000", "0.01000000", "1699999999.1234", "b", "m", ""]], "trade", "XBT/USD"], [0, {"a": [["55001.00000", "1.00000000", "1699999999.1234"]], "c": "1234"}, "book-10", "XBT/USD"], [0, [["55000.00000", "0.01000000", "1699999999.1234", "b", "m", ""]], "trade", "XBT/USD"], [0, {"a": [["55001.00000", "1.00000000", "1699999999.1234"]], "c": "1234"}, "book-10", "XBT/USD"], [0, [["55000.00000", "0.01000000", "1699999999.1234", "b", "m", ""]], "trade", "XBT/USD"], [0, {"a": [["55001.00000", "1.00000000", "1699999999.1234"]], "c": "1234"}, "book-10", "XBT/USD"], [0, [["55000.00000", "0.01000000", "1699999999.1234", "b", "m", ""]], "trade", "XBT/USD"], [0, {"a": [["55001.00000", "1.00000000", "1699999999.1234"]], "c": "1234"}, "book-10", "XBT/USD"], [0, [["55000.00000", "0.01000000", "1699999999.1234", "b", "m", ""]], "trade", "XBT/USD"], [0, {"a": [["55001.00000", "1.00000000", "1699999999.1234"]], "c": "1234"}, "book-10", "XBT/USD"], [0, [["55000.00000", "0.01000000", "1699999999.1234", "b", "m", ""]], "trade", "XBT/USD"], [0, {"a": [["55001.00000", "1.00000000", "1699999999.1234"]], "c": "1234"}, "book-10", "XBT/USD"], [0, [["55000.00000", "0.01000000", "1699999999.1234", "b", "m", ""]], "trade", "XBT/USD"], [0, {"a": [["55001.00000", "1.00000000", "1699999999.1234"]], "c": "1234"}, "book-10", "XBT/USD"], [0, [["55000.00000", "0.01000000", "1699999999.1234", "b", "m", ""]], "trade", "XBT/USD"], [0, {"a": [["55001.00000", "1.00000000", "1699999999.1234"]], "c": "1234"}, "book-10", "XBT/USD"], [0, [["55000.00000", "0.01000000", "1699999999.1234", "b", "m", ""]], "trade", "XBT/USD"], [0, {"a": [["55001.00000", "1.00000000", "1699999999.1234"]], "c": "1234"}, "book-10", "XBT/USD"], [0, [["55000.00000", "0.01000000", "1699999999.1234", "b", "m", ""]], "trade", "XBT/USD"], [0, {"a": [["55001.00000", "1.00000000", "1699999999.1234"]], "c": "1234"}, "book-10", "XBT/USD"], [0, [["55000.00000", "0.01000000", "1699999999.1234", "b", "m", ""]], "trade", "XBT/USD"], [0, {"a": [["55001.00000", "1.00000000", "1699999999.1234"]], "c": "1234"}, "book-10", "XBT/USD"], [0, [["55000.00000", "0.01000000", "1699999999.1234", "b", "m", ""]], "trade", "XBT/USD"], [0, {"a": [["55001.00000", "1.00000000", "1699999999.1234"]], "c": "1234"}, "book-10", "XBT/USD"], [0, [["55000.00000", "0.01000000", "1699999999.1234", "b", "m", ""]], "trade", "XBT/USD"], [0, {"a": [["55001.00000", "1.00000000", "1699999999.1234"]], "c": "1234"}, "book-10", "XBT/USD"], [0, [["55000.00000", "0.01000000", "1699999999.1234", "b", "m", ""]], "trade", "XBT/USD"], [0, {"a": [["55001.00000", "1.00000000", "1699999999.1234"]], "c": "1234"}, "book-10", "XBT/USD"], [0, [["55000.00000", "0.01000000", "1699999999.1234", "b", "m", ""]], "trade", "XBT/USD"], [0, {"a": [["55001.00000", "1.00000000", "1699999999.1234"]], "c": "1234"}, "book-10", "XBT/USD"], [0, [["55000.00000", "0.01000000", "1699999999.1234", "b", "m", ""]], "trade", "XBT/USD"], [0, {"a": [["55001.00000", "1.00000000", "1699999999.1234"]], "c": "1234"}, "book-10", "XBT/USD"], [0, [["55000.00000", "0.01000000", "1699999999.1234", "b", "m", ""]], "trade", "XBT/USD"], [0, {"a": [["55001.00000", "1.00000000", "1699999999.1234"]], "c": "1234"}, "book-10", "XBT/USD"], [0, [["55000.00000", "0.01000000", "1699999999.1234", "b", "m", ""]], "trade", "XBT/USD"], [0, {"a": [["55001.00000", "1.00000000", "1699999999.1234"]], "c": "1234"}, "book-10", "XBT/USD"], [0, [["55000.00000", "0.01000000", "1699999999.1234", "b", "m", ""]], "trade", "XBT/USD"], [0, {"a": [["55001.00000", "1.00000000", "1699999999.1234"]], "c": "1234"}, "book-10", "XBT/USD"], [0, [["55000.00000", "0.01000000", "1699999999.1234", "b", "m", ""]], "trade", "XBT/USD"], [0, {"a": [["55001.00000", "1.00000000", "1699999999.1234"]], "c": "1234"}, "book-10", "XBT/USD"], [0, [["55000.00000", "0.01000000", "1699999999.1234", "b", "m", ""]], "trade", "XBT/USD"], [0, {"a": [["55001.00000", "1.00000000", "1699999999.1234"]], "c": "1234"}, "book-10", "XBT/USD"], [0, [["55000.00000", "0.01000000", "1699999999.1234", "b", "m", ""]], "trade", "XBT/USD"], [0, {"a": [["55001.00000", "1.00000000", "1699999999.1234"]], "c": "1234"}, "book-10", "XBT/USD"], [0, [["55000.00000", "0.01000000", "1699999999.1234", "b", "m", ""]], "trade", "XBT/USD"], [0, {"a": [["55001.00000", "1.00000000", "1699999999.1234"]], "c": "1234"}, "book-10", "XBT/USD"], [0, [["55000.00000", "0.01000000", "1699999999.1234", "b", "m", ""]], "trade", "XBT/USD"], [0, {"a": [["55001.00000", "1.00000000", "1699999999.1234"]], "c": "1234"}, "book-10", "XBT/USD"], [0, [["55000.00000", "0.01000000", "1699999999.1234", "b", "m", ""]], "trade", "XBT/USD"], [0, {"a": [["55001.00000", "1.00000000", "1699999999.1234"]], "c": "1234"}, "book-10", "XBT/USD"], [0, [["55000.00000", "0.01000000", "1699999999.1234", "b", "m", ""]], "trade", "XBT/USD"], [0, {"a": [["55001.00000", "1.00000000", "1699999999.1234"]], "c": "1234"}, "book-10", "XBT/USD"], [0, [["55000.00000", "0.01000000", "1699999999.1234", "b", "m", ""]], "trade", "XBT/USD"], [0, {"a": [["55001.00000", "1.00000000", "1699999999.1234"]], "c": "1234"}, "book-10", "XBT/USD"], [0, [["55000.00000", "0.01000000", "1699999999.1234", "b", "m", ""]], "trade", "XBT/USD"], [0, {"a": [["55001.00000", "1.00000000", "1699999999.1234"]], "c": "1234"}, "book-10", "XBT/USD"], [0, [["55000.00000", "0.01000000", "1699999999.1234", "b", "m", ""]], "trade", "XBT/USD"], [0, {"a": [["55001.00000", "1.00000000", "1699999999.1234"]], "c": "1234"}, "book-10", "XBT/USD"], [0, [["55000.00000", "0.01000000", "1699999999.1234", "b", "m", ""]], "trade", "XBT/USD"], [0, {"a": [["55001.00000", "1.00000000", "1699999999.1234"]], "c": "1234"}, "book-10", "XBT/USD"], [0, [["55000.00000", "0.01000000", "1699999999.1234", "b", "m", ""]], "trade", "XBT/USD"], [0, {"a": [["55001.00000", "1.00000000", "1699999999.1234"]], "c": "1234"}, "book-10", "XBT/USD"], [0, [["55000.00000", "0.01000000", "1699999999.1234", "b", "m", ""]], "trade", "XBT/USD"], [0, {"a": [["55001.00000", "1.00000000", "1699999999.1234"]], "c": "1234"}, "book-10", "XBT/USD"], [0, [["55000.00000", "0.01000000", "1699999999.1234", "b", "m", ""]], "trade", "XBT/USD"], [0, {"a": [["55001.00000", "1.00000000", "1699999999.1234"]], "c": "1234"}, "book-10", "XBT/USD"], [0, [["55000.00000", "0.01000000", "1699999999.1234", "b", "m", ""]], "trade", "XBT/USD"], [0, {"a": [["55001.00000", "1.00000000", "1699999999.1234"]], "c": "1234"}, "book-10", "XBT/USD"], [0, [["55000.00000", "0.01000000", "1699999999.1234", "b", "m", ""]], "trade", "XBT/USD"], [0, {"a": [["55001.00000", "1.00000000", "1699999999.1234"]], "c": "1234"}, "book-10", "XBT/USD"], [0, [["55000.00000", "0.01000000", "1699999999.1234", "b", "m", ""]], "trade", "XBT/USD"], [0, {"a": [["55001.00000", "1.00000000", "1699999999.1234"]], "c": "1234"}, "book-10", "XBT/USD"], [0, [["55000.00000", "0.01000000", "1699999999.1234", "b", "m", ""]], "trade", "XBT/USD"], [0, {"a": [["55001.00000", "1.00000000", "1699999999.1234"]], "c": "1234"}, "book-10", "XBT/USD"], [0, [["55000.00000", "0.01000000", "1699999999.1234", "b", "m", ""]], "trade", "XBT/USD"], [0, {"a": [["55001.00000", "1.00000000", "1699999999.1234"]], "c": "1234"}, "book-10", "XBT/USD"], [0, [["55000.00000", "0.01000000", "1699999999.1234", "b", "m", ""]], "trade", "XBT/USD"], [0, {"a": [["55001.00000", "1.00000000", "1699999999.1234"]], "c": "1234"}, "book-10", "XBT/USD"], [0, [["55000.00000", "0.01000000", "1699999999.1234", "b", "m", ""]], "trade", "XBT/USD"], [0, {"a": [["55001.00000", "1.00000000", "1699999999.1234"]], "c": "1234"}, "book-10", "XBT/USD"], [0, [["55000.00000", "0.01000000", "1699999999.1234", "b", "m", ""]], "trade", "XBT/USD"], [0, {"a": [["55001.00000", "1.00000000", "1699999999.1234"]], "c": "1234"}, "book-10", "XBT/USD"], [0, [["55000.00000", "0.01000000", "1699999999.1234", "b", "m", ""]], "trade", "XBT/USD"], [0, {"a": [["55001.00000", "1.00000000", "1699999999.1234"]], "c": "1234"}, "book-10", "XBT/USD"], [0, [["55000.00000", "0.01000000", "1699999999.1234", "b", "m", ""]], "trade", "XBT/USD"], [0, {"a": [["55001.00000", "1.00000000", "1699999999.1234"]], "c": "1234"}, "book-10", "XBT/USD"], [0, [["55000.00000", "0.01000000", "1699999999.1234", "b", "m", ""]], "trade", "XBT/USD"], [0, {"a": [["55001.00000", "1.00000000", "1699999999.1234"]], "c": "1234"}, "book-10", "XBT/USD"], [0, [["55000.00000", "0.01000000", "1699999999.1234", "b", "m", ""]], "trade", "XBT/USD"], [0, {"a": [["55001.00000", "1.00000000", "1699999999.1234"]], "c": "1234"}, "book-10", "XBT/USD"], [0, [["55000.00000", "0.01000000", "1699999999.1234", "b", "m", ""]], "trade", "XBT/USD"], [0, {"a": [["55001.00000", "1.00000000", "1699999999.1234"]], "c": "1234"}, "book-10", "XBT/USD"], [0, [["55000.00000", "0.01000000", "1699999999.1234", "b", "m", ""]], "trade", "XBT/USD"], [0, {"a": [["55001.00000", "1.00000000", "1699999999.1234"]], "c": "1234"}, "book-10", "XBT/USD"], [0, [["55000.00000", "0.01000000", "1699999999.1234", "b", "m", ""]], "trade", "XBT/USD"], [0, {"a": [["55001.00000", "1.00000000", "1699999999.1234"]], "c": "1234"}, "book-10", "XBT/USD"], [0, [["55000.00000", "0.01000000", "1699999999.1234", "b", "m", ""]], "trade", "XBT/USD"], [0, {"a": [["55001.00000", "1.00000000", "1699999999.1234"]], "c": "1234"}, "book-10", "XBT/USD"], [0, [["55000.00000", "0.01000000", "1699999999.1234", "b", "m", ""]], "trade", "XBT/USD"], [0, {"a": [["55001.00000", "1.00000000", "1699999999.1234"]], "c": "1234"}, "book-10", "XBT/USD"], [0, [["55000.00000", "0.01000000", "1699999999.1234", "b", "m", ""]], "trade", "XBT/USD"], [0, {"a": [["55001.00000", "1.00000000", "1699999999.1234"]], "c": "1234"}, "book-10", "XBT/USD"], [0, [["55000.00000", "0.01000000", "1699999999.1234", "b", "m", ""]], "trade", "XBT/USD"], [0, {"a": [["55001.00000", "1.00000000", "1699999999.1234"]], "c": "1234"}, "book-10", "XBT/USD"], [0, [["55000.00000", "0.01000000", "1699999999.1234", "b", "m", ""]], "trade", "XBT/USD"], [0, {"a": [["55001.00000", "1.00000000", "1699999999.1234"]], "c": "1234"}, "book-10", "XBT/USD"], [0, [["55000.00000", "0.01000000", "1699999999.1234", "b", "m", ""]], "trade", "XBT/USD"], [0, {"a": [["55001.00000", "1.00000000", "1699999999.1234"]], "c": "1234"}, "book-10", "XBT/USD"], [0, [["55000.00000", "0.01000000", "1699999999.1234", "b", "m", ""]], "trade", "XBT/USD"], [0, {"a": [["55001.00000", "1.00000000", "1699999999.1234"]], "c": "1234"}, "book-10", "XBT/USD"], [0, [["55000.00000", "0.01000000", "1699999999.1234", "b", "m", ""]], "trade", "XBT/USD"], [0, {"a": [["55001.00000", "1.00000000", "1699999999.1234"]], "c": "1234"}, "book-10", "XBT/USD"], [0, [["55000.00000", "0.01000000", "1699999999.1234", "b", "m", ""]], "trade", "XBT/USD"], [0, {"a": [["55001.00000", "1.00000000", "1699999999.1234"]], "c": "1234"}, "book-10", "XBT/USD"], [0, [["55000.00000", "0.01000000", "1699999999.1234", "b", "m", ""]], "trade", "XBT/USD"], [0, {"a": [["55001.00000", "1.00000000", "1699999999.1234"]], "c": "1234"}, "book-10", "XBT/USD"], [0, [["55000.00000", "0.01000000", "1699999999.1234", "b", "m", ""]], "trade", "XBT/USD"], [0, {"a": [["55001.00000", "1.00000000", "1699999999.1234"]], "c": "1234"}, "book-10", "XBT/USD"], [0, [["55000.00000", "0.01000000", "1699999999.1234", "b", "m", ""]], "trade", "XBT/USD"], [0, {"a": [["55001.00000", "1.00000000", "1699999999.1234"]], "c": "1234"}, "book-10", "XBT/USD"], [0, [["55000.00000", "0.01000000", "1699999999.1234", "b", "m", ""]], "trade", "XBT/USD"], [0, {"a": [["55001.00000", "1.00000000", "1699999999.1234"]], "c": "1234"}, "book-10", "XBT/USD"], [0, [["55000.00000", "0.01000000", "1699999999.1234", "b", "m", ""]], "trade", "XBT/USD"], [0, {"a": [["55001.00000", "1.00000000", "1699999999.1234"]], "c": "1234"}, "book-10", "XBT/USD"], [0, [["55000.00000", "0.01000000", "1699999999.1234", "b", "m", ""]], "trade", "XBT/USD"], [0, {"a": [["55001.00000", "1.00000000", "1699999999.1234"]], "c": "1234"}, "book-10", "XBT/USD"], [0, [["55000.00000", "0.01000000", "1699999999.1234", "b", "m", ""]], "trade", "XBT/USD"], [0, {"a": [["55001.00000", "1.00000000", "1699999999.1234"]], "c": "1234"}, "book-10", "XBT/USD"], [0, [["55000.00000", "0.01000000", "1699999999.1234", "b", "m", ""]], "trade", "XBT/USD"], [0, {"a": [["55001.00000", "1.00000000", "1699999999.1234"]], "c": "1234"}, "book-10", "XBT/USD"], [0, [["55000.00000", "0.01000000", "1699999999.1234", "b", "m", ""]], "trade", "XBT/USD"], [0, {"a": [["55001.00000", "1.00000000", "1699999999.1234"]], "c": "1234"}, "book-10", "XBT/USD"], [0, [["55000.00000", "0.01000000", "1699999999.1234", "b", "m", ""]], "trade", "XBT/USD"], [0, {"a": [["55001.00000", "1.00000000", "1699999999.1234"]], "c": "1234"}, "book-10", "XBT/USD"], [0, [["55000.00000", "0.01000000", "1699999999.1234", "b", "m", ""]], "trade", "XBT/USD"], [0, {"a": [["55001.00000", "1.00000000", "1699999999.1234"]], "c": "1234"}, "book-10", "XBT/USD"], [0, [["55000.00000", "0.01000000", "1699999999.1234", "b", "m", ""]], "trade", "XBT/USD"], [0, {"a": [["55001.00000", "1.00000000", "1699999999.1234"]], "c": "1234"}, "book-10", "XBT/USD"], [0, [["55000.00000", "0.01000000", "1699999999.1234", "b", "m", ""]], "trade", "XBT/USD"], [0, {"a": [["55001.00000", "1.00000000", "1699999999.1234"]], "c": "1234"}, "book-10", "XBT/USD"], [0, [["55000.00000", "0.01000000", "1699999999.1234", "b", "m", ""]], "trade", "XBT/USD"], [0, {"a": [["55001.00000", "1.00000000", "1699999999.1234"]], "c": "1234"}, "book-10", "XBT/USD"], [0, [["55000.00000", "0.01000000", "1699999999.1234", "b", "m", ""]], "trade", "XBT/USD"], [0, {"a": [["55001.00000", "1.00000000", "1699999999.1234"]], "c": "1234"}, "book-10", "XBT/USD"], [0, [["55000.00000", "0.01000000", "1699999999.1234", "b", "m", ""]], "trade", "XBT/USD"], [0, {"a": [["55001.00000", "1.00000000", "1699999999.1234"]], "c": "1234"}, "book-10", "XBT/USD"], [0, [["55000.00000", "0.01000000", "1699999999.1234", "b", "m", ""]], "trade", "XBT/USD"], [0, {"a": [["55001.00000", "1.00000000", "1699999999.1234"]], "c": "1234"}, "book-10", "XBT/USD"], [0, [["55000.00000", "0.01000000", "1699999999.1234", "b", "m", ""]], "trade", "XBT/USD"], [0, {"a": [["55001.00000", "1.00000000", "1699999999.1234"]], "c": "1234"}, "book-10", "XBT/USD"], [0, [["55000.00000", "0.01000000", "1699999999.1234", "b", "m", ""]], "trade", "XBT/USD"], [0, {"a": [["55001.00000", "1.00000000", "1699999999.1234"]], "c": "1234"}, "book-10", "XBT/USD"], [0, [["55000.00000", "0.01000000", "1699999999.1234", "b", "m", ""]], "trade", "XBT/USD"], [0, {"a": [["55001.00000", "1.00000000", "1699999999.1234"]], "c": "1234"}, "book-10", "XBT/USD"], [0, [["55000.00000", "0.01000000", "1699999999.1234", "b", "m", ""]], "trade", "XBT/USD"], [0, {"a": [["55001.00000", "1.00000000", "1699999999.1234"]], "c": "1234"}, "book-10", "XBT/USD"], [0, [["55000.00000", "0.01000000", "1699999999.1234", "b", "m", ""]], "trade", "XBT/USD"], [0, {"a": [["55001.00000", "1.00000000", "1699999999.1234"]], "c": "1234"}, "book-10", "XBT/USD"], [0, [["55000.00000", "0.01000000", "1699999999.1234", "b", "m", ""]], "trade", "XBT/USD"], [0, {"a": [["55001.00000", "1.00000000", "1699999999.1234"]], "c": "1234"}, "book-10", "XBT/USD"], [0, [["55000.00000", "0.01000000", "1699999999.1234", "b", "m", ""]], "trade", "XBT/USD"], [0, {"a": [["55001.00000", "1.00000000", "1699999999.1234"]], "c": "1234"}, "book-10", "XBT/USD"], [0, [["55000.00000", "0.01000000", "1699999999.1234", "b", "m", ""]], "trade", "XBT/USD"], [0, {"a": [["55001.00000", "1.00000000", "1699999999.1234"]], "c": "1234"}, "book-10", "XBT/USD"], [0, [["55000.00000", "0.01000000", "1699999999.1234", "b", "m", ""]], "trade", "XBT/USD"], [0, {"a": [["55001.00000", "1.00000000", "1699999999.1234"]], "c": "1234"}, "book-10", "XBT/USD"], [0, [["55000.00000", "0.01000000", "1699999999.1234", "b", "m", ""]], "trade", "XBT/USD"], [0, {"a": [["55001.00000", "1.00000000", "1699999999.1234"]], "c": "1234"}, "book-10", "XBT/USD"], [0, [["55000.00000", "0.01000000", "1699999999.1234", "b", "m", ""]], "trade", "XBT/USD"], [0, {"a": [["55001.00000", "1.00000000", "1699999999.1234"]], "c": "1234"}, "book-10", "XBT/USD"], [0, [["55000.00000", "0.01000000", "1699999999.1234", "b", "m", ""]], "trade", "XBT/USD"], [0, {"a": [["55001.00000", "1.00000000", "1699999999.1234"]], "c": "1234"}, "book-10", "XBT/USD"], [0, [["55000.00000", "0.01000000", "1699999999.1234", "b", "m", ""]], "trade", "XBT/USD"], [0, {"a": [["55001.00000", "1.00000000", "1699999999.1234"]], "c": "1234"}, "book-10", "XBT/USD"], [0, [["55000.00000", "0.01000000", "1699999999.1234", "b", "m", ""]], "trade", "XBT/USD"], [0, {"a": [["55001.00000", "1.00000000", "1699999999.1234"]], "c": "1234"}, "book-10", "XBT/USD"], [0, [["55000.00000", "0.01000000", "1699999999.1234", "b", "m", ""]], "trade", "XBT/USD"], [0, {"a": [["55001.00000", "1.00000000", "1699999999.1234"]], "c": "1234"}, "book-10", "XBT/USD"], [0, [["55000.00000", "0.01000000", "1699999999.1234", "b", "m", ""]], "trade", "XBT/USD"], [0, {"a": [["55001.00000", "1.00000000", "1699999999.1234"]], "c": "1234"}, "book-10", "XBT/USD"], [0, [["55000.00000", "0.01000000", "1699999999.1234", "b", "m", ""]], "trade", "XBT/USD"], [0, {"a": [["55001.00000", "1.00000000", "1699999999.1234"]], "c": "1234"}, "book-10", "XBT/USD"], [0, [["55000.00000", "0.01000000", "1699999999.1234", "b", "m", ""]], "trade", "XBT/USD"], [0, {"a": [["55001.00000", "1.00000000", "1699999999.1234"]], "c": "1234"}, "book-10", "XBT/USD"], [0, [["55000.00000", "0.01000000", "1699999999.1234", "b", "m", ""]], "trade", "XBT/USD"], [0, {"a": [["55001.00000", "1.00000000", "1699999999.1234"]], "c": "1234"}, "book-10", "XBT/USD"], [0, [["55000.00000", "0.01000000", "1699999999.1234", "b", "m", ""]], "trade", "XBT/USD"], [0, {"a": [["55001.00000", "1.00000000", "1699999999.1234"]], "c": "1234"}, "book-10", "XBT/USD"], [0, [["55000.00000", "0.01000000", "1699999999.1234", "b", "m", ""]], "trade", "XBT/USD"], [0, {"a": [["55001.00000", "1.00000000", "1699999999.1234"]], "c": "1234"}, "book-10", "XBT/USD"], [0, [["55000.00000", "0.01000000", "1699999999.1234", "b", "m", ""]], "trade", "XBT/USD"], [0, {"a": [["55001.00000", "1.00000000", "1699999999.1234"]], "c": "1234"}, "book-10", "XBT/USD"], [0, [["55000.00000", "0.01000000", "1699999999.1234", "b", "m", ""]], "trade", "XBT/USD"], [0, {"a": [["55001.00000", "1.00000000", "1699999999.1234"]], "c": "1234"}, "book-10", "XBT/USD"], [0, [["55000.00000", "0.01000000", "1699999999.1234", "b", "m", ""]], "trade", "XBT/USD"], [0, {"a": [["55001.00000", "1.00000000", "1699999999.1234"]], "c": "1234"}, "book-10", "XBT/USD"], [0, [["55000.00000", "0.01000000", "1699999999.1234", "b", "m", ""]], "trade", "XBT/USD"], [0, {"a": [["55001.00000", "1.00000000", "1699999999.1234"]], "c": "1234"}, "book-10", "XBT/USD"], [0, [["55000.00000", "0.01000000", "1699999999.1234", "b", "m", ""]], "trade", "XBT/USD"], [0, {"a": [["55001.00000", "1.00000000", "1699999999.1234"]], "c": "1234"}, "book-10", "XBT/USD"], [0, [["55000.00000", "0.01000000", "1699999999.1234", "b", "m", ""]], "trade", "XBT/USD"], [0, {"a": [["55001.00000", "1.00000000", "1699999999.1234"]], "c": "1234"}, "book-10", "XBT/USD"], [0, [["55000.00000", "0.01000000", "1699999999.1234", "b", "m", ""]], "trade", "XBT/USD"], [0, {"a": [["55001.00000", "1.00000000", "1699999999.1234"]], "c": "1234"}, "book-10", "XBT/USD"], [0, [["55000.00000", "0.01000000", "1699999999.1234", "b", "m", ""]], "trade", "XBT/USD"], [0, {"a": [["55001.00000", "1.00000000", "1699999999.1234"]], "c": "1234"}, "book-10", "XBT/USD"], [0, [["55000.00000", "0.01000000", "1699999999.1234", "b", "m", ""]], "trade", "XBT/USD"], [0, {"a": [["55001.00000", "1.00000000", "1699999999.1234"]], "c": "1234"}, "book-10", "XBT/USD"], [0, [["55000.00000", "0.01000000", "1699999999.1234", "b", "m", ""]], "trade", "XBT/USD"], [0, {"a": [["55001.00000", "1.00000000", "1699999999.1234"]], "c": "1234"}, "book-10", "XBT/USD"], [0, [["55000.00000", "0.01000000", "1699999999.1234", "b", "m", ""]], "trade", "XBT/USD"], [0, {"a": [["55001.00000", "1.00000000", "1699999999.1234"]], "c": "1234"}, "book-10", "XBT/USD"], [0, [["55000.00000", "0.01000000", "1699999999.1234", "b", "m", ""]], "trade", "XBT/USD"], [0, {"a": [["55001.00000", "1.00000000", "1699999999.1234"]], "c": "1234"}, "book-10", "XBT/USD"], [0, [["55000.00000", "0.01000000", "1699999999.1234", "b", "m", ""]], "trade", "XBT/USD"], [0, {"a": [["55001.00000", "1.00000000", "1699999999.1234"]], "c": "1234"}, "book-10", "XBT/USD"], [0, [["55000.00000", "0.01000000", "1699999999.1234", "b", "m", ""]], "trade", "XBT/USD"], [0, {"a": [["55001.00000", "1.00000000", "1699999999.1234"]], "c": "1234"}, "book-10", "XBT/USD"], [0, [["55000.00000", "0.01000000", "1699999999.1234", "b", "m", ""]], "trade", "XBT/USD"], [0, {"a": [["55001.00000", "1.00000000", "1699999999.1234"]], "c": "1234"}, "book-10", "XBT/USD"], [0, [["55000.00000", "0.01000000", "1699999999.1234", "b", "m", ""]], "trade", "XBT/USD"], [0, {"a": [["55001.00000", "1.00000000", "1699999999.1234"]], "c": "1234"}, "book-10", "XBT/USD"], [0, [["55000.00000", "0.01000000", "1699999999.1234", "b", "m", ""]], "trade", "XBT/USD"], [0, {"a": [["55001.00000", "1.00000000", "1699999999.1234"]], "c": "1234"}, "book-10", "XBT/USD"], [0, [["55000.00000", "0.01000000", "1699999999.1234", "b", "m", ""]], "trade", "XBT/USD"], [0, {"a": [["55001.00000", "1.00000000", "1699999999.1234"]], "c": "1234"}, "book-10", "XBT/USD"], [0, [["55000.00000", "0.01000000", "1699999999.1234", "b", "m", ""]], "trade", "XBT/USD"], [0, {"a": [["55001.00000", "1.00000000", "1699999999.1234"]], "c": "1234"}, "book-10", "XBT/USD"], [0, [["55000.00000", "0.01000000", "1699999999.1234", "b", "m", ""]], "trade", "XBT/USD"], [0, {"a": [["55001.00000", "1.00000000", "1699999999.1234"]], "c": "1234"}, "book-10", "XBT/USD"], [0, [["55000.00000", "0.01000000", "1699999999.1234", "b", "m", ""]], "trade", "XBT/USD"], [0, {"a": [["55001.00000", "1.00000000", "1699999999.1234"]], "c": "1234"}, "book-10", "XBT/USD"], [0, [["55000.00000", "0.01000000", "1699999999.1234", "b", "m", ""]], "trade", "XBT/USD"], [0, {"a": [["55001.00000", "1.00000000", "1699999999.1234"]], "c": "1234"}, "book-10", "XBT/USD"], [0, [["55000.00000", "0.01000000", "1699999999.1234", "b", "m", ""]], "trade", "XBT/USD"], [0, {"a": [["55001.00000", "1.00000000", "1699999999.1234"]], "c": "1234"}, "book-10", "XBT/USD"], [0, [["55000.00000", "0.01000000", "1699999999.1234", "b", "m", ""]], "trade", "XBT/USD"], [0, {"a": [["55001.00000", "1.00000000", "1699999999.1234"]], "c": "1234"}, "book-10", "XBT/USD"], [0, [["55000.00000", "0.01000000", "1699999999.1234", "b", "m", ""]], "trade", "XBT/USD"], [0, {"a": [["55001.00000", "1.00000000", "1699999999.1234"]], "c": "1234"}, "book-10", "XBT/USD"], [0, [["55000.00000", "0.01000000", "1699999999.1234", "b", "m", ""]], "trade", "XBT/USD"], [0, {"a": [["55001.00000", "1.00000000", "1699999999.1234"]], "c": "1234"}, "book-10", "XBT/USD"], [0, [["55000.00000", "0.01000000", "1699999999.1234", "b", "m", ""]], "trade", "XBT/USD"], [0, {"a": [["55001.00000", "1.00000000", "1699999999.1234"]], "c": "1234"}, "book-10", "XBT/USD"], [0, [["55000.00000", "0.01000000", "1699999999.1234", "b", "m", ""]], "trade", "XBT/USD"], [0, {"a": [["55001.00000", "1.00000000", "1699999999.1234"]], "c": "1234"}, "book-10", "XBT/USD"], [0, [["55000.00000", "0.01000000", "1699999999.1234", "b", "m", ""]], "trade", "XBT/USD"], [0, {"a": [["55001.00000", "1.00000000", "1699999999.1234"]], "c": "1234"}, "book-10", "XBT/USD"], [0, [["55000.00000", "0.01000000", "1699999999.1234", "b", "m", ""]], "trade", "XBT/USD"], [0, {"a": [["55001.00000", "1.00000000", "1699999999.1234"]], "c": "1234"}, "book-10", "XBT/USD"], [0, [["55000.00000", "0.01000000", "1699999999.1234", "b", "m", ""]], "trade", "XBT/USD"], [0, {"a": [["55001.00000", "1.00000000", "1699999999.1234"]], "c": "1234"}, "book-10", "XBT/USD"], [0, [["55000.00000", "0.01000000", "1699999999.1234", "b", "m", ""]], "trade", "XBT/USD"], [0, {"a": [["55001.00000", "1.00000000", "1699999999.1234"]], "c": "1234"}, "book-10", "XBT/USD"], [0, [["55000.00000", "0.01000000", "1699999999.1234", "b", "m", ""]], "trade", "XBT/USD"], [0, {"a": [["55001.00000", "1.00000000", "1699999999.1234"]], "c": "1234"}, "book-10", "XBT/USD"], [0, [["55000.00000", "0.01000000", "1699999999.1234", "b", "m", ""]], "trade", "XBT/USD"], [0, {"a": [["55001.00000", "1.00000000", "1699999999.1234"]], "c": "1234"}, "book-10", "XBT/USD"], [0, [["55000.00000", "0.01000000", "1699999999.1234", "b", "m", ""]], "trade", "XBT/USD"], [0, {"a": [["55001.00000", "1.00000000", "1699999999.1234"]], "c": "1234"}, "book-10", "XBT/USD"], [0, [["55000.00000", "0.01000000", "1699999999.1234", "b", "m", ""]], "trade", "XBT/USD"], [0, {"a": [["55001.00000", "1.00000000", "1699999999.1234"]], "c": "1234"}, "book-10", "XBT/USD"], [0, [["55000.00000", "0.01000000", "1699999999.1234", "b", "m", ""]], "trade", "XBT/USD"], [0, {"a": [["55001.00000", "1.00000000", "1699999999.1234"]], "c": "1234"}, "book-10", "XBT/USD"], [0, [["55000.00000", "0.01000000", "1699999999.1234", "b", "m", ""]], "trade", "XBT/USD"], [0, {"a": [["55001.00000", "1.00000000", "1699999999.1234"]], "c": "1234"}, "book-10", "XBT/USD"], [0, [["55000.00000", "0.01000000", "1699999999.1234", "b", "m", ""]], "trade", "XBT/USD"], [0, {"a": [["55001.00000", "1.00000000", "1699999999.1234"]], "c": "1234"}, "book-10", "XBT/USD"], [0, [["55000.00000", "0.01000000", "1699999999.1234", "b", "m", ""]], "trade", "XBT/USD"], [0, {"a": [["55001.00000", "1.00000000", "1699999999.1234"]], "c": "1234"}, "book-10", "XBT/USD"], [0, [["55000.00000", "0.01000000", "1699999999.1234", "b", "m", ""]], "trade", "XBT/USD"], [0, {"a": [["55001.00000", "1.00000000", "1699999999.1234"]], "c": "1234"}, "book-10", "XBT/USD"], [0, [["55000.00000", "0.01000000", "1699999999.1234", "b", "m", ""]], "trade", "XBT/USD"], [0, {"a": [["55001.00000", "1.00000000", "1699999999.1234"]], "c": "1234"}, "book-10", "XBT/USD"], [0, [["55000.00000", "0.01000000", "1699999999.1234", "b", "m", ""]], "trade", "XBT/USD"], [0, {"a": [["55001.00000", "1.00000000", "1699999999.1234"]], "c": "1234"}, "book-10", "XBT/USD"], [0, [["55000.00000", "0.01000000", "1699999999.1234", "b", "m", ""]], "trade", "XBT/USD"], [0, {"a": [["55001.00000", "1.00000000", "1699999999.1234"]], "c": "1234"}, "book-10", "XBT/USD"], [0, [["55000.00000", "0.01000000", "1699999999.1234", "b", "m", ""]], "trade", "XBT/USD"], [0, {"a": [["55001.00000", "1.00000000", "1699999999.1234"]], "c": "1234"}, "book-10", "XBT/USD"], [0, [["55000.00000", "0.01000000", "1699999999.1234", "b", "m", ""]], "trade", "XBT/USD"], [0, {"a": [["55001.00000", "1.00000000", "1699999999.1234"]], "c": "1234"}, "book-10", "XBT/USD"], [0, [["55000.00000", "0.01000000", "1699999999.1234", "b", "m", ""]], "trade", "XBT/USD"], [0, {"a": [["55001.00000", "1.00000000", "1699999999.1234"]], "c": "1234"}, "book-10", "XBT/USD"], [0, [["55000.00000", "0.01000000", "1699999999.1234", "b", "m", ""]], "trade", "XBT/USD"], [0, {"a": [["55001.00000", "1.00000000", "1699999999.1234"]], "c": "1234"}, "book-10", "XBT/USD"], [0, [["55000.00000", "0.01000000", "1699999999.1234", "b", "m", ""]], "trade", "XBT/USD"], [0, {"a": [["55001.00000", "1.00000000", "1699999999.1234"]], "c": "1234"}, "book-10", "XBT/USD"], [0, [["55000.00000", "0.01000000", "1699999999.1234", "b", "m", ""]], "trade", "XBT/USD"], [0, {"a": [["55001.00000", "1.00000000", "1699999999.1234"]], "c": "1234"}, "book-10", "XBT/USD"], [0, [["55000.00000", "0.01000000", "1699999999.1234", "b", "m", ""]], "trade", "XBT/USD"], [0, {"a": [["55001.00000", "1.00000000", "1699999999.1234"]], "c": "1234"}, "book-10", "XBT/USD"], [0, [["55000.00000", "0.01000000", "1699999999.1234", "b", "m", ""]], "trade", "XBT/USD"], [0, {"a": [["55001.00000", "1.00000000", "1699999999.1234"]], "c": "1234"}, "book-10", "XBT/USD"], [0, [["55000.00000", "0.01000000", "1699999999.1234", "b", "m", ""]], "trade", "XBT/USD"], [0, {"a": [["55001.00000", "1.00000000", "1699999999.1234"]], "c": "1234"}, "book-10", "XBT/USD"], [0, [["55000.00000", "0.01000000", "1699999999.1234", "b", "m", ""]], "trade", "XBT/USD"], [0, {"a": [["55001.00000", "1.00000000", "1699999999.1234"]], "c": "1234"}, "book-10", "XBT/USD"], [0, [["55000.00000", "0.01000000", "1699999999.1234", "b", "m", ""]], "trade", "XBT/USD"], [0, {"a": [["55001.00000", "1.00000000", "1699999999.1234"]], "c": "1234"}, "book-10", "XBT/USD"], [0, [["55000.00000", "0.01000000", "1699999999.1234", "b", "m", ""]], "trade", "XBT/USD"], [0, {"a": [["55001.00000", "1.00000000", "1699999999.1234"]], "c": "1234"}, "book-10", "XBT/USD"], [0, [["55000.00000", "0.01000000", "1699999999.1234", "b", "m", ""]], "trade", "XBT/USD"], [0, {"a": [["55001.00000", "1.00000000", "1699999999.1234"]], "c": "1234"}, "book-10", "XBT/USD"], [0, [["55000.00000", "0.01000000", "1699999999.1234", "b", "m", ""]], "trade", "XBT/USD"], [0, {"a": [["55001.00000", "1.00000000", "1699999999.1234"]], "c": "1234"}, "book-10", "XBT/USD"], [0, [["55000.00000", "0.01000000", "1699999999.1234", "b", "m", ""]], "trade", "XBT/USD"], [0, {"a": [["55001.00000", "1.00000000", "1699999999.1234"]], "c": "1234"}, "book-10", "XBT/USD"], [0, [["55000.00000", "0.01000000", "1699999999.1234", "b", "m", ""]], "trade", "XBT/USD"], [0, {"a": [["55001.00000", "1.00000000", "1699999999.1234"]], "c": "1234"}, "book-10", "XBT/USD"], [0, [["55000.00000", "0.01000000", "1699999999.1234", "b", "m", ""]], "trade", "XBT/USD"], [0, {"a": [["55001.00000", "1.00000000", "1699999999.1234"]], "c": "1234"}, "book-10", "XBT/USD"], [0, [["55000.00000", "0.01000000", "1699999999.1234", "b", "m", ""]], "trade", "XBT/USD"], [0, {"a": [["55001.00000", "1.00000000", "1699999999.1234"]], "c": "1234"}, "book-10", "XBT/USD"], [0, [["55000.00000", "0.01000000", "1699999999.1234", "b", "m", ""]], "trade", "XBT/USD"], [0, {"a": [["55001.00000", "1.00000000", "1699999999.1234"]], "c": "1234"}, "book-10", "XBT/USD"], [0, [["55000.00000", "0.01000000", "1699999999.1234", "b", "m", ""]], "trade", "XBT/USD"], [0, {"a": [["55001.00000", "1.00000000", "1699999999.1234"]], "c": "1234"}, "book-10", "XBT/USD"], [0, [["55000.00000", "0.01000000", "1699999999.1234", "b", "m", ""]], "trade", "XBT/USD"], [0, {"a": [["55001.00000", "1.00000000", "1699999999.1234"]], "c": "1234"}, "book-10", "XBT/USD"], [0, [["55000.00000", "0.01000000", "1699999999.1234", "b", "m", ""]], "trade", "XBT/USD"], [0, {"a": [["55001.00000", "1.00000000", "1699999999.1234"]], "c": "1234"}, "book-10", "XBT/USD"], [0, [["55000.00000", "0.01000000", "1699999999.1234", "b", "m", ""]], "trade", "XBT/USD"], [0, {"a": [["55001.00000", "1.00000000", "1699999999.1234"]], "c": "1234"}, "book-10", "XBT/USD"], [0, [["55000.00000", "0.01000000", "1699999999.1234", "b", "m", ""]], "trade", "XBT/USD"], [0, {"a": [["55001.00000", "1.00000000", "1699999999.1234"]], "c": "1234"}, "book-10", "XBT/USD"], [0, [["55000.00000", "0.01000000", "1699999999.1234", "b", "m", ""]], "trade", "XBT/USD"], [0, {"a": [["55001.00000", "1.00000000", "1699999999.1234"]], "c": "1234"}, "book-10", "XBT/USD"], [0, [["55000.00000", "0.01000000", "1699999999.1234", "b", "m", ""]], "trade", "XBT/USD"], [0, {"a": [["55001.00000", "1.00000000", "1699999999.1234"]], "c": "1234"}, "book-10", "XBT/USD"], [0, [["55000.00000", "0.01000000", "1699999999.1234", "b", "m", ""]], "trade", "XBT/USD"], [0, {"a": [["55001.00000", "1.00000000", "1699999999.1234"]], "c": "1234"}, "book-10", "XBT/USD"], [0, [["55000.00000", "0.01000000", "1699999999.1234", "b", "m", ""]], "trade", "XBT/USD"], [0, {"a": [["55001.00000", "1.00000000", "1699999999.1234"]], "c": "1234"}, "book-10", "XBT/USD"], [0, [["55000.00000", "0.01000000", "1699999999.1234", "b", "m", ""]], "trade", "XBT/USD"], [0, {"a": [["55001.00000", "1.00000000", "1699999999.1234"]], "c": "1234"}, "book-10", "XBT/USD"], [0, [["55000.00000", "0.01000000", "1699999999.1234", "b", "m", ""]], "trade", "XBT/USD"], [0, {"a": [["55001.00000", "1.00000000", "1699999999.1234"]], "c": "1234"}, "book-10", "XBT/USD"], [0, [["55000.00000", "0.01000000", "1699999999.1234", "b", "m", ""]], "trade", "XBT/USD"], [0, {"a": [["55001.00000", "1.00000000", "1699999999.1234"]], "c": "1234"}, "book-10", "XBT/USD"], [0, [["55000.00000", "0.01000000", "1699999999.1234", "b", "m", ""]], "trade", "XBT/USD"], [0, {"a": [["55001.00000", "1.00000000", "1699999999.1234"]], "c": "1234"}, "book-10", "XBT/USD"], [0, [["55000.00000", "0.01000000", "1699999999.1234", "b", "m", ""]], "trade", "XBT/USD"], [0, {"a": [["55001.00000", "1.00000000", "1699999999.1234"]], "c": "1234"}, "book-10", "XBT/USD"], [0, [["55000.00000", "0.01000000", "1699999999.1234", "b", "m", ""]], "trade", "XBT/USD"], [0, {"a": [["55001.00000", "1.00000000", "1699999999.1234"]], "c": "1234"}, "book-10", "XBT/USD"], [0, [["55000.00000", "0.01000000", "1699999999.1234", "b", "m", ""]], "trade", "XBT/USD"], [0, {"a": [["55001.00000", "1.00000000", "1699999999.1234"]], "c": "1234"}, "book-10", "XBT/USD"], [0, [["55000.00000", "0.01000000", "1699999999.1234", "b", "m", ""]], "trade", "XBT/USD"], [0, {"a": [["55001.00000", "1.00000000", "1699999999.1234"]], "c": "1234"}, "book-10", "XBT/USD"], [0, [["55000.00000", "0.01000000", "1699999999.1234", "b", "m", ""]], "trade", "XBT/USD"], [0, {"a": [["55001.00000", "1.00000000", "1699999999.1234"]], "c": "1234"}, "book-10", "XBT/USD"], [0, [["55000.00000", "0.01000000", "1699999999.1234", "b", "m", ""]], "trade", "XBT/USD"], [0, {"a": [["55001.00000", "1.00000000", "1699999999.1234"]], "c": "1234"}, "book-10", "XBT/USD"], [0, [["55000.00000", "0.01000000", "1699999999.1234", "b", "m", ""]], "trade", "XBT/USD"], [0, {"a": [["55001.00000", "1.00000000", "1699999999.1234"]], "c": "1234"}, "book-10", "XBT/USD"], [0, [["55000.00000", "0.01000000", "1699999999.1234", "b", "m", ""]], "trade", "XBT/USD"], [0, {"a": [["55001.00000", "1.00000000", "1699999999.1234"]], "c": "1234"}, "book-10", "XBT/USD"], [0, [["55000.00000", "0.01000000", "1699999999.1234", "b", "m", ""]], "trade", "XBT/USD"], [0, {"a": [["55001.00000", "1.00000000", "1699999999.1234"]], "c": "1234"}, "book-10", "XBT/USD"], [0, [["55000.00000", "0.01000000", "1699999999.1234", "b", "m", ""]], "trade", "XBT/USD"], [0, {"a": [["55001.00000", "1.00000000", "1699999999.1234"]], "c": "1234"}, "book-10", "XBT/USD"], [0, [["55000.00000", "0.01000000", "1699999999.1234", "b", "m", ""]], "trade", "XBT/USD"], [0, {"a": [["55001.00000", "1.00000000", "1699999999.1234"]], "c": "1234"}, "book-10", "XBT/USD"], [0, [["55000.00000", "0.01000000", "1699999999.1234", "b", "m", ""]], "trade", "XBT/USD"], [0, {"a": [["55001.00000", "1.00000000", "1699999999.1234"]], "c": "1234"}, "book-10", "XBT/USD"], [0, [["55000.00000", "0.01000000", "1699999999.1234", "b", "m", ""]], "trade", "XBT/USD"], [0, {"a": [["55001.00000", "1.00000000", "1699999999.1234"]], "c": "1234"}, "book-10", "XBT/USD"], [0, [["55000.00000", "0.01000000", "1699999999.1234", "b", "m", ""]], "trade", "XBT/USD"], [0, {"a": [["55001.00000", "1.00000000", "1699999999.1234"]], "c": "1234"}, "book-10", "XBT/USD"], [0, [["55000.00000", "0.01000000", "1699999999.1234", "b", "m", ""]], "trade", "XBT/USD"], [0, {"a": [["55001.00000", "1.00000000", "1699999999.1234"]], "c": "1234"}, "book-10", "XBT/USD"], [0, [["55000.00000", "0.01000000", "1699999999.1234", "b", "m", ""]], "trade", "XBT/USD"], [0, {"a": [["55001.00000", "1.00000000", "1699999999.1234"]], "c": "1234"}, "book-10", "XBT/USD"], [0, [["55000.00000", "0.01000000", "1699999999.1234", "b", "m", ""]], "trade", "XBT/USD"], [0, {"a": [["55001.00000", "1.00000000", "1699999999.1234"]], "c": "1234"}, "book-10", "XBT/USD"], [0, [["55000.00000", "0.01000000", "1699999999.1234", "b", "m", ""]], "trade", "XBT/USD"], [0, {"a": [["55001.00000", "1.00000000", "1699999999.1234"]], "c": "1234"}, "book-10", "XBT/USD"], [0, [["55000.00000", "0.01000000", "1699999999.1234", "b", "m", ""]], "trade", "XBT/USD"], [0, {"a": [["55001.00000", "1.00000000", "1699999999.1234"]], "c": "1234"}, "book-10", "XBT/USD"], [0, [["55000.00000", "0.01000000", "1699999999.1234", "b", "m", ""]], "trade", "XBT/USD"], [0, {"a": [["55001.00000", "1.00000000", "1699999999.1234"]], "c": "1234"}, "book-10", "XBT/USD"], [0, [["55000.00000", "0.01000000", "1699999999.1234", "b", "m", ""]], "trade", "XBT/USD"], [0, {"a": [["55001.00000", "1.00000000", "1699999999.1234"]], "c": "1234"}, "book-10", "XBT/USD"], [0, [["55000.00000", "0.01000000", "1699999999.1234", "b", "m", ""]], "trade", "XBT/USD"], [0, {"a": [["55001.00000", "1.00000000", "1699999999.1234"]], "c": "1234"}, "book-10", "XBT/USD"], [0, [["55000.00000", "0.01000000", "1699999999.1234", "b", "m", ""]], "trade", "XBT/USD"], [0, {"a": [["55001.00000", "1.00000000", "1699999999.1234"]], "c": "1234"}, "book-10", "XBT/USD"], [0, [["55000.00000", "0.01000000", "1699999999.1234", "b", "m", ""]], "trade", "XBT/USD"], [0, {"a": [["55001.00000", "1.00000000", "1699999999.1234"]], "c": "1234"}, "book-10", "XBT/USD"], [0, [["55000.00000", "0.01000000", "1699999999.1234", "b", "m", ""]], "trade", "XBT/USD"], [0, {"a": [["55001.00000", "1.00000000", "1699999999.1234"]], "c": "1234"}, "book-10", "XBT/USD"], [0, [["55000.00000", "0.01000000", "1699999999.1234", "b", "m", ""]], "trade", "XBT/USD"], [0, {"a": [["55001.00000", "1.00000000", "1699999999.1234"]], "c": "1234"}, "book-10", "XBT/USD"], [0, [["55000.00000", "0.01000000", "1699999999.1234", "b", "m", ""]], "trade", "XBT/USD"], [0, {"a": [["55001.00000", "1.00000000", "1699999999.1234"]], "c": "1234"}, "book-10", "XBT/USD"], [0, [["55000.00000", "0.01000000", "1699999999.1234", "b", "m", ""]], "trade", "XBT/USD"], [0, {"a": [["55001.00000", "1.00000000", "1699999999.1234"]], "c": "1234"}, "book-10", "XBT/USD"], [0, [["55000.00000", "0.01000000", "1699999999.1234", "b", "m", ""]], "trade", "XBT/USD"], [0, {"a": [["55001.00000", "1.00000000", "1699999999.1234"]], "c": "1234"}, "book-10", "XBT/USD"], [0, [["55000.00000", "0.01000000", "1699999999.1234", "b", "m", ""]], "trade", "XBT/USD"], [0, {"a": [["55001.00000", "1.00000000", "1699999999.1234"]], "c": "1234"}, "book-10", "XBT/USD"], [0, [["55000.00000", "0.01000000", "1699999999.1234", "b", "m", ""]], "trade", "XBT/USD"], [0, {"a": [["55001.00000", "1.00000000", "1699999999.1234"]], "c": "1234"}, "book-10", "XBT/USD"], [0, [["55000.00000", "0.01000000", "1699999999.1234", "b", "m", ""]], "trade", "XBT/USD"], [0, {"a": [["55001.00000", "1.00000000", "1699999999.1234"]], "c": "1234"}, "book-10", "XBT/USD"], [0, [["55000.00000", "0.01000000", "1699999999.1234", "b", "m", ""]], "trade", "XBT/USD"], [0, {"a": [["55001.00000", "1.00000000", "1699999999.1234"]], "c": "1234"}, "book-10", "XBT/USD"], [0, [["55000.00000", "0.01000000", "1699999999.1234", "b", "m", ""]], "trade", "XBT/USD"], [0, {"a": [["55001.00000", "1.00000000", "1699999999.1234"]], "c": "1234"}, "book-10", "XBT/USD"], [0, [["55000.00000", "0.01000000", "1699999999.1234", "b", "m", ""]], "trade", "XBT/USD"], [0, {"a": [["55001.00000", "1.00000000", "1699999999.1234"]], "c": "1234"}, "book-10", "XBT/USD"], [0, [["55000.00000", "0.01000000", "1699999999.1234", "b", "m", ""]], "trade", "XBT/USD"], [0, {"a": [["55001.00000", "1.00000000", "1699999999.1234"]], "c": "1234"}, "book-10", "XBT/USD"], [0, [["55000.00000", "0.01000000", "1699999999.1234", "b", "m", ""]], "trade", "XBT/USD"], [0, {"a": [["55001.00000", "1.00000000", "1699999999.1234"]], "c": "1234"}, "book-10", "XBT/USD"], [0, [["55000.00000", "0.01000000", "1699999999.1234", "b", "m", ""]], "trade", "XBT/USD"], [0, {"a": [["55001.00000", "1.00000000", "1699999999.1234"]], "c": "1234"}, "book-10", "XBT/USD"], [0, [["55000.00000", "0.01000000", "1699999999.1234", "b", "m", ""]], "trade", "XBT/USD"], [0, {"a": [["55001.00000", "1.00000000", "1699999999.1234"]], "c": "1234"}, "book-10", "XBT/USD"], [0, [["55000.00000", "0.01000000", "1699999999.1234", "b", "m", ""]], "trade", "XBT/USD"], [0, {"a": [["55001.00000", "1.00000000", "1699999999.1234"]], "c": "1234"}, "book-10", "XBT/USD"], [0, [["55000.00000", "0.01000000", "1699999999.1234", "b", "m", ""]], "trade", "XBT/USD"], [0, {"a": [["55001.00000", "1.00000000", "1699999999.1234"]], "c": "1234"}, "book-10", "XBT/USD"], [0, [["55000.00000", "0.01000000", "1699999999.1234", "b", "m", ""]], "trade", "XBT/USD"], [0, {"a": [["55001.00000", "1.00000000", "1699999999.1234"]], "c": "1234"}, "book-10", "XBT/USD"], [0, [["55000.00000", "0.01000000", "1699999999.1234", "b", "m", ""]], "trade", "XBT/USD"], [0, {"a": [["55001.00000", "1.00000000", "1699999999.1234"]], "c": "1234"}, "book-10", "XBT/USD"], [0, [["55000.00000", "0.01000000", "1699999999.1234", "b", "m", ""]], "trade", "XBT/USD"], [0, {"a": [["55001.00000", "1.00000000", "1699999999.1234"]], "c": "1234"}, "book-10", "XBT/USD"], [0, [["55000.00000", "0.01000000", "1699999999.1234", "b", "m", ""]], "trade", "XBT/USD"], [0, {"a": [["55001.00000", "1.00000000", "1699999999.1234"]], "c": "1234"}, "book-10", "XBT/USD"], [0, [["55000.00000", "0.01000000", "1699999999.1234", "b", "m", ""]], "trade", "XBT/USD"], [0, {"a": [["55001.00000", "1.00000000", "1699999999.1234"]], "c": "1234"}, "book-10", "XBT/USD"], [0, [["55000.00000", "0.01000000", "1699999999.1234", "b", "m", ""]], "trade", "XBT/USD"], [0, {"a": [["55001.00000", "1.00000000", "1699999999.1234"]], "c": "1234"}, "book-10", "XBT/USD"], [0, [["55000.00000", "0.01000000", "1699999999.1234", "b", "m", ""]], "trade", "XBT/USD"], [0, {"a": [["55001.00000", "1.00000000", "1699999999.1234"]], "c": "1234"}, "book-10", "XBT/USD"], [0, [["55000.00000", "0.01000000", "1699999999.1234", "b", "m", ""]], "trade", "XBT/USD"], [0, {"a": [["55001.00000", "1.00000000", "1699999999.1234"]], "c": "1234"}, "book-10", "XBT/USD"], [0, [["55000.00000", "0.01000000", "1699999999.1234", "b", "m", ""]], "trade", "XBT/USD"], [0, {"a": [["55001.00000", "1.00000000", "1699999999.1234"]], "c": "1234"}, "book-10", "XBT/USD"], [0, [["55000.00000", "0.01000000", "1699999999.1234", "b", "m", ""]], "trade", "XBT/USD"], [0, {"a": [["55001.00000", "1.00000000", "1699999999.1234"]], "c": "1234"}, "book-10", "XBT/USD"], [0, [["55000.00000", "0.01000000", "1699999999.1234", "b", "m", ""]], "trade", "XBT/USD"], [0, {"a": [["55001.00000", "1.00000000", "1699999999.1234"]], "c": "1234"}, "book-10", "XBT/USD"], [0, [["55000.00000", "0.01000000", "1699999999.1234", "b", "m", ""]], "trade", "XBT/USD"], [0, {"a": [["55001.00000", "1.00000000", "1699999999.1234"]], "c": "1234"}, "book-10", "XBT/USD"], [0, [["55000.00000", "0.01000000", "1699999999.1234", "b", "m", ""]], "trade", "XBT/USD"], [0, {"a": [["55001.00000", "1.00000000", "1699999999.1234"]], "c": "1234"}, "book-10", "XBT/USD"], [0, [["55000.00000", "0.01000000", "1699999999.1234", "b", "m", ""]], "trade", "XBT/USD"], [0, {"a": [["55001.00000", "1.00000000", "1699999999.1234"]], "c": "1234"}, "book-10", "XBT/USD"], [0, [["55000.00000", "0.01000000", "1699999999.1234", "b", "m", ""]], "trade", "XBT/USD"], [0, {"a": [["55001.00000", "1.00000000", "1699999999.1234"]], "c": "1234"}, "book-10", "XBT/USD"], [0, [["55000.00000", "0.01000000", "1699999999.1234", "b", "m", ""]], "trade", "XBT/USD"], [0, {"a": [["55001.00000", "1.00000000", "1699999999.1234"]], "c": "1234"}, "book-10", "XBT/USD"], [0, [["55000.00000", "0.01000000", "1699999999.1234", "b", "m", ""]], "trade", "XBT/USD"], [0, {"a": [["55001.00000", "1.00000000", "1699999999.1234"]], "c": "1234"}, "book-10", "XBT/USD"], [0, [["55000.00000", "0.01000000", "1699999999.1234", "b", "m", ""]], "trade", "XBT/USD"], [0, {"a": [["55001.00000", "1.00000000", "1699999999.1234"]], "c": "1234"}, "book-10", "XBT/USD"], [0, [["55000.00000", "0.01000000", "1699999999.1234", "b", "m", ""]], "trade", "XBT/USD"], [0, {"a": [["55001.00000", "1.00000000", "1699999999.1234"]], "c": "1234"}, "book-10", "XBT/USD"], [0, [["55000.00000", "0.01000000", "1699999999.1234", "b", "m", ""]], "trade", "XBT/USD"], [0, {"a": [["55001.00000", "1.00000000", "1699999999.1234"]], "c": "1234"}, "book-10", "XBT/USD"], [0, [["55000.00000", "0.01000000", "1699999999.1234", "b", "m", ""]], "trade", "XBT/USD"], [0, {"a": [["55001.00000", "1.00000000", "1699999999.1234"]], "c": "1234"}, "book-10", "XBT/USD"], [0, [["55000.00000", "0.01000000", "1699999999.1234", "b", "m", ""]], "trade", "XBT/USD"], [0, {"a": [["55001.00000", "1.00000000", "1699999999.1234"]], "c": "1234"}, "book-10", "XBT/USD"], [0, [["55000.00000", "0.01000000", "1699999999.1234", "b", "m", ""]], "trade", "XBT/USD"], [0, {"a": [["55001.00000", "1.00000000", "1699999999.1234"]], "c": "1234"}, "book-10", "XBT/USD"], [0, [["55000.00000", "0.01000000", "1699999999.1234", "b", "m", ""]], "trade", "XBT/USD"], [0, {"a": [["55001.00000", "1.00000000", "1699999999.1234"]], "c": "1234"}, "book-10", "XBT/USD"], [0, [["55000.00000", "0.01000000", "1699999999.1234", "b", "m", ""]], "trade", "XBT/USD"], [0, {"a": [["55001.00000", "1.00000000", "1699999999.1234"]], "c": "1234"}, "book-10", "XBT/USD"], [0, [["55000.00000", "0.01000000", "1699999999.1234", "b", "m", ""]], "trade", "XBT/USD"], [0, {"a": [["55001.00000", "1.00000000", "1699999999.1234"]], "c": "1234"}, "book-10", "XBT/USD"], [0, [["55000.00000", "0.01000000", "1699999999.1234", "b", "m", ""]], "trade", "XBT/USD"], [0, {"a": [["55001.00000", "1.00000000", "1699999999.1234"]], "c": "1234"}, "book-10", "XBT/USD"], [0, [["55000.00000", "0.01000000", "1699999999.1234", "b", "m", ""]], "trade", "XBT/USD"], [0, {"a": [["55001.00000", "1.00000000", "1699999999.1234"]], "c": "1234"}, "book-10", "XBT/USD"], [0, [["55000.00000", "0.01000000", "1699999999.1234", "b", "m", ""]], "trade", "XBT/USD"], [0, {"a": [["55001.00000", "1.00000000", "1699999999.1234"]], "c": "1234"}, "book-10", "XBT/USD"], [0, [["55000.00000", "0.01000000", "1699999999.1234", "b", "m", ""]], "trade", "XBT/USD"], [0, {"a": [["55001.00000", "1.00000000", "1699999999.1234"]], "c": "1234"}, "book-10", "XBT/USD"], [0, [["55000.00000", "0.01000000", "1699999999.1234", "b", "m", ""]], "trade", "XBT/USD"], [0, {"a": [["55001.00000", "1.00000000", "1699999999.1234"]], "c": "1234"}, "book-10", "XBT/USD"], [0, [["55000.00000", "0.01000000", "1699999999.1234", "b", "m", ""]], "trade", "XBT/USD"], [0, {"a": [["55001.00000", "1.00000000", "1699999999.1234"]], "c": "1234"}, "book-10", "XBT/USD"], [0, [["55000.00000", "0.01000000", "1699999999.1234", "b", "m", ""]], "trade", "XBT/USD"], [0, {"a": [["55001.00000", "1.00000000", "1699999999.1234"]], "c": "1234"}, "book-10", "XBT/USD"], [0, [["55000.00000", "0.01000000", "1699999999.1234", "b", "m", ""]], "trade", "XBT/USD"], [0, {"a": [["55001.00000", "1.00000000", "1699999999.1234"]], "c": "1234"}, "book-10", "XBT/USD"], [0, [["55000.00000", "0.01000000", "1699999999.1234", "b", "m", ""]], "trade", "XBT/USD"], [0, {"a": [["55001.00000", "1.00000000", "1699999999.1234"]], "c": "1234"}, "book-10", "XBT/USD"], [0, [["55000.00000", "0.01000000", "1699999999.1234", "b", "m", ""]], "trade", "XBT/USD"], [0, {"a": [["55001.00000", "1.00000000", "1699999999.1234"]], "c": "1234"}, "book-10", "XBT/USD"], [0, [["55000.00000", "0.01000000", "1699999999.1234", "b", "m", ""]], "trade", "XBT/USD"], [0, {"a": [["55001.00000", "1.00000000", "1699999999.1234"]], "c": "1234"}, "book-10", "XBT/USD"], [0, [["55000.00000", "0.01000000", "1699999999.1234", "b", "m", ""]], "trade", "XBT/USD"], [0, {"a": [["55001.00000", "1.00000000", "1699999999.1234"]], "c": "1234"}, "book-10", "XBT/USD"], [0, [["55000.00000", "0.01000000", "1699999999.1234", "b", "m", ""]], "trade", "XBT/USD"], [0, {"a": [["55001.00000", "1.00000000", "1699999999.1234"]], "c": "1234"}, "book-10", "XBT/USD"], [0, [["55000.00000", "0.01000000", "1699999999.1234", "b", "m", ""]], "trade", "XBT/USD"], [0, {"a": [["55001.00000", "1.00000000", "1699999999.1234"]], "c": "1234"}, "book-10", "XBT/USD"], [0, [["55000.00000", "0.01000000", "1699999999.1234", "b", "m", ""]], "trade", "XBT/USD"], [0, {"a": [["55001.00000", "1.00000000", "1699999999.1234"]], "c": "1234"}, "book-10", "XBT/USD"], [0, [["55000.00000", "0.01000000", "1699999999.1234", "b", "m", ""]], "trade", "XBT/USD"], [0, {"a": [["55001.00000", "1.00000000", "1699999999.1234"]], "c": "1234"}, "book-10", "XBT/USD"], [0, [["55000.00000", "0.01000000", "1699999999.1234", "b", "m", ""]], "trade", "XBT/USD"], [0, {"a": [["55001.00000", "1.00000000", "1699999999.1234"]], "c": "1234"}, "book-10", "XBT/USD"], [0, [["55000.00000", "0.01000000", "1699999999.1234", "b", "m", ""]], "trade", "XBT/USD"], [0, {"a": [["55001.00000", "1.00000000", "1699999999.1234"]], "c": "1234"}, "book-10", "XBT/USD"], [0, [["55000.00000", "0.01000000", "1699999999.1234", "b", "m", ""]], "trade", "XBT/USD"], [0, {"a": [["55001.00000", "1.00000000", "1699999999.1234"]], "c": "1234"}, "book-10", "XBT/USD"], [0, [["55000.00000", "0.01000000", "1699999999.1234", "b", "m", ""]], "trade", "XBT/USD"], [0, {"a": [["55001.00000", "1.00000000", "1699999999.1234"]], "c": "1234"}, "book-10", "XBT/USD"], [0, [["55000.00000", "0.01000000", "1699999999.1234", "b", "m", ""]], "trade", "XBT/USD"], [0, {"a": [["55001.00000", "1.00000000", "1699999999.1234"]], "c": "1234"}, "book-10", "XBT/USD"], [0, [["55000.00000", "0.01000000", "1699999999.1234", "b", "m", ""]], "trade", "XBT/USD"], [0, {"a": [["55001.00000", "1.00000000", "1699999999.1234"]], "c": "1234"}, "book-10", "XBT/USD"], [0, [["55000.00000", "0.01000000", "1699999999.1234", "b", "m", ""]], "trade", "XBT/USD"], [0, {"a": [["55001.00000", "1.00000000", "1699999999.1234"]], "c": "1234"}, "book-10", "XBT/USD"], [0, [["55000.00000", "0.01000000", "1699999999.1234", "b", "m", ""]], "trade", "XBT/USD"], [0, {"a": [["55001.00000", "1.00000000", "1699999999.1234"]], "c": "1234"}, "book-10", "XBT/USD"], [0, [["55000.00000", "0.01000000", "1699999999.1234", "b", "m", ""]], "trade", "XBT/USD"], [0, {"a": [["55001.00000", "1.00000000", "1699999999.1234"]], "c": "1234"}, "book-10", "XBT/USD"], [0, [["55000.00000", "0.01000000", "1699999999.1234", "b", "m", ""]], "trade", "XBT/USD"], [0, {"a": [["55001.00000", "1.00000000", "1699999999.1234"]], "c": "1234"}, "book-10", "XBT/USD"], [0, [["55000.00000", "0.01000000", "1699999999.1234", "b", "m", ""]], "trade", "XBT/USD"], [0, {"a": [["55001.00000", "1.00000000", "1699999999.1234"]], "c": "1234"}, "book-10", "XBT/USD"], [0, [["55000.00000", "0.01000000", "1699999999.1234", "b", "m", ""]], "trade", "XBT/USD"], [0, {"a": [["55001.00000", "1.00000000", "1699999999.1234"]], "c": "1234"}, "book-10", "XBT/USD"], [0, [["55000.00000", "0.01000000", "1699999999.1234", "b", "m", ""]], "trade", "XBT/USD"], [0, {"a": [["55001.00000", "1.00000000", "1699999999.1234"]], "c": "1234"}, "book-10", "XBT/USD"], [0, [["55000.00000", "0.01000000", "1699999999.1234", "b", "m", ""]], "trade", "XBT/USD"], [0, {"a": [["55001.00000", "1.00000000", "1699999999.1234"]], "c": "1234"}, "book-10", "XBT/USD"], [0, [["55000.00000", "0.01000000", "1699999999.1234", "b", "m", ""]], "trade", "XBT/USD"], [0, {"a": [["55001.00000", "1.00000000", "1699999999.1234"]], "c": "1234"}, "book-10", "XBT/USD"], [0, [["55000.00000", "0.01000000", "1699999999.1234", "b", "m", ""]], "trade", "XBT/USD"], [0, {"a": [["55001.00000", "1.00000000", "1699999999.1234"]], "c": "1234"}, "book-10", "XBT/USD"], [0, [["55000.00000", "0.01000000", "1699999999.1234", "b", "m", ""]], "trade", "XBT/USD"], [0, {"a": [["55001.00000", "1.00000000", "1699999999.1234"]], "c": "1234"}, "book-10", "XBT/USD"], [0, [["55000.00000", "0.01000000", "1699999999.1234", "b", "m", ""]], "trade", "XBT/USD"], [0, {"a": [["55001.00000", "1.00000000", "1699999999.1234"]], "c": "1234"}, "book-10", "XBT/USD"], [0, [["55000.00000", "0.01000000", "1699999999.1234", "b", "m", ""]], "trade", "XBT/USD"], [0, {"a": [["55001.00000", "1.00000000", "1699999999.1234"]], "c": "1234"}, "book-10", "XBT/USD"], [0, [["55000.00000", "0.01000000", "1699999999.1234", "b", "m", ""]], "trade", "XBT/USD"], [0, {"a": [["55001.00000", "1.00000000", "1699999999.1234"]], "c": "1234"}, "book-10", "XBT/USD"], [0, [["55000.00000", "0.01000000", "1699999999.1234", "b", "m", ""]], "trade", "XBT/USD"], [0, {"a": [["55001.00000", "1.00000000", "1699999999.1234"]], "c": "1234"}, "book-10", "XBT/USD"], [0, [["55000.00000", "0.01000000", "1699999999.1234", "b", "m", ""]], "trade", "XBT/USD"], [0, {"a": [["55001.00000", "1.00000000", "1699999999.1234"]], "c": "1234"}, "book-10", "XBT/USD"], [0, [["55000.00000", "0.01000000", "1699999999.1234", "b", "m", ""]], "trade", "XBT/USD"], [0, {"a": [["55001.00000", "1.00000000", "1699999999.1234"]], "c": "1234"}, "book-10", "XBT/USD"], [0, [["55000.00000", "0.01000000", "1699999999.1234", "b", "m", ""]], "trade", "XBT/USD"], [0, {"a": [["55001.00000", "1.00000000", "1699999999.1234"]], "c": "1234"}, "book-10", "XBT/USD"], [0, [["55000.00000", "0.01000000", "1699999999.1234", "b", "m", ""]], "trade", "XBT/USD"], [0, {"a": [["55001.00000", "1.00000000", "1699999999.1234"]], "c": "1234"}, "book-10", "XBT/USD"], [0, [["55000.00000", "0.01000000", "1699999999.1234", "b", "m", ""]], "trade", "XBT/USD"], [0, {"a": [["55001.00000", "1.00000000", "1699999999.1234"]], "c": "1234"}, "book-10", "XBT/USD"], [0, [["55000.00000", "0.01000000", "1699999999.1234", "b", "m", ""]], "trade", "XBT/USD"], [0, {"a": [["55001.00000", "1.00000000", "1699999999.1234"]], "c": "1234"}, "book-10", "XBT/USD"], [0, [["55000.00000", "0.01000000", "1699999999.1234", "b", "m", ""]], "trade", "XBT/USD"], [0, {"a": [["55001.00000", "1.00000000", "1699999999.1234"]], "c": "1234"}, "book-10", "XBT/USD"], [0, [["55000.00000", "0.01000000", "1699999999.1234", "b", "m", ""]], "trade", "XBT/USD"], [0, {"a": [["55001.00000", "1.00000000", "1699999999.1234"]], "c": "1234"}, "book-10", "XBT/USD"], [0, [["55000.00000", "0.01000000", "1699999999.1234", "b", "m", ""]], "trade", "XBT/USD"], [0, {"a": [["55001.00000", "1.00000000", "1699999999.1234"]], "c": "1234"}, "book-10", "XBT/USD"], [0, [["55000.00000", "0.01000000", "1699999999.1234", "b", "m", ""]], "trade", "XBT/USD"], [0, {"a": [["55001.00000", "1.00000000", "1699999999.1234"]], "c": "1234"}, "book-10", "XBT/USD"], [0, [["55000.00000", "0.01000000", "1699999999.1234", "b", "m", ""]], "trade", "XBT/USD"], [0, {"a": [["55001.00000", "1.00000000", "1699999999.1234"]], "c": "1234"}, "book-10", "XBT/USD"], [0, [["55000.00000", "0.01000000", "1699999999.1234", "b", "m", ""]], "trade", "XBT/USD"], [0, {"a": [["55001.00000", "1.00000000", "1699999999.1234"]], "c": "1234"}, "book-10", "XBT/USD"], [0, [["55000.00000", "0.01000000", "1699999999.1234", "b", "m", ""]], "trade", "XBT/USD"], [0, {"a": [["55001.00000", "1.00000000", "1699999999.1234"]], "c": "1234"}, "book-10", "XBT/USD"], [0, [["55000.00000", "0.01000000", "1699999999.1234", "b", "m", ""]], "trade", "XBT/USD"], [0, {"a": [["55001.00000", "1.00000000", "1699999999.1234"]], "c": "1234"}, "book-10", "XBT/USD"], [0, [["55000.00000", "0.01000000", "1699999999.1234", "b", "m", ""]], "trade", "XBT/USD"], [0, {"a": [["55001.00000", "1.00000000", "1699999999.1234"]], "c": "1234"}, "book-10", "XBT/USD"], [0, [["55000.00000", "0.01000000", "1699999999.1234", "b", "m", ""]], "trade", "XBT/USD"], [0, {"a": [["55001.00000", "1.00000000", "1699999999.1234"]], "c": "1234"}, "book-10", "XBT/USD"], [0, [["55000.00000", "0.01000000", "1699999999.1234", "b", "m", ""]], "trade", "XBT/USD"], [0, {"a": [["55001.00000", "1.00000000", "1699999999.1234"]], "c": "1234"}, "book-10", "XBT/USD"], [0, [["55000.00000", "0.01000000", "1699999999.1234", "b", "m", ""]], "trade", "XBT/USD"], [0, {"a": [["55001.00000", "1.00000000", "1699999999.1234"]], "c": "1234"}, "book-10", "XBT/USD"], [0, [["55000.00000", "0.01000000", "1699999999.1234", "b", "m", ""]], "trade", "XBT/USD"], [0, {"a": [["55001.00000", "1.00000000", "1699999999.1234"]], "c": "1234"}, "book-10", "XBT/USD"], [0, [["55000.00000", "0.01000000", "1699999999.1234", "b", "m", ""]], "trade", "XBT/USD"], [0, {"a": [["55001.00000", "1.00000000", "1699999999.1234"]], "c": "1234"}, "book-10", "XBT/USD"], [0, [["55000.00000", "0.01000000", "1699999999.1234", "b", "m", ""]], "trade", "XBT/USD"], [0, {"a": [["55001.00000", "1.00000000", "1699999999.1234"]], "c": "1234"}, "book-10", "XBT/USD"], [0, [["55000.00000", "0.01000000", "1699999999.1234", "b", "m", ""]], "trade", "XBT/USD"], [0, {"a": [["55001.00000", "1.00000000", "1699999999.1234"]], "c": "1234"}, "book-10", "XBT/USD"], [0, [["55000.00000", "0.01000000", "1699999999.1234", "b", "m", ""]], "trade", "XBT/USD"], [0, {"a": [["55001.00000", "1.00000000", "1699999999.1234"]], "c": "1234"}, "book-10", "XBT/USD"], [0, [["55000.00000", "0.01000000", "1699999999.1234", "b", "m", ""]], "trade", "XBT/USD"], [0, {"a": [["55001.00000", "1.00000000", "1699999999.1234"]], "c": "1234"}, "book-10", "XBT/USD"], [0, [["55000.00000", "0.01000000", "1699999999.1234", "b", "m", ""]], "trade", "XBT/USD"], [0, {"a": [["55001.00000", "1.00000000", "1699999999.1234"]], "c": "1234"}, "book-10", "XBT/USD"], [0, [["55000.00000", "0.01000000", "1699999999.1234", "b", "m", ""]], "trade", "XBT/USD"], [0, {"a": [["55001.00000", "1.00000000", "1699999999.1234"]], "c": "1234"}, "book-10", "XBT/USD"], [0, [["55000.00000", "0.01000000", "1699999999.1234", "b", "m", ""]], "trade", "XBT/USD"], [0, {"a": [["55001.00000", "1.00000000", "1699999999.1234"]], "c": "1234"}, "book-10", "XBT/USD"], [0, [["55000.00000", "0.01000000", "1699999999.1234", "b", "m", ""]], "trade", "XBT/USD"], [0, {"a": [["55001.00000", "1.00000000", "1699999999.1234"]], "c": "1234"}, "book-10", "XBT/USD"], [0, [["55000.00000", "0.01000000", "1699999999.1234", "b", "m", ""]], "trade", "XBT/USD"], [0, {"a": [["55001.00000", "1.00000000", "1699999999.1234"]], "c": "1234"}, "book-10", "XBT/USD"], [0, [["55000.00000", "0.01000000", "1699999999.1234", "b", "m", ""]], "trade", "XBT/USD"], [0, {"a": [["55001.00000", "1.00000000", "1699999999.1234"]], "c": "1234"}, "book-10", "XBT/USD"], [0, [["55000.00000", "0.01000000", "1699999999.1234", "b", "m", ""]], "trade", "XBT/USD"], [0, {"a": [["55001.00000", "1.00000000", "1699999999.1234"]], "c": "1234"}, "book-10", "XBT/USD"], [0, [["55000.00000", "0.01000000", "1699999999.1234", "b", "m", ""]], "trade", "XBT/USD"], [0, {"a": [["55001.00000", "1.00000000", "1699999999.1234"]], "c": "1234"}, "book-10", "XBT/USD"], [0, [["55000.00000", "0.01000000", "1699999999.1234", "b", "m", ""]], "trade", "XBT/USD"], [0, {"a": [["55001.00000", "1.00000000", "1699999999.1234"]], "c": "1234"}, "book-10", "XBT/USD"], [0, [["55000.00000", "0.01000000", "1699999999.1234", "b", "m", ""]], "trade", "XBT/USD"], [0, {"a": [["55001.00000", "1.00000000", "1699999999.1234"]], "c": "1234"}, "book-10", "XBT/USD"], [0, [["55000.00000", "0.01000000", "1699999999.1234", "b", "m", ""]], "trade", "XBT/USD"], [0, {"a": [["55001.00000", "1.00000000", "1699999999.1234"]], "c": "1234"}, "book-10", "XBT/USD"], [0, [["55000.00000", "0.01000000", "1699999999.1234", "b", "m", ""]], "trade", "XBT/USD"], [0, {"a": [["55001.00000", "1.00000000", "1699999999.1234"]], "c": "1234"}, "book-10", "XBT/USD"], [0, [["55000.00000", "0.01000000", "1699999999.1234", "b", "m", ""]], "trade", "XBT/USD"], [0, {"a": [["55001.00000", "1.00000000", "1699999999.1234"]], "c": "1234"}, "book-10", "XBT/USD"], [0, [["55000.00000", "0.01000000", "1699999999.1234", "b", "m", ""]], "trade", "XBT/USD"], [0, {"a": [["55001.00000", "1.00000000", "1699999999.1234"]], "c": "1234"}, "book-10", "XBT/USD"], [0, [["55000.00000", "0.01000000", "1699999999.1234", "b", "m", ""]], "trade", "XBT/USD"], [0, {"a": [["55001.00000", "1.00000000", "1699999999.1234"]], "c": "1234"}, "book-10", "XBT/USD"], [0, [["55000.00000", "0.01000000", "1699999999.1234", "b", "m", ""]], "trade", "XBT/USD"], [0, {"a": [["55001.00000", "1.00000000", "1699999999.1234"]], "c": "1234"}, "book-10", "XBT/USD"], [0, [["55000.00000", "0.01000000", "1699999999.1234", "b", "m", ""]], "trade", "XBT/USD"], [0, {"a": [["55001.00000", "1.00000000", "1699999999.1234"]], "c": "1234"}, "book-10", "XBT/USD"], [0, [["55000.00000", "0.01000000", "1699999999.1234", "b", "m", ""]], "trade", "XBT/USD"], [0, {"a": [["55001.00000", "1.00000000", "1699999999.1234"]], "c": "1234"}, "book-10", "XBT/USD"], [0, [["55000.00000", "0.01000000", "1699999999.1234", "b", "m", ""]], "trade", "XBT/USD"], [0, {"a": [["55001.00000", "1.00000000", "1699999999.1234"]], "c": "1234"}, "book-10", "XBT/USD"], [0, [["55000.00000", "0.01000000", "1699999999.1234", "b", "m", ""]], "trade", "XBT/USD"], [0, {"a": [["55001.00000", "1.00000000", "1699999999.1234"]], "c": "1234"}, "book-10", "XBT/USD"], [0, [["55000.00000", "0.01000000", "1699999999.1234", "b", "m", ""]], "trade", "XBT/USD"], [0, {"a": [["55001.00000", "1.00000000", "1699999999.1234"]], "c": "1234"}, "book-10", "XBT/USD"], [0, [["55000.00000", "0.01000000", "1699999999.1234", "b", "m", ""]], "trade", "XBT/USD"], [0, {"a": [["55001.00000", "1.00000000", "1699999999.1234"]], "c": "1234"}, "book-10", "XBT/USD"], [0, [["55000.00000", "0.01000000", "1699999999.1234", "b", "m", ""]], "trade", "XBT/USD"], [0, {"a": [["55001.00000", "1.00000000", "1699999999.1234"]], "c": "1234"}, "book-10", "XBT/USD"], [0, [["55000.00000", "0.01000000", "1699999999.1234", "b", "m", ""]], "trade", "XBT/USD"], [0, {"a": [["55001.00000", "1.00000000", "1699999999.1234"]], "c": "1234"}, "book-10", "XBT/USD"], [0, [["55000.00000", "0.01000000", "1699999999.1234", "b", "m", ""]], "trade", "XBT/USD"], [0, {"a": [["55001.00000", "1.00000000", "1699999999.1234"]], "c": "1234"}, "book-10", "XBT/USD"], [0, [["55000.00000", "0.01000000", "1699999999.1234", "b", "m", ""]], "trade", "XBT/USD"], [0, {"a": [["55001.00000", "1.00000000", "1699999999.1234"]], "c": "1234"}, "book-10", "XBT/USD"], [0, [["55000.00000", "0.01000000", "1699999999.1234", "b", "m", ""]], "trade", "XBT/USD"], [0, {"a": [["55001.00000", "1.00000000", "1699999999.1234"]], "c": "1234"}, "book-10", "XBT/USD"], [0, [["55000.00000", "0.01000000", "1699999999.1234", "b", "m", ""]], "trade", "XBT/USD"], [0, {"a": [["55001.00000", "1.00000000", "1699999999.1234"]], "c": "1234"}, "book-10", "XBT/USD"], [0, [["55000.00000", "0.01000000", "1699999999.1234", "b", "m", ""]], "trade", "XBT/USD"], [0, {"a": [["55001.00000", "1.00000000", "1699999999.1234"]], "c": "1234"}, "book-10", "XBT/USD"], [0, [["55000.00000", "0.01000000", "1699999999.1234", "b", "m", ""]], "trade", "XBT/USD"], [0, {"a": [["55001.00000", "1.00000000", "1699999999.1234"]], "c": "1234"}, "book-10", "XBT/USD"], [0, [["55000.00000", "0.01000000", "1699999999.1234", "b", "m", ""]], "trade", "XBT/USD"], [0, {"a": [["55001.00000", "1.00000000", "1699999999.1234"]], "c": "1234"}, "book-10", "XBT/USD"], [0, [["55000.00000", "0.01000000", "1699999999.1234", "b", "m", ""]], "trade", "XBT/USD"], [0, {"a": [["55001.00000", "1.00000000", "1699999999.1234"]], "c": "1234"}, "book-10", "XBT/USD"], [0, [["55000.00000", "0.01000000", "1699999999.1234", "b", "m", ""]], "trade", "XBT/USD"], [0, {"a": [["55001.00000", "1.00000000", "1699999999.1234"]], "c": "1234"}, "book-10", "XBT/USD"], [0, [["55000.00000", "0.01000000", "1699999999.1234", "b", "m", ""]], "trade", "XBT/USD"], [0, {"a": [["55001.00000", "1.00000000", "1699999999.1234"]], "c": "1234"}, "book-10", "XBT/USD"], [0, [["55000.00000", "0.01000000", "1699999999.1234", "b", "m", ""]], "trade", "XBT/USD"], [0, {"a": [["55001.00000", "1.00000000", "1699999999.1234"]], "c": "1234"}, "book-10", "XBT/USD"], [0, [["55000.00000", "0.01000000", "1699999999.1234", "b", "m", ""]], "trade", "XBT/USD"], [0, {"a": [["55001.00000", "1.00000000", "1699999999.1234"]], "c": "1234"}, "book-10", "XBT/USD"], [0, [["55000.00000", "0.01000000", "1699999999.1234", "b", "m", ""]], "trade", "XBT/USD"], [0, {"a": [["55001.00000", "1.00000000", "1699999999.1234"]], "c": "1234"}, "book-10", "XBT/USD"], [0, [["55000.00000", "0.01000000", "1699999999.1234", "b", "m", ""]], "trade", "XBT/USD"], [0, {"a": [["55001.00000", "1.00000000", "1699999999.1234"]], "c": "1234"}, "book-10", "XBT/USD"], [0, [["55000.00000", "0.01000000", "1699999999.1234", "b", "m", ""]], "trade", "XBT/USD"], [0, {"a": [["55001.00000", "1.00000000", "1699999999.1234"]], "c": "1234"}, "book-10", "XBT/USD"], [0, [["55000.00000", "0.01000000", "1699999999.1234", "b", "m", ""]], "trade", "XBT/USD"], [0, {"a": [["55001.00000", "1.00000000", "1699999999.1234"]], "c": "1234"}, "book-10", "XBT/USD"], [0, [["55000.00000", "0.01000000", "1699999999.1234", "b", "m", ""]], "trade", "XBT/USD"], [0, {"a": [["55001.00000", "1.00000000", "1699999999.1234"]], "c": "1234"}, "book-10", "XBT/USD"], [0, [["55000.00000", "0.01000000", "1699999999.1234", "b", "m", ""]], "trade", "XBT/USD"], [0, {"a": [["55001.00000", "1.00000000", "1699999999.1234"]], "c": "1234"}, "book-10", "XBT/USD"], [0, [["55000.00000", "0.01000000", "1699999999.1234", "b", "m", ""]], "trade", "XBT/USD"], [0, {"a": [["55001.00000", "1.00000000", "1699999999.1234"]], "c": "1234"}, "book-10", "XBT/USD"], [0, [["55000.00000", "0.01000000", "1699999999.1234", "b", "m", ""]], "trade", "XBT/USD"], [0, {"a": [["55001.00000", "1.00000000", "1699999999.1234"]], "c": "1234"}, "book-10", "XBT/USD"], [0, [["55000.00000", "0.01000000", "1699999999.1234", "b", "m", ""]], "trade", "XBT/USD"], [0, {"a": [["55001.00000", "1.00000000", "1699999999.1234"]], "c": "1234"}, "book-10", "XBT/USD"], [0, [["55000.00000", "0.01000000", "1699999999.1234", "b", "m", ""]], "trade", "XBT/USD"], [0, {"a": [["55001.00000", "1.00000000", "1699999999.1234"]], "c": "1234"}, "book-10", "XBT/USD"], [0, [["55000.00000", "0.01000000", "1699999999.1234", "b", "m", ""]], "trade", "XBT/USD"], [0, {"a": [["55001.00000", "1.00000000", "1699999999.1234"]], "c": "1234"}, "book-10", "XBT/USD"], [0, [["55000.00000", "0.01000000", "1699999999.1234", "b", "m", ""]], "trade", "XBT/USD"], [0, {"a": [["55001.00000", "1.00000000", "1699999999.1234"]], "c": "1234"}, "book-10", "XBT/USD"], [0, [["55000.00000", "0.01000000", "1699999999.1234", "b", "m", ""]], "trade", "XBT/USD"], [0, {"a": [["55001.00000", "1.00000000", "1699999999.1234"]], "c": "1234"}, "book-10", "XBT/USD"], [0, [["55000.00000", "0.01000000", "1699999999.1234", "b", "m", ""]], "trade", "XBT/USD"], [0, {"a": [["55001.00000", "1.00000000", "1699999999.1234"]], "c": "1234"}, "book-10", "XBT/USD"], [0, [["55000.00000", "0.01000000", "1699999999.1234", "b", "m", ""]], "trade", "XBT/USD"], [0, {"a": [["55001.00000", "1.00000000", "1699999999.1234"]], "c": "1234"}, "book-10", "XBT/USD"], [0, [["55000.00000", "0.01000000", "1699999999.1234", "b", "m", ""]], "trade", "XBT/USD"], [0, {"a": [["55001.00000", "1.00000000", "1699999999.1234"]], "c": "1234"}, "book-10", "XBT/USD"], [0, [["55000.00000", "0.01000000", "1699999999.1234", "b", "m", ""]], "trade", "XBT/USD"], [0, {"a": [["55001.00000", "1.00000000", "1699999999.1234"]], "c": "1234"}, "book-10", "XBT/USD"], [0, [["55000.00000", "0.01000000", "1699999999.1234", "b", "m", ""]], "trade", "XBT/USD"], [0, {"a": [["55001.00000", "1.00000000", "1699999999.1234"]], "c": "1234"}, "book-10", "XBT/USD"], [0, [["55000.00000", "0.01000000", "1699999999.1234", "b", "m", ""]], "trade", "XBT/USD"], [0, {"a": [["55001.00000", "1.00000000", "1699999999.1234"]], "c": "1234"}, "book-10", "XBT/USD"], [0, [["55000.00000", "0.01000000", "1699999999.1234", "b", "m", ""]], "trade", "XBT/USD"], [0, {"a": [["55001.00000", "1.00000000", "1699999999.1234"]], "c": "1234"}, "book-10", "XBT/USD"], [0, [["55000.00000", "0.01000000", "1699999999.1234", "b", "m", ""]], "trade", "XBT/USD"], [0, {"a": [["55001.00000", "1.00000000", "1699999999.1234"]], "c": "1234"}, "book-10", "XBT/USD"], [0, [["55000.00000", "0.01000000", "1699999999.1234", "b", "m", ""]], "trade", "XBT/USD"], [0, {"a": [["55001.00000", "1.00000000", "1699999999.1234"]], "c": "1234"}, "book-10", "XBT/USD"], [0, [["55000.00000", "0.01000000", "1699999999.1234", "b", "m", ""]], "trade", "XBT/USD"], [0, {"a": [["55001.00000", "1.00000000", "1699999999.1234"]], "c": "1234"}, "book-10", "XBT/USD"], [0, [["55000.00000", "0.01000000", "1699999999.1234", "b", "m", ""]], "trade", "XBT/USD"], [0, {"a": [["55001.00000", "1.00000000", "1699999999.1234"]], "c": "1234"}, "book-10", "XBT/USD"], [0, [["55000.00000", "0.01000000", "1699999999.1234", "b", "m", ""]], "trade", "XBT/USD"], [0, {"a": [["55001.00000", "1.00000000", "1699999999.1234"]], "c": "1234"}, "book-10", "XBT/USD"], [0, [["55000.00000", "0.01000000", "1699999999.1234", "b", "m", ""]], "trade", "XBT/USD"], [0, {"a": [["55001.00000", "1.00000000", "1699999999.1234"]], "c": "1234"}, "book-10", "XBT/USD"], [0, [["55000.00000", "0.01000000", "1699999999.1234", "b", "m", ""]], "trade", "XBT/USD"], [0, {"a": [["55001.00000", "1.00000000", "1699999999.1234"]], "c": "1234"}, "book-10", "XBT/USD"], [0, [["55000.00000", "0.01000000", "1699999999.1234", "b", "m", ""]], "trade", "XBT/USD"], [0, {"a": [["55001.00000", "1.00000000", "1699999999.1234"]], "c": "1234"}, "book-10", "XBT/USD"], [0, [["55000.00000", "0.01000000", "1699999999.1234", "b", "m", ""]], "trade", "XBT/USD"], [0, {"a": [["55001.00000", "1.00000000", "1699999999.1234"]], "c": "1234"}, "book-10", "XBT/USD"], [0, [["55000.00000", "0.01000000", "1699999999.1234", "b", "m", ""]], "trade", "XBT/USD"], [0, {"a": [["55001.00000", "1.00000000", "1699999999.1234"]], "c": "1234"}, "book-10", "XBT/USD"], [0, [["55000.00000", "0.01000000", "1699999999.1234", "b", "m", ""]], "trade", "XBT/USD"], [0, {"a": [["55001.00000", "1.00000000", "1699999999.1234"]], "c": "1234"}, "book-10", "XBT/USD"], [0, [["55000.00000", "0.01000000", "1699999999.1234", "b", "m", ""]], "trade", "XBT/USD"], [0, {"a": [["55001.00000", "1.00000000", "1699999999.1234"]], "c": "1234"}, "book-10", "XBT/USD"], [0, [["55000.00000", "0.01000000", "1699999999.1234", "b", "m", ""]], "trade", "XBT/USD"], [0, {"a": [["55001.00000", "1.00000000", "1699999999.1234"]], "c": "1234"}, "book-10", "XBT/USD"], [0, [["55000.00000", "0.01000000", "1699999999.1234", "b", "m", ""]], "trade", "XBT/USD"], [0, {"a": [["55001.00000", "1.00000000", "1699999999.1234"]], "c": "1234"}, "book-10", "XBT/USD"], [0, [["55000.00000", "0.01000000", "1699999999.1234", "b", "m", ""]], "trade", "XBT/USD"], [0, {"a": [["55001.00000", "1.00000000", "1699999999.1234"]], "c": "1234"}, "book-10", "XBT/USD"], [0, [["55000.00000", "0.01000000", "1699999999.1234", "b", "m", ""]], "trade", "XBT/USD"], [0, {"a": [["55001.00000", "1.00000000", "1699999999.1234"]], "c": "1234"}, "book-10", "XBT/USD"], [0, [["55000.00000", "0.01000000", "1699999999.1234", "b", "m", ""]], "trade", "XBT/USD"], [0, {"a": [["55001.00000", "1.00000000", "1699999999.1234"]], "c": "1234"}, "book-10", "XBT/USD"], [0, [["55000.00000", "0.01000000", "1699999999.1234", "b", "m", ""]], "trade", "XBT/USD"], [0, {"a": [["55001.00000", "1.00000000", "1699999999.1234"]], "c": "1234"}, "book-10", "XBT/USD"], [0, [["55000.00000", "0.01000000", "1699999999.1234", "b", "m", ""]], "trade", "XBT/USD"], [0, {"a": [["55001.00000", "1.00000000", "1699999999.1234"]], "c": "1234"}, "book-10", "XBT/USD"], [0, [["55000.00000", "0.01000000", "1699999999.1234", "b", "m", ""]], "trade", "XBT/USD"], [0, {"a": [["55001.00000", "1.00000000", "1699999999.1234"]], "c": "1234"}, "book-10", "XBT/USD"], [0, [["55000.00000", "0.01000000", "1699999999.1234", "b", "m", ""]], "trade", "XBT/USD"], [0, {"a": [["55001.00000", "1.00000000", "1699999999.1234"]], "c": "1234"}, "book-10", "XBT/USD"], [0, [["55000.00000", "0.01000000", "1699999999.1234", "b", "m", ""]], "trade", "XBT/USD"], [0, {"a": [["55001.00000", "1.00000000", "1699999999.1234"]], "c": "1234"}, "book-10", "XBT/USD"], [0, [["55000.00000", "0.01000000", "1699999999.1234", "b", "m", ""]], "trade", "XBT/USD"], [0, {"a": [["55001.00000", "1.00000000", "1699999999.1234"]], "c": "1234"}, "book-10", "XBT/USD"], [0, [["55000.00000", "0.01000000", "1699999999.1234", "b", "m", ""]], "trade", "XBT/USD"], [0, {"a": [["55001.00000", "1.00000000", "1699999999.1234"]], "c": "1234"}, "book-10", "XBT/USD"], [0, [["55000.00000", "0.01000000", "1699999999.1234", "b", "m", ""]], "trade", "XBT/USD"], [0, {"a": [["55001.00000", "1.00000000", "1699999999.1234"]], "c": "1234"}, "book-10", "XBT/USD"], [0, [["55000.00000", "0.01000000", "1699999999.1234", "b", "m", ""]], "trade", "XBT/USD"], [0, {"a": [["55001.00000", "1.00000000", "1699999999.1234"]], "c": "1234"}, "book-10", "XBT/USD"], [0, [["55000.00000", "0.01000000", "1699999999.1234", "b", "m", ""]], "trade", "XBT/USD"], [0, {"a": [["55001.00000", "1.00000000", "1699999999.1234"]], "c": "1234"}, "book-10", "XBT/USD"], [0, [["55000.00000", "0.01000000", "1699999999.1234", "b", "m", ""]], "trade", "XBT/USD"], [0, {"a": [["55001.00000", "1.00000000", "1699999999.1234"]], "c": "1234"}, "book-10", "XBT/USD"], [0, [["55000.00000", "0.01000000", "1699999999.1234", "b", "m", ""]], "trade", "XBT/USD"], [0, {"a": [["55001.00000", "1.00000000", "1699999999.1234"]], "c": "1234"}, "book-10", "XBT/USD"], [0, [["55000.00000", "0.01000000", "1699999999.1234", "b", "m", ""]], "trade", "XBT/USD"], [0, {"a": [["55001.00000", "1.00000000", "1699999999.1234"]], "c": "1234"}, "book-10", "XBT/USD"], [0, [["55000.00000", "0.01000000", "1699999999.1234", "b", "m", ""]], "trade", "XBT/USD"], [0, {"a": [["55001.00000", "1.00000000", "1699999999.1234"]], "c": "1234"}, "book-10", "XBT/USD"], [0, [["55000.00000", "0.01000000", "1699999999.1234", "b", "m", ""]], "trade", "XBT/USD"], [0, {"a": [["55001.00000", "1.00000000", "1699999999.1234"]], "c": "1234"}, "book-10", "XBT/USD"], [0, [["55000.00000", "0.01000000", "1699999999.1234", "b", "m", ""]], "trade", "XBT/USD"], [0, {"a": [["55001.00000", "1.00000000", "1699999999.1234"]], "c": "1234"}, "book-10", "XBT/USD"], [0, [["55000.00000", "0.01000000", "1699999999.1234", "b", "m", ""]], "trade", "XBT/USD"], [0, {"a": [["55001.00000", "1.00000000", "1699999999.1234"]], "c": "1234"}, "book-10", "XBT/USD"], [0, [["55000.00000", "0.01000000", "1699999999.1234", "b", "m", ""]], "trade", "XBT/USD"], [0, {"a": [["55001.00000", "1.00000000", "1699999999.1234"]], "c": "1234"}, "book-10", "XBT/USD"], [0, [["55000.00000", "0.01000000", "1699999999.1234", "b", "m", ""]], "trade", "XBT/USD"], [0, {"a": [["55001.00000", "1.00000000", "1699999999.1234"]], "c": "1234"}, "book-10", "XBT/USD"], [0, [["55000.00000", "0.01000000", "1699999999.1234", "b", "m", ""]], "trade", "XBT/USD"], [0, {"a": [["55001.00000", "1.00000000", "1699999999.1234"]], "c": "1234"}, "book-10", "XBT/USD"], [0, [["55000.00000", "0.01000000", "1699999999.1234", "b", "m", ""]], "trade", "XBT/USD"], [0, {"a": [["55001.00000", "1.00000000", "1699999999.1234"]], "c": "1234"}, "book-10", "XBT/USD"], [0, [["55000.00000", "0.01000000", "1699999999.1234", "b", "m", ""]], "trade", "XBT/USD"], [0, {"a": [["55001.00000", "1.00000000", "1699999999.1234"]], "c": "1234"}, "book-10", "XBT/USD"], [0, [["55000.00000", "0.01000000", "1699999999.1234", "b", "m", ""]], "trade", "XBT/USD"], [0, {"a": [["55001.00000", "1.00000000", "1699999999.1234"]], "c": "1234"}, "book-10", "XBT/USD"], [0, [["55000.00000", "0.01000000", "1699999999.1234", "b", "m", ""]], "trade", "XBT/USD"], [0, {"a": [["55001.00000", "1.00000000", "1699999999.1234"]], "c": "1234"}, "book-10", "XBT/USD"], [0, [["55000.00000", "0.01000000", "1699999999.1234", "b", "m", ""]], "trade", "XBT/USD"], [0, {"a": [["55001.00000", "1.00000000", "1699999999.1234"]], "c": "1234"}, "book-10", "XBT/USD"], [0, [["55000.00000", "0.01000000", "1699999999.1234", "b", "m", ""]], "trade", "XBT/USD"], [0, {"a": [["55001.00000", "1.00000000", "1699999999.1234"]], "c": "1234"}, "book-10", "XBT/USD"], [0, [["55000.00000", "0.01000000", "1699999999.1234", "b", "m", ""]], "trade", "XBT/USD"], [0, {"a": [["55001.00000", "1.00000000", "1699999999.1234"]], "c": "1234"}, "book-10", "XBT/USD"], [0, [["55000.00000", "0.01000000", "1699999999.1234", "b", "m", ""]], "trade", "XBT/USD"], [0, {"a": [["55001.00000", "1.00000000", "1699999999.1234"]], "c": "1234"}, "book-10", "XBT/USD"], [0, [["55000.00000", "0.01000000", "1699999999.1234", "b", "m", ""]], "trade", "XBT/USD"], [0, {"a": [["55001.00000", "1.00000000", "1699999999.1234"]], "c": "1234"}, "book-10", "XBT/USD"], [0, [["55000.00000", "0.01000000", "1699999999.1234", "b", "m", ""]], "trade", "XBT/USD"], [0, {"a": [["55001.00000", "1.00000000", "1699999999.1234"]], "c": "1234"}, "book-10", "XBT/USD"], [0, [["55000.00000", "0.01000000", "1699999999.1234", "b", "m", ""]], "trade", "XBT/USD"], [0, {"a": [["55001.00000", "1.00000000", "1699999999.1234"]], "c": "1234"}, "book-10", "XBT/USD"], [0, [["55000.00000", "0.01000000", "1699999999.1234", "b", "m", ""]], "trade", "XBT/USD"], [0, {"a": [["55001.00000", "1.00000000", "1699999999.1234"]], "c": "1234"}, "book-10", "XBT/USD"], [0, [["55000.00000", "0.01000000", "1699999999.1234", "b", "m", ""]], "trade", "XBT/USD"], [0, {"a": [["55001.00000", "1.00000000", "1699999999.1234"]], "c": "1234"}, "book-10", "XBT/USD"], [0, [["55000.00000", "0.01000000", "1699999999.1234", "b", "m", ""]], "trade", "XBT/USD"], [0, {"a": [["55001.00000", "1.00000000", "1699999999.1234"]], "c": "1234"}, "book-10", "XBT/USD"], [0, [["55000.00000", "0.01000000", "1699999999.1234", "b", "m", ""]], "trade", "XBT/USD"], [0, {"a": [["55001.00000", "1.00000000", "1699999999.1234"]], "c": "1234"}, "book-10", "XBT/USD"], [0, [["55000.00000", "0.01000000", "1699999999.1234", "b", "m", ""]], "trade", "XBT/USD"], [0, {"a": [["55001.00000", "1.00000000", "1699999999.1234"]], "c": "1234"}, "book-10", "XBT/USD"], [0, [["55000.00000", "0.01000000", "1699999999.1234", "b", "m", ""]], "trade", "XBT/USD"], [0, {"a": [["55001.00000", "1.00000000", "1699999999.1234"]], "c": "1234"}, "book-10", "XBT/USD"], [0, [["55000.00000", "0.01000000", "1699999999.1234", "b", "m", ""]], "trade", "XBT/USD"], [0, {"a": [["55001.00000", "1.00000000", "1699999999.1234"]], "c": "1234"}, "book-10", "XBT/USD"], [0, [["55000.00000", "0.01000000", "1699999999.1234", "b", "m", ""]], "trade", "XBT/USD"], [0, {"a": [["55001.00000", "1.00000000", "1699999999.1234"]], "c": "1234"}, "book-10", "XBT/USD"], [0, [["55000.00000", "0.01000000", "1699999999.1234", "b", "m", ""]], "trade", "XBT/USD"], [0, {"a": [["55001.00000", "1.00000000", "1699999999.1234"]], "c": "1234"}, "book-10", "XBT/USD"], [0, [["55000.00000", "0.01000000", "1699999999.1234", "b", "m", ""]], "trade", "XBT/USD"], [0, {"a": [["55001.00000", "1.00000000", "1699999999.1234"]], "c": "1234"}, "book-10", "XBT/USD"], [0, [["55000.00000", "0.01000000", "1699999999.1234", "b", "m", ""]], "trade", "XBT/USD"], [0, {"a": [["55001.00000", "1.00000000", "1699999999.1234"]], "c": "1234"}, "book-10", "XBT/USD"], [0, [["55000.00000", "0.01000000", "1699999999.1234", "b", "m", ""]], "trade", "XBT/USD"], [0, {"a": [["55001.00000", "1.00000000", "1699999999.1234"]], "c": "1234"}, "book-10", "XBT/USD"], [0, [["55000.00000", "0.01000000", "1699999999.1234", "b", "m", ""]], "trade", "XBT/USD"], [0, {"a": [["55001.00000", "1.00000000", "1699999999.1234"]], "c": "1234"}, "book-10", "XBT/USD"], [0, [["55000.00000", "0.01000000", "1699999999.1234", "b", "m", ""]], "trade", "XBT/USD"], [0, {"a": [["55001.00000", "1.00000000", "1699999999.1234"]], "c": "1234"}, "book-10", "XBT/USD"], [0, [["55000.00000", "0.01000000", "1699999999.1234", "b", "m", ""]], "trade", "XBT/USD"], [0, {"a": [["55001.00000", "1.00000000", "1699999999.1234"]], "c": "1234"}, "book-10", "XBT/USD"], [0, [["55000.00000", "0.01000000", "1699999999.1234", "b", "m", ""]], "trade", "XBT/USD"], [0, {"a": [["55001.00000", "1.00000000", "1699999999.1234"]], "c": "1234"}, "book-10", "XBT/USD"], [0, [["55000.00000", "0.01000000", "1699999999.1234", "b", "m", ""]], "trade", "XBT/USD"], [0, {"a": [["55001.00000", "1.00000000", "1699999999.1234"]], "c": "1234"}, "book-10", "XBT/USD"], [0, [["55000.00000", "0.01000000", "1699999999.1234", "b", "m", ""]], "trade", "XBT/USD"], [0, {"a": [["55001.00000", "1.00000000", "1699999999.1234"]], "c": "1234"}, "book-10", "XBT/USD"], [0, [["55000.00000", "0.01000000", "1699999999.1234", "b", "m", ""]], "trade", "XBT/USD"], [0, {"a": [["55001.00000", "1.00000000", "1699999999.1234"]], "c": "1234"}, "book-10", "XBT/USD"], [0, [["55000.00000", "0.01000000", "1699999999.1234", "b", "m", ""]], "trade", "XBT/USD"], [0, {"a": [["55001.00000", "1.00000000", "1699999999.1234"]], "c": "1234"}, "book-10", "XBT/USD"], [0, [["55000.00000", "0.01000000", "1699999999.1234", "b", "m", ""]], "trade", "XBT/USD"], [0, {"a": [["55001.00000", "1.00000000", "1699999999.1234"]], "c": "1234"}, "book-10", "XBT/USD"], [0, [["55000.00000", "0.01000000", "1699999999.1234", "b", "m", ""]], "trade", "XBT/USD"], [0, {"a": [["55001.00000", "1.00000000", "1699999999.1234"]], "c": "1234"}, "book-10", "XBT/USD"], [0, [["55000.00000", "0.01000000", "1699999999.1234", "b", "m", ""]], "trade", "XBT/USD"], [0, {"a": [["55001.00000", "1.00000000", "1699999999.1234"]], "c": "1234"}, "book-10", "XBT/USD"], [0, [["55000.00000", "0.01000000", "1699999999.1234", "b", "m", ""]], "trade", "XBT/USD"], [0, {"a": [["55001.00000", "1.00000000", "1699999999.1234"]], "c": "1234"}, "book-10", "XBT/USD"], [0, [["55000.00000", "0.01000000", "1699999999.1234", "b", "m", ""]], "trade", "XBT/USD"], [0, {"a": [["55001.00000", "1.00000000", "1699999999.1234"]], "c": "1234"}, "book-10", "XBT/USD"], [0, [["55000.00000", "0.01000000", "1699999999.1234", "b", "m", ""]], "trade", "XBT/USD"], [0, {"a": [["55001.00000", "1.00000000", "1699999999.1234"]], "c": "1234"}, "book-10", "XBT/USD"], [0, [["55000.00000", "0.01000000", "1699999999.1234", "b", "m", ""]], "trade", "XBT/USD"], [0, {"a": [["55001.00000", "1.00000000", "1699999999.1234"]], "c": "1234"}, "book-10", "XBT/USD"], [0, [["55000.00000", "0.01000000", "1699999999.1234", "b", "m", ""]], "trade", "XBT/USD"], [0, {"a": [["55001.00000", "1.00000000", "1699999999.1234"]], "c": "1234"}, "book-10", "XBT/USD"], [0, [["55000.00000", "0.01000000", "1699999999.1234", "b", "m", ""]], "trade", "XBT/USD"], [0, {"a": [["55001.00000", "1.00000000", "1699999999.1234"]], "c": "1234"}, "book-10", "XBT/USD"], [0, [["55000.00000", "0.01000000", "1699999999.1234", "b", "m", ""]], "trade", "XBT/USD"], [0, {"a": [["55001.00000", "1.00000000", "1699999999.1234"]], "c": "1234"}, "book-10", "XBT/USD"], [0, [["55000.00000", "0.01000000", "1699999999.1234", "b", "m", ""]], "trade", "XBT/USD"], [0, {"a": [["55001.00000", "1.00000000", "1699999999.1234"]], "c": "1234"}, "book-10", "XBT/USD"], [0, [["55000.00000", "0.01000000", "1699999999.1234", "b", "m", ""]], "trade", "XBT/USD"], [0, {"a": [["55001.00000", "1.00000000", "1699999999.1234"]], "c": "1234"}, "book-10", "XBT/USD"], [0, [["55000.00000", "0.01000000", "1699999999.1234", "b", "m", ""]], "trade", "XBT/USD"], [0, {"a": [["55001.00000", "1.00000000", "1699999999.1234"]], "c": "1234"}, "book-10", "XBT/USD"], [0, [["55000.00000", "0.01000000", "1699999999.1234", "b", "m", ""]], "trade", "XBT/USD"], [0, {"a": [["55001.00000", "1.00000000", "1699999999.1234"]], "c": "1234"}, "book-10", "XBT/USD"], [0, [["55000.00000", "0.01000000", "1699999999.1234", "b", "m", ""]], "trade", "XBT/USD"], [0, {"a": [["55001.00000", "1.00000000", "1699999999.1234"]], "c": "1234"}, "book-10", "XBT/USD"], [0, [["55000.00000", "0.01000000", "1699999999.1234", "b", "m", ""]], "trade", "XBT/USD"], [0, {"a": [["55001.00000", "1.00000000", "1699999999.1234"]], "c": "1234"}, "book-10", "XBT/USD"], [0, [["55000.00000", "0.01000000", "1699999999.1234", "b", "m", ""]], "trade", "XBT/USD"], [0, {"a": [["55001.00000", "1.00000000", "1699999999.1234"]], "c": "1234"}, "book-10", "XBT/USD"], [0, [["55000.00000", "0.01000000", "1699999999.1234", "b", "m", ""]], "trade", "XBT/USD"], [0, {"a": [["55001.00000", "1.00000000", "1699999999.1234"]], "c": "1234"}, "book-10", "XBT/USD"], [0, [["55000.00000", "0.01000000", "1699999999.1234", "b", "m", ""]], "trade", "XBT/USD"], [0, {"a": [["55001.00000", "1.00000000", "1699999999.1234"]], "c": "1234"}, "book-10", "XBT/USD"], [0, [["55000.00000", "0.01000000", "1699999999.1234", "b", "m", ""]], "trade", "XBT/USD"], [0, {"a": [["55001.00000", "1.00000000", "1699999999.1234"]], "c": "1234"}, "book-10", "XBT/USD"], [0, [["55000.00000", "0.01000000", "1699999999.1234", "b", "m", ""]], "trade", "XBT/USD"], [0, {"a": [["55001.00000", "1.00000000", "1699999999.1234"]], "c": "1234"}, "book-10", "XBT/USD"], [0, [["55000.00000", "0.01000000", "1699999999.1234", "b", "m", ""]], "trade", "XBT/USD"], [0, {"a": [["55001.00000", "1.00000000", "1699999999.1234"]], "c": "1234"}, "book-10", "XBT/USD"], [0, [["55000.00000", "0.01000000", "1699999999.1234", "b", "m", ""]], "trade", "XBT/USD"], [0, {"a": [["55001.00000", "1.00000000", "1699999999.1234"]], "c": "1234"}, "book-10", "XBT/USD"], [0, [["55000.00000", "0.01000000", "1699999999.1234", "b", "m", ""]], "trade", "XBT/USD"], [0, {"a": [["55001.00000", "1.00000000", "1699999999.1234"]], "c": "1234"}, "book-10", "XBT/USD"], [0, [["55000.00000", "0.01000000", "1699999999.1234", "b", "m", ""]], "trade", "XBT/USD"], [0, {"a": [["55001.00000", "1.00000000", "1699999999.1234"]], "c": "1234"}, "book-10", "XBT/USD"], [0, [["55000.00000", "0.01000000", "1699999999.1234", "b", "m", ""]], "trade", "XBT/USD"], [0, {"a": [["55001.00000", "1.00000000", "1699999999.1234"]], "c": "1234"}, "book-10", "XBT/USD"], [0, [["55000.00000", "0.01000000", "1699999999.1234", "b", "m", ""]], "trade", "XBT/USD"], [0, {"a": [["55001.00000", "1.00000000", "1699999999.1234"]], "c": "1234"}, "book-10", "XBT/USD"], [0, [["55000.00000", "0.01000000", "1699999999.1234", "b", "m", ""]], "trade", "XBT/USD"], [0, {"a": [["55001.00000", "1.00000000", "1699999999.1234"]], "c": "1234"}, "book-10", "XBT/USD"], [0, [["55000.00000", "0.01000000", "1699999999.1234", "b", "m", ""]], "trade", "XBT/USD"], [0, {"a": [["55001.00000", "1.00000000", "1699999999.1234"]], "c": "1234"}, "book-10", "XBT/USD"], [0, [["55000.00000", "0.01000000", "1699999999.1234", "b", "m", ""]], "trade", "XBT/USD"], [0, {"a": [["55001.00000", "1.00000000", "1699999999.1234"]], "c": "1234"}, "book-10", "XBT/USD"], [0, [["55000.00000", "0.01000000", "1699999999.1234", "b", "m", ""]], "trade", "XBT/USD"], [0, {"a": [["55001.00000", "1.00000000", "1699999999.1234"]], "c": "1234"}, "book-10", "XBT/USD"], [0, [["55000.00000", "0.01000000", "1699999999.1234", "b", "m", ""]], "trade", "XBT/USD"], [0, {"a": [["55001.00000", "1.00000000", "1699999999.1234"]], "c": "1234"}, "book-10", "XBT/USD"], [0, [["55000.00000", "0.01000000", "1699999999.1234", "b", "m", ""]], "trade", "XBT/USD"], [0, {"a": [["55001.00000", "1.00000000", "1699999999.1234"]], "c": "1234"}, "book-10", "XBT/USD"], [0, [["55000.00000", "0.01000000", "1699999999.1234", "b", "m", ""]], "trade", "XBT/USD"], [0, {"a": [["55001.00000", "1.00000000", "1699999999.1234"]], "c": "1234"}, "book-10", "XBT/USD"], [0, [["55000.00000", "0.01000000", "1699999999.1234", "b", "m", ""]], "trade", "XBT/USD"], [0, {"a": [["55001.00000", "1.00000000", "1699999999.1234"]], "c": "1234"}, "book-10", "XBT/USD"], [0, [["55000.00000", "0.01000000", "1699999999.1234", "b", "m", ""]], "trade", "XBT/USD"], [0, {"a": [["55001.00000", "1.00000000", "1699999999.1234"]], "c": "1234"}, "book-10", "XBT/USD"], [0, [["55000.00000", "0.01000000", "1699999999.1234", "b", "m", ""]], "trade", "XBT/USD"], [0, {"a": [["55001.00000", "1.00000000", "1699999999.1234"]], "c": "1234"}, "book-10", "XBT/USD"], [0, [["55000.00000", "0.01000000", "1699999999.1234", "b", "m", ""]], "trade", "XBT/USD"], [0, {"a": [["55001.00000", "1.00000000", "1699999999.1234"]], "c": "1234"}, "book-10", "XBT/USD"], [0, [["55000.00000", "0.01000000", "1699999999.1234", "b", "m", ""]], "trade", "XBT/USD"], [0, {"a": [["55001.00000", "1.00000000", "1699999999.1234"]], "c": "1234"}, "book-10", "XBT/USD"], [0, [["55000.00000", "0.01000000", "1699999999.1234", "b", "m", ""]], "trade", "XBT/USD"], [0, {"a": [["55001.00000", "1.00000000", "1699999999.1234"]], "c": "1234"}, "book-10", "XBT/USD"], [0, [["55000.00000", "0.01000000", "1699999999.1234", "b", "m", ""]], "trade", "XBT/USD"], [0, {"a": [["55001.00000", "1.00000000", "1699999999.1234"]], "c": "1234"}, "book-10", "XBT/USD"], [0, [["55000.00000", "0.01000000", "1699999999.1234", "b", "m", ""]], "trade", "XBT/USD"], [0, {"a": [["55001.00000", "1.00000000", "1699999999.1234"]], "c": "1234"}, "book-10", "XBT/USD"], [0, [["55000.00000", "0.01000000", "1699999999.1234", "b", "m", ""]], "trade", "XBT/USD"], [0, {"a": [["55001.00000", "1.00000000", "1699999999.1234"]], "c": "1234"}, "book-10", "XBT/USD"], [0, [["55000.00000", "0.01000000", "1699999999.1234", "b", "m", ""]], "trade", "XBT/USD"], [0, {"a": [["55001.00000", "1.00000000", "1699999999.1234"]], "c": "1234"}, "book-10", "XBT/USD"], [0, [["55000.00000", "0.01000000", "1699999999.1234", "b", "m", ""]], "trade", "XBT/USD"], [0, {"a": [["55001.00000", "1.00000000", "1699999999.1234"]], "c": "1234"}, "book-10", "XBT/USD"], [0, [["55000.00000", "0.01000000", "1699999999.1234", "b", "m", ""]], "trade", "XBT/USD"], [0, {"a": [["55001.00000", "1.00000000", "1699999999.1234"]], "c": "1234"}, "book-10", "XBT/USD"], [0, [["55000.00000", "0.01000000", "1699999999.1234", "b", "m", ""]], "trade", "XBT/USD"], [0, {"a": [["55001.00000", "1.00000000", "1699999999.1234"]], "c": "1234"}, "book-10", "XBT/USD"], [0, [["55000.00000", "0.01000000", "1699999999.1234", "b", "m", ""]], "trade", "XBT/USD"], [0, {"a": [["55001.00000", "1.00000000", "1699999999.1234"]], "c": "1234"}, "book-10", "XBT/USD"], [0, [["55000.00000", "0.01000000", "1699999999.1234", "b", "m", ""]], "trade", "XBT/USD"], [0, {"a": [["55001.00000", "1.00000000", "1699999999.1234"]], "c": "1234"}, "book-10", "XBT/USD"], [0, [["55000.00000", "0.01000000", "1699999999.1234", "b", "m", ""]], "trade", "XBT/USD"], [0, {"a": [["55001.00000", "1.00000000", "1699999999.1234"]], "c": "1234"}, "book-10", "XBT/USD"], [0, [["55000.00000", "0.01000000", "1699999999.1234", "b", "m", ""]], "trade", "XBT/USD"], [0, {"a": [["55001.00000", "1.00000000", "1699999999.1234"]], "c": "1234"}, "book-10", "XBT/USD"], [0, [["55000.00000", "0.01000000", "1699999999.1234", "b", "m", ""]], "trade", "XBT/USD"], [0, {"a": [["55001.00000", "1.00000000", "1699999999.1234"]], "c": "1234"}, "book-10", "XBT/USD"], [0, [["55000.00000", "0.01000000", "1699999999.1234", "b", "m", ""]], "trade", "XBT/USD"], [0, {"a": [["55001.00000", "1.00000000", "1699999999.1234"]], "c": "1234"}, "book-10", "XBT/USD"], [0, [["55000.00000", "0.01000000", "1699999999.1234", "b", "m", ""]], "trade", "XBT/USD"], [0, {"a": [["55001.00000", "1.00000000", "1699999999.1234"]], "c": "1234"}, "book-10", "XBT/USD"], [0, [["55000.00000", "0.01000000", "1699999999.1234", "b", "m", ""]], "trade", "XBT/USD"], [0, {"a": [["55001.00000", "1.00000000", "1699999999.1234"]], "c": "1234"}, "book-10", "XBT/USD"], [0, [["55000.00000", "0.01000000", "1699999999.1234", "b", "m", ""]], "trade", "XBT/USD"], [0, {"a": [["55001.00000", "1.00000000", "1699999999.1234"]], "c": "1234"}, "book-10", "XBT/USD"], [0, [["55000.00000", "0.01000000", "1699999999.1234", "b", "m", ""]], "trade", "XBT/USD"], [0, {"a": [["55001.00000", "1.00000000", "1699999999.1234"]], "c": "1234"}, "book-10", "XBT/USD"], [0, [["55000.00000", "0.01000000", "1699999999.1234", "b", "m", ""]], "trade", "XBT/USD"], [0, {"a": [["55001.00000", "1.00000000", "1699999999.1234"]], "c": "1234"}, "book-10", "XBT/USD"], [0, [["55000.00000", "0.01000000", "1699999999.1234", "b", "m", ""]], "trade", "XBT/USD"], [0, {"a": [["55001.00000", "1.00000000", "1699999999.1234"]], "c": "1234"}, "book-10", "XBT/USD"], [0, [["55000.00000", "0.01000000", "1699999999.1234", "b", "m", ""]], "trade", "XBT/USD"], [0, {"a": [["55001.00000", "1.00000000", "1699999999.1234"]], "c": "1234"}, "book-10", "XBT/USD"], [0, [["55000.00000", "0.01000000", "1699999999.1234", "b", "m", ""]], "trade", "XBT/USD"], [0, {"a": [["55001.00000", "1.00000000", "1699999999.1234"]], "c": "1234"}, "book-10", "XBT/USD"], [0, [["55000.00000", "0.01000000", "1699999999.1234", "b", "m", ""]], "trade", "XBT/USD"], [0, {"a": [["55001.00000", "1.00000000", "1699999999.1234"]], "c": "1234"}, "book-10", "XBT/USD"], [0, [["55000.00000", "0.01000000", "1699999999.1234", "b", "m", ""]], "trade", "XBT/USD"], [0, {"a": [["55001.00000", "1.00000000", "1699999999.1234"]], "c": "1234"}, "book-10", "XBT/USD"], [0, [["55000.00000", "0.01000000", "1699999999.1234", "b", "m", ""]], "trade", "XBT/USD"], [0, {"a": [["55001.00000", "1.00000000", "1699999999.1234"]], "c": "1234"}, "book-10", "XBT/USD"], [0, [["55000.00000", "0.01000000", "1699999999.1234", "b", "m", ""]], "trade", "XBT/USD"], [0, {"a": [["55001.00000", "1.00000000", "1699999999.1234"]], "c": "1234"}, "book-10", "XBT/USD"], [0, [["55000.00000", "0.01000000", "1699999999.1234", "b", "m", ""]], "trade", "XBT/USD"], [0, {"a": [["55001.00000", "1.00000000", "1699999999.1234"]], "c": "1234"}, "book-10", "XBT/USD"], [0, [["55000.00000", "0.01000000", "1699999999.1234", "b", "m", ""]], "trade", "XBT/USD"], [0, {"a": [["55001.00000", "1.00000000", "1699999999.1234"]], "c": "1234"}, "book-10", "XBT/USD"], [0, [["55000.00000", "0.01000000", "1699999999.1234", "b", "m", ""]], "trade", "XBT/USD"], [0, {"a": [["55001.00000", "1.00000000", "1699999999.1234"]], "c": "1234"}, "book-10", "XBT/USD"], [0, [["55000.00000", "0.01000000", "1699999999.1234", "b", "m", ""]], "trade", "XBT/USD"], [0, {"a": [["55001.00000", "1.00000000", "1699999999.1234"]], "c": "1234"}, "book-10", "XBT/USD"], [0, [["55000.00000", "0.01000000", "1699999999.1234", "b", "m", ""]], "trade", "XBT/USD"], [0, {"a": [["55001.00000", "1.00000000", "1699999999.1234"]], "c": "1234"}, "book-10", "XBT/USD"], [0, [["55000.00000", "0.01000000", "1699999999.1234", "b", "m", ""]], "trade", "XBT/USD"], [0, {"a": [["55001.00000", "1.00000000", "1699999999.1234"]], "c": "1234"}, "book-10", "XBT/USD"], [0, [["55000.00000", "0.01000000", "1699999999.1234", "b", "m", ""]], "trade", "XBT/USD"], [0, {"a": [["55001.00000", "1.00000000", "1699999999.1234"]], "c": "1234"}, "book-10", "XBT/USD"], [0, [["55000.00000", "0.01000000", "1699999999.1234", "b", "m", ""]], "trade", "XBT/USD"], [0, {"a": [["55001.00000", "1.00000000", "1699999999.1234"]], "c": "1234"}, "book-10", "XBT/USD"], [0, [["55000.00000", "0.01000000", "1699999999.1234", "b", "m", ""]], "trade", "XBT/USD"], [0, {"a": [["55001.00000", "1.00000000", "1699999999.1234"]], "c": "1234"}, "book-10", "XBT/USD"], [0, [["55000.00000", "0.01000000", "1699999999.1234", "b", "m", ""]], "trade", "XBT/USD"], [0, {"a": [["55001.00000", "1.00000000", "1699999999.1234"]], "c": "1234"}, "book-10", "XBT/USD"], [0, [["55000.00000", "0.01000000", "1699999999.1234", "b", "m", ""]], "trade", "XBT/USD"], [0, {"a": [["55001.00000", "1.00000000", "1699999999.1234"]], "c": "1234"}, "book-10", "XBT/USD"], [0, [["55000.00000", "0.01000000", "1699999999.1234", "b", "m", ""]], "trade", "XBT/USD"], [0, {"a": [["55001.00000", "1.00000000", "1699999999.1234"]], "c": "1234"}, "book-10", "XBT/USD"], [0, [["55000.00000", "0.01000000", "1699999999.1234", "b", "m", ""]], "trade", "XBT/USD"], [0, {"a": [["55001.00000", "1.00000000", "1699999999.1234"]], "c": "1234"}, "book-10", "XBT/USD"], [0, [["55000.00000", "0.01000000", "1699999999.1234", "b", "m", ""]], "trade", "XBT/USD"], [0, {"a": [["55001.00000", "1.00000000", "1699999999.1234"]], "c": "1234"}, "book-10", "XBT/USD"], [0, [["55000.00000", "0.01000000", "1699999999.1234", "b", "m", ""]], "trade", "XBT/USD"], [0, {"a": [["55001.00000", "1.00000000", "1699999999.1234"]], "c": "1234"}, "book-10", "XBT/USD"], [0, [["55000.00000", "0.01000000", "1699999999.1234", "b", "m", ""]], "trade", "XBT/USD"], [0, {"a": [["55001.00000", "1.00000000", "1699999999.1234"]], "c": "1234"}, "book-10", "XBT/USD"], [0, [["55000.00000", "0.01000000", "1699999999.1234", "b", "m", ""]], "trade", "XBT/USD"], [0, {"a": [["55001.00000", "1.00000000", "1699999999.1234"]], "c": "1234"}, "book-10", "XBT/USD"], [0, [["55000.00000", "0.01000000", "1699999999.1234", "b", "m", ""]], "trade", "XBT/USD"], [0, {"a": [["55001.00000", "1.00000000", "1699999999.1234"]], "c": "1234"}, "book-10", "XBT/USD"], [0, [["55000.00000", "0.01000000", "1699999999.1234", "b", "m", ""]], "trade", "XBT/USD"], [0, {"a": [["55001.00000", "1.00000000", "1699999999.1234"]], "c": "1234"}, "book-10", "XBT/USD"], [0, [["55000.00000", "0.01000000", "1699999999.1234", "b", "m", ""]], "trade", "XBT/USD"], [0, {"a": [["55001.00000", "1.00000000", "1699999999.1234"]], "c": "1234"}, "book-10", "XBT/USD"], [0, [["55000.00000", "0.01000000", "1699999999.1234", "b", "m", ""]], "trade", "XBT/USD"], [0, {"a": [["55001.00000", "1.00000000", "1699999999.1234"]], "c": "1234"}, "book-10", "XBT/USD"], [0, [["55000.00000", "0.01000000", "1699999999.1234", "b", "m", ""]], "trade", "XBT/USD"], [0, {"a": [["55001.00000", "1.00000000", "1699999999.1234"]], "c": "1234"}, "book-10", "XBT/USD"], [0, [["55000.00000", "0.01000000", "1699999999.1234", "b", "m", ""]], "trade", "XBT/USD"], [0, {"a": [["55001.00000", "1.00000000", "1699999999.1234"]], "c": "1234"}, "book-10", "XBT/USD"], [0, [["55000.00000", "0.01000000", "1699999999.1234", "b", "m", ""]], "trade", "XBT/USD"], [0, {"a": [["55001.00000", "1.00000000", "1699999999.1234"]], "c": "1234"}, "book-10", "XBT/USD"], [0, [["55000.00000", "0.01000000", "1699999999.1234", "b", "m", ""]], "trade", "XBT/USD"], [0, {"a": [["55001.00000", "1.00000000", "1699999999.1234"]], "c": "1234"}, "book-10", "XBT/USD"], [0, [["55000.00000", "0.01000000", "1699999999.1234", "b", "m", ""]], "trade", "XBT/USD"], [0, {"a": [["55001.00000", "1.00000000", "1699999999.1234"]], "c": "1234"}, "book-10", "XBT/USD"], [0, [["55000.00000", "0.01000000", "1699999999.1234", "b", "m", ""]], "trade", "XBT/USD"], [0, {"a": [["55001.00000", "